<?xml version="1.0" ?>
<!-- =================================================================================== -->
<!-- |    This document was autogenerated by xacro from /catkin_ws/src/ginko_ros/ginko_description/xacro/ginko_xm540/ginko.xacro | -->
<!-- |    EDITING THIS FILE BY HAND IS NOT RECOMMENDED                                 | -->
<!-- =================================================================================== -->
<robot name="ginko" xmlns:xacro="http://www.ros.org/wiki/xacro">
  <link name="root_link"/>
  <joint name="root_joint" type="fixed">
    <parent link="root_link"/>
    <child link="waist_link01"/>
    <origin rpy="0 0 0" xyz="0 0 0"/>
  </joint>
  <!-- waist -->
  <link name="waist_link01">
    <visual>
      <origin rpy="0 0 0" xyz="0 0 0"/>
      <geometry>
        <mesh filename="package://ginko_description/meshes/ginko_xm540/obj/waist_link01.obj"/>
      </geometry>
    </visual>
    <collision>
      <origin rpy="0 0 0" xyz="0 0 0.0305"/>
      <geometry>
        <box size="0.084 0.04 0.0895"/>
      </geometry>
    </collision>
    <inertial>
      <origin rpy="0 0 0" xyz="0 0 0.0305"/>
      <mass value="0.382"/>
      <inertia ixx="0.000305926291667" ixy="0.0" ixz="0.0" iyy="0.000479608958333" iyz="0.0" izz="0.000275549333333"/>
    </inertial>
    <!-- <inertial>
				<mass value="0.382"/>
				<origin xyz="0.000083485 0.0 0.03686607" rpy="0 0 0"/>
				<inertia
					ixx="0.00034299"
					ixy="0.00000000" iyy="0.00044850"
					ixz="-0.00000583" iyz="0.00000000" izz="0.00022842"/>
			</inertial> -->
  </link>
  <!-- Joint1 -->
  <joint name="chest_joint01" type="revolute">
    <parent link="waist_link01"/>
    <child link="chest_link01"/>
    <origin rpy="0 0 0" xyz="0 0 0.0975"/>
    <axis xyz="0 0 1"/>
    <limit effort="1000.0" lower="-3.1" upper="3.1" velocity="10.0"/>
    <dynamics damping="0.0" friction="0.0"/>
  </joint>
  <!-- chest -->
  <link name="chest_link01">
    <visual>
      <origin rpy="0 0 0" xyz="0 0 0"/>
      <geometry>
        <mesh filename="package://ginko_description/meshes/ginko_xm540/obj/chest_link01.obj"/>
      </geometry>
    </visual>
    <collision>
      <origin rpy="0 0 0" xyz="0 0 0.012"/>
      <geometry>
        <box size="0.11 0.201 0.053"/>
      </geometry>
    </collision>
    <collision>
      <origin rpy="0 0.74915633 0" xyz="0.048 0 0.044"/>
      <geometry>
        <box size="0.074 0.062 0.072"/>
      </geometry>
    </collision>
    <inertial>
      <origin rpy="0 0 0" xyz="0 0 0.012"/>
      <mass value="0.665"/>
      <inertia ixx="0.00239455416667" ixy="0.0" ixz="0.0" iyy="0.000826207083333" iyz="0.0" izz="0.00290943041667"/>
    </inertial>
    <!-- <inertial>
				<mass value="0.665"/>
				<origin xyz="0.00121250 0.0 0.01189965" rpy="0 0 0"/>
				<inertia
					ixx="0.00260149"
					ixy="0.00000002" iyy="0.00082845"
					ixz="-0.00004048" iyz="0.00000002" izz="0.00291420"/>
			</inertial> -->
  </link>
  <gazebo reference="chest_link01">
    <kp>1000000.0</kp>
    <kd>100.0</kd>
    <mu1>0.1</mu1>
    <maxVel>10.0</maxVel>
    <minDepth>0.0001</minDepth>
    <maxContacts>6</maxContacts>
    <selfCollide>false</selfCollide>
    <dampingFactor>0</dampingFactor>
  </gazebo>
  <gazebo reference="chest_joint01">
    <implicitSpringDamper>1</implicitSpringDamper>
  </gazebo>
  <transmission name="chest_joint01_trans">
    <type>transmission_interface/SimpleTransmission</type>
    <joint name="chest_joint01">
      <hardwareInterface>hardware_interface/PositionJointInterface</hardwareInterface>
    </joint>
    <actuator name="chest_joint01_motor">
      <hardwareInterface>hardware_interface/PositionJointInterface</hardwareInterface>
      <mechanicalReduction>1</mechanicalReduction>
    </actuator>
  </transmission>
  <gazebo reference="waist_link01">
    <kp>1000000.0</kp>
    <kd>100.0</kd>
    <mu1>0.1</mu1>
    <maxVel>10.0</maxVel>
    <minDepth>0.0001</minDepth>
    <maxContacts>6</maxContacts>
    <selfCollide>false</selfCollide>
    <dampingFactor>0</dampingFactor>
  </gazebo>
  <!-- Link conencts from body. Femoral first. -->
  <joint name="leg_r_joint01" type="revolute">
    <parent link="waist_link01"/>
    <child link="leg_r_link01"/>
    <origin rpy="0 0 0" xyz="0 0 0"/>
    <axis xyz="1 0 0"/>
    <limit effort="1000.0" lower="-0.78539816" upper="0.78539816" velocity="10.0"/>
    <dynamics damping="0.0" friction="0.0"/>
  </joint>
  <link name="leg_r_link01">
    <visual>
      <origin rpy="0 0 0" xyz="0 0 0"/>
      <geometry>
        <mesh filename="package://ginko_description/meshes/ginko_xm540/obj/leg_r_link01.obj"/>
      </geometry>
    </visual>
    <collision>
      <origin rpy="0 0 0" xyz="0 -0.015 0"/>
      <geometry>
        <box size="0.095 0.05 0.03"/>
      </geometry>
    </collision>
    <inertial>
      <origin rpy="0 0 0" xyz="0 -0.015 0"/>
      <mass value="0.025"/>
      <inertia ixx="1e-05" ixy="0.0" ixz="0.0" iyy="2.06770833333e-05" iyz="0.0" izz="2.40104166667e-05"/>
    </inertial>
  </link>
  <joint name="leg_r_joint02" type="revolute">
    <parent link="leg_r_link01"/>
    <child link="leg_r_link02"/>
    <origin rpy="0 0 0" xyz="0 -0.06085 0"/>
    <axis xyz="0 1 0"/>
    <limit effort="1000.0" lower="-1.57079633" upper="1.57079633" velocity="10.0"/>
    <dynamics damping="0.0" friction="0.0"/>
  </joint>
  <link name="leg_r_link02">
    <visual>
      <origin rpy="0 0 0" xyz="0 0 0"/>
      <geometry>
        <mesh filename="package://ginko_description/meshes/ginko_xm540/obj/leg_r_link02.obj"/>
      </geometry>
    </visual>
    <collision>
      <origin rpy="0 0 0" xyz="0 -0.02 -0.0037"/>
      <geometry>
        <box size="0.067 0.095 0.077"/>
      </geometry>
    </collision>
    <inertial>
      <origin rpy="0 0 0" xyz="0 -0.02 -0.0037"/>
      <mass value="0.48"/>
      <inertia ixx="0.00059816" ixy="0.0" ixz="0.0" iyy="0.00041672" iyz="0.0" izz="0.00054056"/>
    </inertial>
  </link>
  <joint name="leg_r_joint03" type="revolute">
    <parent link="leg_r_link02"/>
    <child link="leg_r_link03"/>
    <origin rpy="0 0.78539816 0" xyz="0.016713 0 -0.027522"/>
    <axis xyz="0 1 0"/>
    <limit effort="1000.0" lower="-0.5" upper="1.4" velocity="10.0"/>
    <dynamics damping="0.0" friction="0.0"/>
  </joint>
  <link name="leg_r_link03">
    <visual>
      <origin rpy="0 0 0" xyz="0 0 0"/>
      <geometry>
        <mesh filename="package://ginko_description/meshes/ginko_xm540/obj/leg_r_link03.obj"/>
      </geometry>
    </visual>
    <collision>
      <origin rpy="0 0 0" xyz="0.046 0 0"/>
      <geometry>
        <box size="0.108655 0.0373 0.023"/>
      </geometry>
    </collision>
    <inertial>
      <origin rpy="0 0 0" xyz="0.046 0 0"/>
      <mass value="0.028"/>
      <inertia ixx="1e-05" ixy="0.0" ixz="0.0" iyy="2.87814543917e-05" iyz="0.0" izz="3.07934643917e-05"/>
    </inertial>
  </link>
  <joint name="leg_r_joint04" type="revolute">
    <parent link="leg_r_link02"/>
    <child link="leg_r_link04"/>
    <origin rpy="0 -0.51016603 0" xyz="-0.016713 0 -0.027522"/>
    <axis xyz="0 1 0"/>
    <limit effort="1000.0" lower="-1.4" upper="0.5" velocity="1000.0"/>
    <dynamics damping="0.0" friction="0.0"/>
  </joint>
  <link name="leg_r_link04">
    <visual>
      <origin rpy="0 0 0" xyz="0 0 0"/>
      <geometry>
        <mesh filename="package://ginko_description/meshes/ginko_xm540/obj/leg_r_link04.obj"/>
      </geometry>
    </visual>
    <collision>
      <origin rpy="0 0 0" xyz="-0.015 0 0"/>
      <geometry>
        <box size="0.04565 0.0373 0.023"/>
      </geometry>
    </collision>
    <inertial>
      <origin rpy="0 0 0" xyz="-0.015 0 0"/>
      <mass value="0.011"/>
      <inertia ixx="1e-05" ixy="0.0" ixz="0.0" iyy="1e-05" iyz="0.0" izz="1e-05"/>
    </inertial>
  </link>
  <joint name="leg_r_joint07" type="revolute">
    <parent link="leg_r_link03"/>
    <child link="leg_r_link07"/>
    <origin rpy="0 -0.78539816 0" xyz="0.1 0 0"/>
    <axis xyz="0 1 0"/>
    <limit effort="1000.0" lower="-3.1" upper="3.1" velocity="1000.0"/>
    <dynamics damping="0.0" friction="0.0"/>
    <mimic joint="leg_r_joint03" multiplier="-1" offset="0"/>
  </joint>
  <link name="leg_r_link07">
    <visual>
      <origin rpy="0 0 0" xyz="0 0 0"/>
      <geometry>
        <mesh filename="package://ginko_description/meshes/ginko_xm540/obj/leg_r_link07.obj"/>
      </geometry>
    </visual>
    <collision>
      <origin rpy="0 0 0" xyz="-0.01 0 0"/>
      <geometry>
        <box size="0.0605 0.0487 0.014"/>
      </geometry>
    </collision>
    <inertial>
      <origin rpy="0 0 0" xyz="-0.01 0 0"/>
      <mass value="0.009"/>
      <inertia ixx="1e-05" ixy="0.0" ixz="0.0" iyy="1e-05" iyz="0.0" izz="1e-05"/>
    </inertial>
  </link>
  <joint name="leg_r_joint05" type="revolute">
    <parent link="leg_r_link07"/>
    <child link="leg_r_link05"/>
    <origin rpy="0 0.78539816 0" xyz="-0.0335 0 0"/>
    <axis xyz="0 1 0"/>
    <limit effort="1000.0" lower="-0.5" upper="1.4" velocity="1000.0"/>
    <dynamics damping="0.0" friction="0.0"/>
    <mimic joint="leg_r_joint03" multiplier="1" offset="0"/>
  </joint>
  <link name="leg_r_link05">
    <visual>
      <origin rpy="0 0 0" xyz="-0.1 0 0"/>
      <geometry>
        <mesh filename="package://ginko_description/meshes/ginko_xm540/obj/leg_r_link05.obj"/>
      </geometry>
    </visual>
    <collision>
      <origin rpy="0 0 0" xyz="-0.05 0 0"/>
      <geometry>
        <box size="0.1 0.0309 0.017"/>
      </geometry>
    </collision>
    <inertial>
      <origin rpy="0 0 0" xyz="-0.05 0 0"/>
      <mass value="0.02"/>
      <inertia ixx="1e-05" ixy="0.0" ixz="0.0" iyy="1.71483333333e-05" iyz="0.0" izz="1.82580166667e-05"/>
    </inertial>
  </link>
  <gazebo>
    <joint name="leg_r_loop_joint01" type="revolute">
      <parent>leg_r_link02</parent>
      <child>leg_r_link05</child>
      <pose>-0.1 0 0 0 0 0</pose>
      <axis>
        <xyz>0 1 0</xyz>
        <limit>
          <lower>-3.1</lower>
          <upper>3.1</upper>
        </limit>
        <dynamics>
          <spring_reference>0</spring_reference>
          <spring_stiffness>0</spring_stiffness>
        </dynamics>
        <use_parent_model_frame>1</use_parent_model_frame>
      </axis>
      <physics>
        <ode>
          <implicit_spring_damper>1</implicit_spring_damper>
          <cfm_damping>0</cfm_damping>
          <limit>
            <cfm>1e-7</cfm>
            <erp>0.8</erp>
          </limit>
        </ode>
      </physics>
    </joint>
  </gazebo>
  <joint name="leg_r_joint08" type="revolute">
    <parent link="leg_r_link07"/>
    <child link="leg_r_link08"/>
    <origin rpy="0 -0.78539816 0" xyz="0 0 0"/>
    <axis xyz="0 1 0"/>
    <limit effort="1000.0" lower="-3.1" upper="3.1" velocity="10.0"/>
    <dynamics damping="0.0" friction="0.0"/>
    <mimic joint="leg_r_joint04" multiplier="1" offset="0"/>
  </joint>
  <link name="leg_r_link08">
    <visual>
      <origin rpy="0 0 0" xyz="0 0 0"/>
      <geometry>
        <mesh filename="package://ginko_description/meshes/ginko_xm540/obj/leg_r_link08.obj"/>
      </geometry>
    </visual>
    <collision>
      <origin rpy="0 0 0" xyz="-0.05 0 0"/>
      <geometry>
        <box size="0.1 0.0301 0.0175"/>
      </geometry>
    </collision>
    <inertial>
      <origin rpy="0 0 0" xyz="-0.05 0 0"/>
      <mass value="0.021"/>
      <inertia ixx="1e-05" ixy="0.0" ixz="0.0" iyy="1.80359375e-05" iyz="0.0" izz="1.90855175e-05"/>
    </inertial>
  </link>
  <joint name="leg_r_joint10" type="revolute">
    <parent link="leg_r_link08"/>
    <child link="leg_r_link10"/>
    <origin rpy="0 0.78539816 0" xyz="-0.1 0 0"/>
    <axis xyz="0 1 0"/>
    <limit effort="1000.0" lower="-0.5" upper="1.4" velocity="1000.0"/>
    <dynamics damping="0.0" friction="0.0"/>
    <mimic joint="leg_r_joint04" multiplier="-1" offset="0"/>
  </joint>
  <link name="leg_r_link10">
    <visual>
      <origin rpy="0 0 0" xyz="0 0 0"/>
      <geometry>
        <mesh filename="package://ginko_description/meshes/ginko_xm540/obj/leg_r_link10.obj"/>
      </geometry>
    </visual>
    <collision>
      <origin rpy="0 0 0" xyz="-0.03335 -0.0087 -0.0160"/>
      <geometry>
        <box size="0.0873 0.0531 0.046"/>
      </geometry>
    </collision>
    <inertial>
      <origin rpy="0 0 0" xyz="-0.03335 -0.0087 -0.0160"/>
      <mass value="0.108"/>
      <inertia ixx="4.442049e-05" ixy="0.0" ixz="0.0" iyy="8.763561e-05" iyz="0.0" izz="9.39681e-05"/>
    </inertial>
  </link>
  <joint name="leg_r_joint09" type="revolute">
    <parent link="leg_r_link10"/>
    <child link="leg_r_link09"/>
    <origin rpy="0 -0.78539816 0" xyz="-0.0335 0 0"/>
    <axis xyz="0 1 0"/>
    <limit effort="1000.0" lower="-1.4" upper="0.5" velocity="1000.0"/>
    <dynamics damping="0.0" friction="0.0"/>
    <mimic joint="leg_r_joint04" multiplier="1" offset="0"/>
  </joint>
  <link name="leg_r_link09">
    <visual>
      <origin rpy="0 0 0" xyz="0.1 0 0"/>
      <geometry>
        <mesh filename="package://ginko_description/meshes/ginko_xm540/obj/leg_r_link09.obj"/>
      </geometry>
    </visual>
    <collision>
      <origin rpy="0 0 0" xyz="0.05 0 0"/>
      <geometry>
        <box size="0.1 0.0237 0.0175"/>
      </geometry>
    </collision>
    <inertial>
      <origin rpy="0 0 0" xyz="0.05 0 0"/>
      <mass value="0.022"/>
      <inertia ixx="1e-05" ixy="0.0" ixz="0.0" iyy="1.88947916667e-05" iyz="0.0" izz="1.93630983333e-05"/>
    </inertial>
  </link>
  <gazebo>
    <joint name="leg_r_loop_joint02" type="revolute">
      <parent>leg_r_link07</parent>
      <child>leg_r_link09</child>
      <pose>0.1 0 0 0 0 0</pose>
      <axis>
        <xyz>0 1 0</xyz>
        <limit>
          <lower>-3.1</lower>
          <upper>3.1</upper>
        </limit>
        <dynamics>
          <spring_reference>0</spring_reference>
          <spring_stiffness>0</spring_stiffness>
        </dynamics>
        <use_parent_model_frame>1</use_parent_model_frame>
      </axis>
      <physics>
        <ode>
          <implicit_spring_damper>1</implicit_spring_damper>
          <cfm_damping>0</cfm_damping>
          <limit>
            <cfm>1e-7</cfm>
            <erp>0.8</erp>
          </limit>
        </ode>
      </physics>
    </joint>
  </gazebo>
  <joint name="leg_r_joint06" type="revolute">
    <parent link="leg_r_link09"/>
    <child link="leg_r_link06"/>
    <origin rpy="0 1.57079633 0" xyz="0.07118 0 0.00834"/>
    <axis xyz="0 1 0"/>
    <limit effort="1000.0" lower="-1.0" upper="1.5" velocity="10.0"/>
    <dynamics damping="0.0" friction="0.0"/>
    <!-- Only for Rviz. Not correct. -->
    <mimic joint="leg_r_joint03" multiplier="1" offset="0"/>
  </joint>
  <link name="leg_r_link06">
    <visual>
      <origin rpy="0 0 0" xyz="-0.1 0 0"/>
      <geometry>
        <mesh filename="package://ginko_description/meshes/ginko_xm540/obj/leg_r_link06.obj"/>
      </geometry>
    </visual>
    <collision>
      <origin rpy="0 0 0" xyz="-0.05 0 0"/>
      <geometry>
        <box size="0.1 0.0181 0.017"/>
      </geometry>
    </collision>
    <inertial>
      <origin rpy="0 0 0" xyz="-0.05 0 0"/>
      <mass value="0.015"/>
      <inertia ixx="1e-05" ixy="0.0" ixz="0.0" iyy="1.286125e-05" iyz="0.0" izz="1.29095125e-05"/>
    </inertial>
  </link>
  <gazebo>
    <joint name="leg_r_loop_joint03" type="revolute">
      <parent>leg_r_link04</parent>
      <child>leg_r_link06</child>
      <pose>-0.1 0 0 0 0 0</pose>
      <axis>
        <xyz>0 1 0</xyz>
        <limit>
          <lower>-3.1</lower>
          <upper>3.1</upper>
        </limit>
        <dynamics>
          <spring_reference>0</spring_reference>
          <spring_stiffness>0</spring_stiffness>
        </dynamics>
        <use_parent_model_frame>1</use_parent_model_frame>
      </axis>
      <physics>
        <ode>
          <implicit_spring_damper>1</implicit_spring_damper>
          <cfm_damping>0</cfm_damping>
          <limit>
            <cfm>1e-7</cfm>
            <erp>0.8</erp>
          </limit>
        </ode>
      </physics>
    </joint>
  </gazebo>
  <joint name="leg_r_joint11" type="revolute">
    <parent link="leg_r_link10"/>
    <child link="leg_r_link11"/>
    <origin rpy="0 0 0" xyz="-0.01675 0 -0.02475"/>
    <axis xyz="1 0 0"/>
    <limit effort="1000.0" lower="-3.1" upper="3.1" velocity="1000.0"/>
    <dynamics damping="0.0" friction="0.0"/>
  </joint>
  <link name="leg_r_link11">
    <visual>
      <origin rpy="0 0 0" xyz="0 0 0"/>
      <geometry>
        <mesh filename="package://ginko_description/meshes/ginko_xm540/obj/leg_r_link11.obj"/>
      </geometry>
    </visual>
    <collision>
      <origin rpy="0 0 0" xyz="0 -0.00835 -0.015"/>
      <geometry>
        <box size="0.0485 0.0567 0.044"/>
      </geometry>
    </collision>
    <inertial>
      <origin rpy="0 0 0" xyz="0 -0.00835 -0.015"/>
      <mass value="0.136"/>
      <inertia ixx="5.83767533333e-05" ixy="0.0" ixz="0.0" iyy="4.86001666667e-05" iyz="0.0" izz="6.30942533333e-05"/>
    </inertial>
  </link>
  <joint name="leg_r_joint12" type="revolute">
    <parent link="leg_r_link11"/>
    <child link="leg_r_link12_1"/>
    <origin rpy="0 0 0" xyz="0 0 -0.0625"/>
    <axis xyz="0 0 -1"/>
    <limit effort="1000.0" lower="-3.1" upper="3.1" velocity="1000.0"/>
    <dynamics damping="0.0" friction="0.0"/>
  </joint>
  <link name="leg_r_link12_1">
    <visual>
      <origin rpy="0 0 0" xyz="0 0 0"/>
      <geometry>
        <mesh filename="package://ginko_description/meshes/ginko_xm540/obj/leg_r_link12_1.obj"/>
      </geometry>
    </visual>
    <collision>
      <origin rpy="0 0 0" xyz="0 0 0.00965"/>
      <geometry>
        <box size="0.038 0.038 0.0272"/>
      </geometry>
    </collision>
    <inertial>
      <origin rpy="0 0 0" xyz="0 0 0.00965"/>
      <mass value="0.0316"/>
      <inertia ixx="1e-05" ixy="0.0" ixz="0.0" iyy="1e-05" iyz="0.0" izz="1e-05"/>
    </inertial>
  </link>
  <joint name="leg_r_ft_sensor_joint" type="fixed">
    <parent link="leg_r_link12_1"/>
    <child link="leg_r_link12_2"/>
    <origin rpy="0 0 0" xyz="0 0 0"/>
  </joint>
  <gazebo reference="leg_r_ft_sensor_joint">
    <preserveFixedJoint>true</preserveFixedJoint>
  </gazebo>
  <link name="leg_r_link12_2">
    <visual>
      <origin rpy="0 0 0" xyz="0 0 -0.01225"/>
      <geometry>
        <mesh filename="package://ginko_description/meshes/ginko_xm540/obj/leg_r_link12_2.obj"/>
      </geometry>
    </visual>
    <collision>
      <origin rpy="0 0 0" xyz="0 0 -0.00025"/>
      <geometry>
        <box size="0.12 0.075 0.024"/>
      </geometry>
    </collision>
    <inertial>
      <origin rpy="0 0 0" xyz="0 0 -0.00025"/>
      <mass value="0.0486"/>
      <inertia ixx="2.511405e-05" ixy="0.0" ixz="0.0" iyy="6.06528e-05" iyz="0.0" izz="8.110125e-05"/>
    </inertial>
  </link>
  <gazebo reference="leg_r_joint01">
    <implicitSpringDamper>1</implicitSpringDamper>
  </gazebo>
  <transmission name="leg_r_joint01_trans">
    <type>transmission_interface/SimpleTransmission</type>
    <joint name="leg_r_joint01">
      <hardwareInterface>hardware_interface/PositionJointInterface</hardwareInterface>
    </joint>
    <actuator name="leg_r_joint01_motor">
      <hardwareInterface>hardware_interface/PositionJointInterface</hardwareInterface>
      <mechanicalReduction>1</mechanicalReduction>
    </actuator>
  </transmission>
  <gazebo reference="leg_r_joint02">
    <implicitSpringDamper>1</implicitSpringDamper>
  </gazebo>
  <transmission name="leg_r_joint02_trans">
    <type>transmission_interface/SimpleTransmission</type>
    <joint name="leg_r_joint02">
      <hardwareInterface>hardware_interface/PositionJointInterface</hardwareInterface>
    </joint>
    <actuator name="leg_r_joint02_motor">
      <hardwareInterface>hardware_interface/PositionJointInterface</hardwareInterface>
      <mechanicalReduction>1</mechanicalReduction>
    </actuator>
  </transmission>
  <gazebo reference="leg_r_joint03">
    <implicitSpringDamper>1</implicitSpringDamper>
  </gazebo>
  <transmission name="leg_r_joint03_trans">
    <type>transmission_interface/SimpleTransmission</type>
    <joint name="leg_r_joint03">
      <hardwareInterface>hardware_interface/PositionJointInterface</hardwareInterface>
    </joint>
    <actuator name="leg_r_joint03_motor">
      <hardwareInterface>hardware_interface/PositionJointInterface</hardwareInterface>
      <mechanicalReduction>1</mechanicalReduction>
    </actuator>
  </transmission>
  <gazebo reference="leg_r_joint04">
    <implicitSpringDamper>1</implicitSpringDamper>
  </gazebo>
  <transmission name="leg_r_joint04_trans">
    <type>transmission_interface/SimpleTransmission</type>
    <joint name="leg_r_joint04">
      <hardwareInterface>hardware_interface/PositionJointInterface</hardwareInterface>
    </joint>
    <actuator name="leg_r_joint04_motor">
      <hardwareInterface>hardware_interface/PositionJointInterface</hardwareInterface>
      <mechanicalReduction>1</mechanicalReduction>
    </actuator>
  </transmission>
  <gazebo reference="leg_r_joint05">
    <implicitSpringDamper>1</implicitSpringDamper>
  </gazebo>
  <gazebo reference="leg_r_joint06">
    <implicitSpringDamper>1</implicitSpringDamper>
  </gazebo>
  <gazebo reference="leg_r_joint07">
    <implicitSpringDamper>1</implicitSpringDamper>
  </gazebo>
  <gazebo reference="leg_r_joint08">
    <implicitSpringDamper>1</implicitSpringDamper>
  </gazebo>
  <gazebo reference="leg_r_joint09">
    <implicitSpringDamper>1</implicitSpringDamper>
  </gazebo>
  <gazebo reference="leg_r_joint10">
    <implicitSpringDamper>1</implicitSpringDamper>
  </gazebo>
  <gazebo reference="leg_r_joint11">
    <implicitSpringDamper>1</implicitSpringDamper>
  </gazebo>
  <transmission name="leg_r_joint11_trans">
    <type>transmission_interface/SimpleTransmission</type>
    <joint name="leg_r_joint11">
      <hardwareInterface>hardware_interface/PositionJointInterface</hardwareInterface>
    </joint>
    <actuator name="leg_r_joint11_motor">
      <hardwareInterface>hardware_interface/PositionJointInterface</hardwareInterface>
      <mechanicalReduction>1</mechanicalReduction>
    </actuator>
  </transmission>
  <gazebo reference="leg_r_joint12">
    <implicitSpringDamper>1</implicitSpringDamper>
  </gazebo>
  <transmission name="leg_r_joint12_trans">
    <type>transmission_interface/SimpleTransmission</type>
    <joint name="leg_r_joint12">
      <hardwareInterface>hardware_interface/PositionJointInterface</hardwareInterface>
    </joint>
    <actuator name="leg_r_joint12_motor">
      <hardwareInterface>hardware_interface/PositionJointInterface</hardwareInterface>
      <mechanicalReduction>1</mechanicalReduction>
    </actuator>
  </transmission>
  <gazebo reference="leg_r_ft_sensor_joint">
    <implicitSpringDamper>1</implicitSpringDamper>
  </gazebo>
  <gazebo reference="leg_r_link01">
    <kp>1000000.0</kp>
    <kd>100.0</kd>
    <mu1>0.0</mu1>
    <maxVel>10.0</maxVel>
    <minDepth>0.0001</minDepth>
    <maxContacts>6</maxContacts>
    <selfCollide>false</selfCollide>
    <dampingFactor>0</dampingFactor>
  </gazebo>
  <gazebo reference="leg_r_link02">
    <kp>1000000.0</kp>
    <kd>100.0</kd>
    <mu1>0.01</mu1>
    <maxVel>10.0</maxVel>
    <minDepth>0.0001</minDepth>
    <maxContacts>6</maxContacts>
    <selfCollide>false</selfCollide>
    <dampingFactor>0</dampingFactor>
  </gazebo>
  <gazebo reference="leg_r_link03">
    <kp>1000000.0</kp>
    <kd>100.0</kd>
    <mu1>0.0</mu1>
    <maxVel>10.0</maxVel>
    <minDepth>0.0001</minDepth>
    <maxContacts>6</maxContacts>
    <selfCollide>false</selfCollide>
    <dampingFactor>0</dampingFactor>
  </gazebo>
  <gazebo reference="leg_r_link04">
    <kp>1000000.0</kp>
    <kd>100.0</kd>
    <mu1>0.0</mu1>
    <maxVel>10.0</maxVel>
    <minDepth>0.0001</minDepth>
    <maxContacts>6</maxContacts>
    <selfCollide>false</selfCollide>
    <dampingFactor>0</dampingFactor>
  </gazebo>
  <gazebo reference="leg_r_link05">
    <kp>1000000.0</kp>
    <kd>100.0</kd>
    <mu1>0.0</mu1>
    <maxVel>10.0</maxVel>
    <minDepth>0.0001</minDepth>
    <maxContacts>6</maxContacts>
    <selfCollide>false</selfCollide>
    <dampingFactor>0</dampingFactor>
  </gazebo>
  <gazebo reference="leg_r_link06">
    <kp>1000000.0</kp>
    <kd>100.0</kd>
    <mu1>0.0</mu1>
    <maxVel>10.0</maxVel>
    <minDepth>0.0001</minDepth>
    <maxContacts>6</maxContacts>
    <selfCollide>false</selfCollide>
    <dampingFactor>0</dampingFactor>
  </gazebo>
  <gazebo reference="leg_r_link07">
    <kp>1000000.0</kp>
    <kd>100.0</kd>
    <mu1>0.01</mu1>
    <maxVel>10.0</maxVel>
    <minDepth>0.0001</minDepth>
    <maxContacts>6</maxContacts>
    <selfCollide>false</selfCollide>
    <dampingFactor>0</dampingFactor>
  </gazebo>
  <gazebo reference="leg_r_link08">
    <kp>1000000.0</kp>
    <kd>100.0</kd>
    <mu1>0.0</mu1>
    <maxVel>10.0</maxVel>
    <minDepth>0.0001</minDepth>
    <maxContacts>6</maxContacts>
    <selfCollide>false</selfCollide>
    <dampingFactor>0</dampingFactor>
  </gazebo>
  <gazebo reference="leg_r_link09">
    <kp>1000000.0</kp>
    <kd>100.0</kd>
    <mu1>0.0</mu1>
    <maxVel>10.0</maxVel>
    <minDepth>0.0001</minDepth>
    <maxContacts>6</maxContacts>
    <selfCollide>false</selfCollide>
    <dampingFactor>0</dampingFactor>
  </gazebo>
  <gazebo reference="leg_r_link10">
    <kp>1000000.0</kp>
    <kd>100.0</kd>
    <mu1>0.01</mu1>
    <maxVel>10.0</maxVel>
    <minDepth>0.0001</minDepth>
    <maxContacts>6</maxContacts>
    <selfCollide>false</selfCollide>
    <dampingFactor>0</dampingFactor>
  </gazebo>
  <gazebo reference="leg_r_link11">
    <kp>1000000.0</kp>
    <kd>100.0</kd>
    <mu1>0.0</mu1>
    <maxVel>10.0</maxVel>
    <minDepth>0.0001</minDepth>
    <maxContacts>6</maxContacts>
    <selfCollide>false</selfCollide>
    <dampingFactor>0</dampingFactor>
  </gazebo>
  <gazebo reference="leg_r_link12_1">
    <kp>1000000.0</kp>
    <kd>100.0</kd>
    <mu1>0.0</mu1>
    <maxVel>10.0</maxVel>
    <minDepth>0.0001</minDepth>
    <maxContacts>6</maxContacts>
    <selfCollide>false</selfCollide>
    <dampingFactor>0</dampingFactor>
  </gazebo>
  <gazebo reference="leg_r_link12_2">
    <kp>1000000.0</kp>
    <kd>100.0</kd>
    <mu1>0.5</mu1>
    <maxVel>10.0</maxVel>
    <minDepth>0.0001</minDepth>
    <maxContacts>6</maxContacts>
    <selfCollide>false</selfCollide>
    <dampingFactor>0</dampingFactor>
  </gazebo>
  <!-- Link conencts from body. Femoral first. -->
  <joint name="leg_l_joint01" type="revolute">
    <parent link="waist_link01"/>
    <child link="leg_l_link01"/>
    <origin rpy="0 0 0" xyz="0 0 0"/>
    <axis xyz="-1 0 0"/>
    <limit effort="1000.0" lower="-0.78539816" upper="0.78539816" velocity="10.0"/>
    <dynamics damping="0.0" friction="0.0"/>
  </joint>
  <link name="leg_l_link01">
    <visual>
      <origin rpy="0 0 0" xyz="0 0 0"/>
      <geometry>
        <mesh filename="package://ginko_description/meshes/ginko_xm540/obj/leg_l_link01.obj"/>
      </geometry>
    </visual>
    <collision>
      <origin rpy="0 0 0" xyz="0 0.015 0"/>
      <geometry>
        <box size="0.095 0.05 0.03"/>
      </geometry>
    </collision>
    <inertial>
      <origin rpy="0 0 0" xyz="0 0.015 0"/>
      <mass value="0.025"/>
      <inertia ixx="1e-05" ixy="0.0" ixz="0.0" iyy="2.06770833333e-05" iyz="0.0" izz="2.40104166667e-05"/>
    </inertial>
  </link>
  <joint name="leg_l_joint02" type="revolute">
    <parent link="leg_l_link01"/>
    <child link="leg_l_link02"/>
    <origin rpy="0 0 0" xyz="0 0.06085 0"/>
    <axis xyz="0 -1 0"/>
    <limit effort="1000.0" lower="-1.57079633" upper="1.57079633" velocity="10.0"/>
    <dynamics damping="0.0" friction="0.0"/>
  </joint>
  <link name="leg_l_link02">
    <visual>
      <origin rpy="0 0 0" xyz="0 0 0"/>
      <geometry>
        <mesh filename="package://ginko_description/meshes/ginko_xm540/obj/leg_l_link02.obj"/>
      </geometry>
    </visual>
    <collision>
      <origin rpy="0 0 0" xyz="0 0.02 -0.0037"/>
      <geometry>
        <box size="0.067 0.095 0.077"/>
      </geometry>
    </collision>
    <inertial>
      <origin rpy="0 0 0" xyz="0 0.02 -0.0037"/>
      <mass value="0.48"/>
      <inertia ixx="0.00059816" ixy="0.0" ixz="0.0" iyy="0.00041672" iyz="0.0" izz="0.00054056"/>
    </inertial>
  </link>
  <joint name="leg_l_joint03" type="revolute">
    <parent link="leg_l_link02"/>
    <child link="leg_l_link03"/>
    <origin rpy="0 0.78539816 0" xyz="0.016713 0 -0.027522"/>
    <axis xyz="0 -1 0"/>
    <limit effort="1000.0" lower="-1.4" upper="0.5" velocity="10.0"/>
    <dynamics damping="0.0" friction="0.0"/>
  </joint>
  <link name="leg_l_link03">
    <visual>
      <origin rpy="0 0 0" xyz="0 0 0"/>
      <geometry>
        <mesh filename="package://ginko_description/meshes/ginko_xm540/obj/leg_r_link03.obj"/>
      </geometry>
    </visual>
    <collision>
      <origin rpy="0 0 0" xyz="0.046 0 0"/>
      <geometry>
        <box size="0.108655 0.0373 0.023"/>
      </geometry>
    </collision>
    <inertial>
      <origin rpy="0 0 0" xyz="0.046 0 0"/>
      <mass value="0.028"/>
      <inertia ixx="1e-05" ixy="0.0" ixz="0.0" iyy="2.87814543917e-05" iyz="0.0" izz="3.07934643917e-05"/>
    </inertial>
  </link>
  <joint name="leg_l_joint04" type="revolute">
    <parent link="leg_l_link02"/>
    <child link="leg_l_link04"/>
    <origin rpy="0 -0.51016603 0" xyz="-0.016713 0 -0.027522"/>
    <axis xyz="0 -1 0"/>
    <limit effort="1000.0" lower="-0.5" upper="1.4" velocity="1000.0"/>
    <dynamics damping="0.0" friction="0.0"/>
  </joint>
  <link name="leg_l_link04">
    <visual>
      <origin rpy="0 0 0" xyz="0 0 0"/>
      <geometry>
        <mesh filename="package://ginko_description/meshes/ginko_xm540/obj/leg_r_link04.obj"/>
      </geometry>
    </visual>
    <collision>
      <origin rpy="0 0 0" xyz="-0.015 0 0"/>
      <geometry>
        <box size="0.04565 0.0373 0.023"/>
      </geometry>
    </collision>
    <inertial>
      <origin rpy="0 0 0" xyz="-0.015 0 0"/>
      <mass value="0.011"/>
      <inertia ixx="1e-05" ixy="0.0" ixz="0.0" iyy="1e-05" iyz="0.0" izz="1e-05"/>
    </inertial>
  </link>
  <joint name="leg_l_joint07" type="revolute">
    <parent link="leg_l_link03"/>
    <child link="leg_l_link07"/>
    <origin rpy="0 -0.78539816 0" xyz="0.1 0 0"/>
    <axis xyz="0 -1 0"/>
    <limit effort="1000.0" lower="-3.1" upper="3.1" velocity="1000.0"/>
    <dynamics damping="0.0" friction="0.0"/>
    <mimic joint="leg_l_joint03" multiplier="-1" offset="0"/>
  </joint>
  <link name="leg_l_link07">
    <visual>
      <origin rpy="0 0 0" xyz="0 0 0"/>
      <geometry>
        <mesh filename="package://ginko_description/meshes/ginko_xm540/obj/leg_r_link07.obj"/>
      </geometry>
    </visual>
    <collision>
      <origin rpy="0 0 0" xyz="-0.01 0 0"/>
      <geometry>
        <box size="0.0605 0.0487 0.014"/>
      </geometry>
    </collision>
    <inertial>
      <origin rpy="0 0 0" xyz="-0.01 0 0"/>
      <mass value="0.009"/>
      <inertia ixx="1e-05" ixy="0.0" ixz="0.0" iyy="1e-05" iyz="0.0" izz="1e-05"/>
    </inertial>
  </link>
  <joint name="leg_l_joint05" type="revolute">
    <parent link="leg_l_link07"/>
    <child link="leg_l_link05"/>
    <origin rpy="0 0.78539816 0" xyz="-0.0335 0 0"/>
    <axis xyz="0 -1 0"/>
    <limit effort="1000.0" lower="-1.4" upper="0.5" velocity="1000.0"/>
    <dynamics damping="0.0" friction="0.0"/>
    <mimic joint="leg_l_joint03" multiplier="1" offset="0"/>
  </joint>
  <link name="leg_l_link05">
    <visual>
      <origin rpy="0 0 0" xyz="-0.1 0 0"/>
      <geometry>
        <mesh filename="package://ginko_description/meshes/ginko_xm540/obj/leg_r_link05.obj"/>
      </geometry>
    </visual>
    <collision>
      <origin rpy="0 0 0" xyz="-0.05 0 0"/>
      <geometry>
        <box size="0.1 0.0309 0.017"/>
      </geometry>
    </collision>
    <inertial>
      <origin rpy="0 0 0" xyz="-0.05 0 0"/>
      <mass value="0.02"/>
      <inertia ixx="1e-05" ixy="0.0" ixz="0.0" iyy="1.71483333333e-05" iyz="0.0" izz="1.82580166667e-05"/>
    </inertial>
  </link>
  <gazebo>
    <joint name="leg_l_loop_joint01" type="revolute">
      <parent>leg_l_link02</parent>
      <child>leg_l_link05</child>
      <pose>-0.1 0 0 0 0 0</pose>
      <axis>
        <xyz>0 -1 0</xyz>
        <limit>
          <lower>-3.1</lower>
          <upper>3.1</upper>
        </limit>
        <dynamics>
          <spring_reference>0</spring_reference>
          <spring_stiffness>0</spring_stiffness>
        </dynamics>
        <use_parent_model_frame>1</use_parent_model_frame>
      </axis>
      <physics>
        <ode>
          <implicit_spring_damper>1</implicit_spring_damper>
          <cfm_damping>0</cfm_damping>
          <limit>
            <cfm>1e-7</cfm>
            <erp>0.8</erp>
          </limit>
        </ode>
      </physics>
    </joint>
  </gazebo>
  <joint name="leg_l_joint08" type="revolute">
    <parent link="leg_l_link07"/>
    <child link="leg_l_link08"/>
    <origin rpy="0 -0.78539816 0" xyz="0 0 0"/>
    <axis xyz="0 -1 0"/>
    <limit effort="1000.0" lower="-3.1" upper="3.1" velocity="10.0"/>
    <dynamics damping="0.0" friction="0.0"/>
    <mimic joint="leg_l_joint04" multiplier="1" offset="0"/>
  </joint>
  <link name="leg_l_link08">
    <visual>
      <origin rpy="0 0 0" xyz="0 0 0"/>
      <geometry>
        <mesh filename="package://ginko_description/meshes/ginko_xm540/obj/leg_r_link08.obj"/>
      </geometry>
    </visual>
    <collision>
      <origin rpy="0 0 0" xyz="-0.05 0 0"/>
      <geometry>
        <box size="0.1 0.0301 0.0175"/>
      </geometry>
    </collision>
    <inertial>
      <origin rpy="0 0 0" xyz="-0.05 0 0"/>
      <mass value="0.021"/>
      <inertia ixx="1e-05" ixy="0.0" ixz="0.0" iyy="1.80359375e-05" iyz="0.0" izz="1.90855175e-05"/>
    </inertial>
  </link>
  <joint name="leg_l_joint10" type="revolute">
    <parent link="leg_l_link08"/>
    <child link="leg_l_link10"/>
    <origin rpy="0 0.78539816 0" xyz="-0.1 0 0"/>
    <axis xyz="0 -1 0"/>
    <limit effort="1000.0" lower="-1.4" upper="0.5" velocity="1000.0"/>
    <dynamics damping="0.0" friction="0.0"/>
    <mimic joint="leg_l_joint04" multiplier="-1" offset="0"/>
  </joint>
  <link name="leg_l_link10">
    <visual>
      <origin rpy="0 0 0" xyz="0 0 0"/>
      <geometry>
        <mesh filename="package://ginko_description/meshes/ginko_xm540/obj/leg_l_link10.obj"/>
      </geometry>
    </visual>
    <collision>
      <origin rpy="0 0 0" xyz="-0.03335 0.0087 -0.0160"/>
      <geometry>
        <box size="0.0873 0.0531 0.046"/>
      </geometry>
    </collision>
    <inertial>
      <origin rpy="0 0 0" xyz="-0.03335 0.0087 -0.0160"/>
      <mass value="0.108"/>
      <inertia ixx="4.442049e-05" ixy="0.0" ixz="0.0" iyy="8.763561e-05" iyz="0.0" izz="9.39681e-05"/>
    </inertial>
  </link>
  <joint name="leg_l_joint09" type="revolute">
    <parent link="leg_l_link10"/>
    <child link="leg_l_link09"/>
    <origin rpy="0 -0.78539816 0" xyz="-0.0335 0 0"/>
    <axis xyz="0 -1 0"/>
    <limit effort="1000.0" lower="-0.5" upper="1.4" velocity="1000.0"/>
    <dynamics damping="0.0" friction="0.0"/>
    <mimic joint="leg_l_joint04" multiplier="1" offset="0"/>
  </joint>
  <link name="leg_l_link09">
    <visual>
      <origin rpy="0 0 0" xyz="0.1 0 0"/>
      <geometry>
        <mesh filename="package://ginko_description/meshes/ginko_xm540/obj/leg_r_link09.obj"/>
      </geometry>
    </visual>
    <collision>
      <origin rpy="0 0 0" xyz="0.05 0 0"/>
      <geometry>
        <box size="0.1 0.0237 0.0175"/>
      </geometry>
    </collision>
    <inertial>
      <origin rpy="0 0 0" xyz="0.05 0 0"/>
      <mass value="0.022"/>
      <inertia ixx="1e-05" ixy="0.0" ixz="0.0" iyy="1.88947916667e-05" iyz="0.0" izz="1.93630983333e-05"/>
    </inertial>
  </link>
  <gazebo>
    <joint name="leg_l_loop_joint02" type="revolute">
      <parent>leg_l_link07</parent>
      <child>leg_l_link09</child>
      <pose>0.1 0 0 0 0 0</pose>
      <axis>
        <xyz>0 -1 0</xyz>
        <limit>
          <lower>-3.1</lower>
          <upper>3.1</upper>
        </limit>
        <dynamics>
          <spring_reference>0</spring_reference>
          <spring_stiffness>0</spring_stiffness>
        </dynamics>
        <use_parent_model_frame>1</use_parent_model_frame>
      </axis>
      <physics>
        <ode>
          <implicit_spring_damper>1</implicit_spring_damper>
          <cfm_damping>0</cfm_damping>
          <limit>
            <cfm>1e-7</cfm>
            <erp>0.8</erp>
          </limit>
        </ode>
      </physics>
    </joint>
  </gazebo>
  <joint name="leg_l_joint06" type="revolute">
    <parent link="leg_l_link09"/>
    <child link="leg_l_link06"/>
    <origin rpy="0 1.57079633 0" xyz="0.07118 0 0.00834"/>
    <axis xyz="0 -1 0"/>
    <limit effort="1000.0" lower="-1.5" upper="1.0" velocity="10.0"/>
    <dynamics damping="0.0" friction="0.0"/>
    <!-- Only for Rviz. Not correct. -->
    <mimic joint="leg_l_joint03" multiplier="1" offset="0"/>
  </joint>
  <link name="leg_l_link06">
    <visual>
      <origin rpy="0 0 0" xyz="-0.1 0 0"/>
      <geometry>
        <mesh filename="package://ginko_description/meshes/ginko_xm540/obj/leg_r_link06.obj"/>
      </geometry>
    </visual>
    <collision>
      <origin rpy="0 0 0" xyz="-0.05 0 0"/>
      <geometry>
        <box size="0.1 0.0181 0.017"/>
      </geometry>
    </collision>
    <inertial>
      <origin rpy="0 0 0" xyz="-0.05 0 0"/>
      <mass value="0.015"/>
      <inertia ixx="1e-05" ixy="0.0" ixz="0.0" iyy="1.286125e-05" iyz="0.0" izz="1.29095125e-05"/>
    </inertial>
  </link>
  <gazebo>
    <joint name="leg_l_loop_joint03" type="revolute">
      <parent>leg_l_link04</parent>
      <child>leg_l_link06</child>
      <pose>-0.1 0 0 0 0 0</pose>
      <axis>
        <xyz>0 -1 0</xyz>
        <limit>
          <lower>-3.1</lower>
          <upper>3.1</upper>
        </limit>
        <dynamics>
          <spring_reference>0</spring_reference>
          <spring_stiffness>0</spring_stiffness>
        </dynamics>
        <use_parent_model_frame>1</use_parent_model_frame>
      </axis>
      <physics>
        <ode>
          <implicit_spring_damper>1</implicit_spring_damper>
          <cfm_damping>0</cfm_damping>
          <limit>
            <cfm>1e-7</cfm>
            <erp>0.8</erp>
          </limit>
        </ode>
      </physics>
    </joint>
  </gazebo>
  <joint name="leg_l_joint11" type="revolute">
    <parent link="leg_l_link10"/>
    <child link="leg_l_link11"/>
    <origin rpy="0 0 0" xyz="-0.01675 0 -0.02475"/>
    <axis xyz="1 0 0"/>
    <limit effort="1000.0" lower="-3.1" upper="3.1" velocity="1000.0"/>
    <dynamics damping="0.0" friction="0.0"/>
  </joint>
  <link name="leg_l_link11">
    <visual>
      <origin rpy="0 0 0" xyz="0 0 0"/>
      <geometry>
        <mesh filename="package://ginko_description/meshes/ginko_xm540/obj/leg_l_link11.obj"/>
      </geometry>
    </visual>
    <collision>
      <origin rpy="0 0 0" xyz="0 0.00835 -0.015"/>
      <geometry>
        <box size="0.0485 0.0567 0.044"/>
      </geometry>
    </collision>
    <inertial>
      <origin rpy="0 0 0" xyz="0 0.00835 -0.015"/>
      <mass value="0.136"/>
      <inertia ixx="5.83767533333e-05" ixy="0.0" ixz="0.0" iyy="4.86001666667e-05" iyz="0.0" izz="6.30942533333e-05"/>
    </inertial>
  </link>
  <joint name="leg_l_joint12" type="revolute">
    <parent link="leg_l_link11"/>
    <child link="leg_l_link12_1"/>
    <origin rpy="0 0 0" xyz="0 0 -0.0625"/>
    <axis xyz="0 0 -1"/>
    <limit effort="1000.0" lower="-3.1" upper="3.1" velocity="1000.0"/>
    <dynamics damping="0.0" friction="0.0"/>
  </joint>
  <link name="leg_l_link12_1">
    <visual>
      <origin rpy="0 0 0" xyz="0 0 0"/>
      <geometry>
        <mesh filename="package://ginko_description/meshes/ginko_xm540/obj/leg_r_link12_1.obj"/>
      </geometry>
    </visual>
    <collision>
      <origin rpy="0 0 0" xyz="0 0 0.00965"/>
      <geometry>
        <box size="0.038 0.038 0.0272"/>
      </geometry>
    </collision>
    <inertial>
      <origin rpy="0 0 0" xyz="0 0 0.00965"/>
      <mass value="0.0316"/>
      <inertia ixx="1e-05" ixy="0.0" ixz="0.0" iyy="1e-05" iyz="0.0" izz="1e-05"/>
    </inertial>
  </link>
  <joint name="leg_l_ft_sensor_joint" type="fixed">
    <parent link="leg_l_link12_1"/>
    <child link="leg_l_link12_2"/>
    <origin rpy="0 0 0" xyz="0 0 0"/>
  </joint>
  <gazebo reference="leg_l_ft_sensor_joint">
    <preserveFixedJoint>true</preserveFixedJoint>
  </gazebo>
  <link name="leg_l_link12_2">
    <visual>
      <origin rpy="0 0 0" xyz="0 0 -0.01225"/>
      <geometry>
        <mesh filename="package://ginko_description/meshes/ginko_xm540/obj/leg_r_link12_2.obj"/>
      </geometry>
    </visual>
    <collision>
      <origin rpy="0 0 0" xyz="0 0 -0.00025"/>
      <geometry>
        <box size="0.12 0.075 0.024"/>
      </geometry>
    </collision>
    <inertial>
      <origin rpy="0 0 0" xyz="0 0 -0.00025"/>
      <mass value="0.0486"/>
      <inertia ixx="2.511405e-05" ixy="0.0" ixz="0.0" iyy="6.06528e-05" iyz="0.0" izz="8.110125e-05"/>
    </inertial>
  </link>
  <gazebo reference="leg_l_joint01">
    <implicitSpringDamper>1</implicitSpringDamper>
  </gazebo>
  <transmission name="leg_l_joint01_trans">
    <type>transmission_interface/SimpleTransmission</type>
    <joint name="leg_l_joint01">
      <hardwareInterface>hardware_interface/PositionJointInterface</hardwareInterface>
    </joint>
    <actuator name="leg_l_joint01_motor">
      <hardwareInterface>hardware_interface/PositionJointInterface</hardwareInterface>
      <mechanicalReduction>1</mechanicalReduction>
    </actuator>
  </transmission>
  <gazebo reference="leg_l_joint02">
    <implicitSpringDamper>1</implicitSpringDamper>
  </gazebo>
  <transmission name="leg_l_joint02_trans">
    <type>transmission_interface/SimpleTransmission</type>
    <joint name="leg_l_joint02">
      <hardwareInterface>hardware_interface/PositionJointInterface</hardwareInterface>
    </joint>
    <actuator name="leg_l_joint02_motor">
      <hardwareInterface>hardware_interface/PositionJointInterface</hardwareInterface>
      <mechanicalReduction>1</mechanicalReduction>
    </actuator>
  </transmission>
  <gazebo reference="leg_l_joint03">
    <implicitSpringDamper>1</implicitSpringDamper>
  </gazebo>
  <transmission name="leg_l_joint03_trans">
    <type>transmission_interface/SimpleTransmission</type>
    <joint name="leg_l_joint03">
      <hardwareInterface>hardware_interface/PositionJointInterface</hardwareInterface>
    </joint>
    <actuator name="leg_l_joint03_motor">
      <hardwareInterface>hardware_interface/PositionJointInterface</hardwareInterface>
      <mechanicalReduction>1</mechanicalReduction>
    </actuator>
  </transmission>
  <gazebo reference="leg_l_joint04">
    <implicitSpringDamper>1</implicitSpringDamper>
  </gazebo>
  <transmission name="leg_l_joint04_trans">
    <type>transmission_interface/SimpleTransmission</type>
    <joint name="leg_l_joint04">
      <hardwareInterface>hardware_interface/PositionJointInterface</hardwareInterface>
    </joint>
    <actuator name="leg_l_joint04_motor">
      <hardwareInterface>hardware_interface/PositionJointInterface</hardwareInterface>
      <mechanicalReduction>1</mechanicalReduction>
    </actuator>
  </transmission>
  <gazebo reference="leg_l_joint05">
    <implicitSpringDamper>1</implicitSpringDamper>
  </gazebo>
  <gazebo reference="leg_l_joint06">
    <implicitSpringDamper>1</implicitSpringDamper>
  </gazebo>
  <gazebo reference="leg_l_joint07">
    <implicitSpringDamper>1</implicitSpringDamper>
  </gazebo>
  <gazebo reference="leg_l_joint08">
    <implicitSpringDamper>1</implicitSpringDamper>
  </gazebo>
  <gazebo reference="leg_l_joint09">
    <implicitSpringDamper>1</implicitSpringDamper>
  </gazebo>
  <gazebo reference="leg_l_joint10">
    <implicitSpringDamper>1</implicitSpringDamper>
  </gazebo>
  <gazebo reference="leg_l_joint11">
    <implicitSpringDamper>1</implicitSpringDamper>
  </gazebo>
  <transmission name="leg_l_joint11_trans">
    <type>transmission_interface/SimpleTransmission</type>
    <joint name="leg_l_joint11">
      <hardwareInterface>hardware_interface/PositionJointInterface</hardwareInterface>
    </joint>
    <actuator name="leg_l_joint11_motor">
      <hardwareInterface>hardware_interface/PositionJointInterface</hardwareInterface>
      <mechanicalReduction>1</mechanicalReduction>
    </actuator>
  </transmission>
  <gazebo reference="leg_l_joint12">
    <implicitSpringDamper>1</implicitSpringDamper>
  </gazebo>
  <transmission name="leg_l_joint12_trans">
    <type>transmission_interface/SimpleTransmission</type>
    <joint name="leg_l_joint12">
      <hardwareInterface>hardware_interface/PositionJointInterface</hardwareInterface>
    </joint>
    <actuator name="leg_l_joint12_motor">
      <hardwareInterface>hardware_interface/PositionJointInterface</hardwareInterface>
      <mechanicalReduction>1</mechanicalReduction>
    </actuator>
  </transmission>
  <gazebo reference="leg_l_ft_sensor_joint">
    <implicitSpringDamper>1</implicitSpringDamper>
  </gazebo>
  <gazebo reference="leg_l_link01">
    <kp>1000000.0</kp>
    <kd>100.0</kd>
    <mu1>0.0</mu1>
    <maxVel>10.0</maxVel>
    <minDepth>0.0001</minDepth>
    <maxContacts>6</maxContacts>
    <selfCollide>false</selfCollide>
    <dampingFactor>0</dampingFactor>
  </gazebo>
  <gazebo reference="leg_l_link02">
    <kp>1000000.0</kp>
    <kd>100.0</kd>
    <mu1>0.1</mu1>
    <maxVel>10.0</maxVel>
    <minDepth>0.0001</minDepth>
    <maxContacts>6</maxContacts>
    <selfCollide>false</selfCollide>
    <dampingFactor>0</dampingFactor>
  </gazebo>
  <gazebo reference="leg_l_link03">
    <kp>1000000.0</kp>
    <kd>100.0</kd>
    <mu1>0.0</mu1>
    <maxVel>10.0</maxVel>
    <minDepth>0.0001</minDepth>
    <maxContacts>6</maxContacts>
    <selfCollide>false</selfCollide>
    <dampingFactor>0</dampingFactor>
  </gazebo>
  <gazebo reference="leg_l_link04">
    <kp>1000000.0</kp>
    <kd>100.0</kd>
    <mu1>0.0</mu1>
    <maxVel>10.0</maxVel>
    <minDepth>0.0001</minDepth>
    <maxContacts>6</maxContacts>
    <selfCollide>false</selfCollide>
    <dampingFactor>0</dampingFactor>
  </gazebo>
  <gazebo reference="leg_l_link05">
    <kp>1000000.0</kp>
    <kd>100.0</kd>
    <mu1>0.0</mu1>
    <maxVel>10.0</maxVel>
    <minDepth>0.0001</minDepth>
    <maxContacts>6</maxContacts>
    <selfCollide>false</selfCollide>
    <dampingFactor>0</dampingFactor>
  </gazebo>
  <gazebo reference="leg_l_link06">
    <kp>1000000.0</kp>
    <kd>100.0</kd>
    <mu1>0.0</mu1>
    <maxVel>10.0</maxVel>
    <minDepth>0.0001</minDepth>
    <maxContacts>6</maxContacts>
    <selfCollide>false</selfCollide>
    <dampingFactor>0</dampingFactor>
  </gazebo>
  <gazebo reference="leg_l_link07">
    <kp>1000000.0</kp>
    <kd>100.0</kd>
    <mu1>0.01</mu1>
    <maxVel>10.0</maxVel>
    <minDepth>0.0001</minDepth>
    <maxContacts>6</maxContacts>
    <selfCollide>false</selfCollide>
    <dampingFactor>0</dampingFactor>
  </gazebo>
  <gazebo reference="leg_l_link08">
    <kp>1000000.0</kp>
    <kd>100.0</kd>
    <mu1>0.0</mu1>
    <maxVel>10.0</maxVel>
    <minDepth>0.0001</minDepth>
    <maxContacts>6</maxContacts>
    <selfCollide>false</selfCollide>
    <dampingFactor>0</dampingFactor>
  </gazebo>
  <gazebo reference="leg_l_link09">
    <kp>1000000.0</kp>
    <kd>100.0</kd>
    <mu1>0.0</mu1>
    <maxVel>10.0</maxVel>
    <minDepth>0.0001</minDepth>
    <maxContacts>6</maxContacts>
    <selfCollide>false</selfCollide>
    <dampingFactor>0</dampingFactor>
  </gazebo>
  <gazebo reference="leg_l_link10">
    <kp>1000000.0</kp>
    <kd>100.0</kd>
    <mu1>0.1</mu1>
    <maxVel>10.0</maxVel>
    <minDepth>0.0001</minDepth>
    <maxContacts>6</maxContacts>
    <selfCollide>false</selfCollide>
    <dampingFactor>0</dampingFactor>
  </gazebo>
  <gazebo reference="leg_l_link11">
    <kp>1000000.0</kp>
    <kd>100.0</kd>
    <mu1>0.0</mu1>
    <maxVel>10.0</maxVel>
    <minDepth>0.0001</minDepth>
    <maxContacts>6</maxContacts>
    <selfCollide>false</selfCollide>
    <dampingFactor>0</dampingFactor>
  </gazebo>
  <gazebo reference="leg_l_link12_1">
    <kp>1000000.0</kp>
    <kd>100.0</kd>
    <mu1>0.0</mu1>
    <maxVel>10.0</maxVel>
    <minDepth>0.0001</minDepth>
    <maxContacts>6</maxContacts>
    <selfCollide>false</selfCollide>
    <dampingFactor>0</dampingFactor>
  </gazebo>
  <gazebo reference="leg_l_link12_2">
    <kp>1000000.0</kp>
    <kd>100.0</kd>
    <mu1>0.5</mu1>
    <maxVel>10.0</maxVel>
    <minDepth>0.0001</minDepth>
    <maxContacts>6</maxContacts>
    <selfCollide>false</selfCollide>
    <dampingFactor>0</dampingFactor>
  </gazebo>
  <!-- Link conencts from body. Shoulder first. -->
  <joint name="arm_r_joint01" type="revolute">
    <parent link="chest_link01"/>
    <child link="arm_r_link01"/>
    <origin rpy="0 0 0" xyz="0 -0.087 0"/>
    <axis xyz="0 -1 0"/>
    <limit effort="1000.0" lower="-3.1" upper="3.1" velocity="10.0"/>
    <dynamics damping="0.0" friction="0.0"/>
  </joint>
  <link name="arm_r_link01">
    <visual>
      <origin rpy="0 0 0" xyz="0 -0.04 0"/>
      <geometry>
        <mesh filename="package://ginko_description/meshes/ginko_xm540/obj/arm_r_link01.obj"/>
      </geometry>
    </visual>
    <collision>
      <origin rpy="0 0 0" xyz="0 -0.03475 0"/>
      <geometry>
        <box size="0.052 0.05 0.04"/>
      </geometry>
    </collision>
    <inertial>
      <origin rpy="0 0 0" xyz="0 -0.03475 0"/>
      <mass value="0.01"/>
      <inertia ixx="1e-05" ixy="0.0" ixz="0.0" iyy="1e-05" iyz="0.0" izz="1e-05"/>
    </inertial>
  </link>
  <joint name="arm_r_joint02" type="revolute">
    <parent link="arm_r_link01"/>
    <child link="arm_r_link02"/>
    <origin rpy="0 0 0" xyz="0 -0.04 0"/>
    <axis xyz="1 0 0"/>
    <limit effort="1000.0" lower="-3.1" upper="3.1" velocity="10.0"/>
    <dynamics damping="0.0" friction="0.0"/>
  </joint>
  <link name="arm_r_link02">
    <visual>
      <origin rpy="0 0 0" xyz="0 0 0"/>
      <geometry>
        <mesh filename="package://ginko_description/meshes/ginko_xm540/obj/arm_r_link02.obj"/>
      </geometry>
    </visual>
    <collision>
      <origin rpy="0 0 0" xyz="-0.006625 -0.04275 -0.01775"/>
      <geometry>
        <box size="0.05725 0.113 0.069"/>
      </geometry>
    </collision>
    <inertial>
      <origin rpy="0 0 0" xyz="-0.006625 -0.04275 -0.01775"/>
      <mass value="0.35"/>
      <inertia ixx="0.000511291666667" ixy="0.0" ixz="0.0" iyy="0.000234458072917" iyz="0.0" izz="0.000468024739583"/>
    </inertial>
  </link>
  <joint name="arm_r_joint03" type="revolute">
    <parent link="arm_r_link02"/>
    <child link="arm_r_link03"/>
    <origin rpy="0 1.5708 0" xyz="0 -0.03325 -0.038"/>
    <axis xyz="0 1 0"/>
    <limit effort="1000.0" lower="-3.1" upper="3.1" velocity="10.0"/>
    <dynamics damping="0.0" friction="0.0"/>
  </joint>
  <link name="arm_r_link03">
    <visual>
      <origin rpy="0 0 0" xyz="0 0 0"/>
      <geometry>
        <mesh filename="package://ginko_description/meshes/ginko_xm540/obj/arm_r_link03.obj"/>
      </geometry>
    </visual>
    <collision>
      <origin rpy="0 0 0" xyz="0.110 0 0"/>
      <geometry>
        <box size="0.251 0.02 0.032"/>
      </geometry>
    </collision>
    <inertial>
      <origin rpy="0 0 0" xyz="0.110 0 0"/>
      <mass value="0.122"/>
      <inertia ixx="1.44773333333e-05" ixy="0.0" ixz="0.0" iyy="0.000650920833333" iyz="0.0" izz="0.000644576833333"/>
    </inertial>
  </link>
  <joint name="arm_r_joint04" type="revolute">
    <parent link="arm_r_link02"/>
    <child link="arm_r_link04"/>
    <origin rpy="0 1.5708 0" xyz="0 -0.03325 -0.038"/>
    <axis xyz="0 1 0"/>
    <limit effort="1000.0" lower="-3.1" upper="3.1" velocity="10.0"/>
    <dynamics damping="0.0" friction="0.0"/>
  </joint>
  <link name="arm_r_link04">
    <visual>
      <origin rpy="0 0 0" xyz="0 0 0"/>
      <geometry>
        <mesh filename="package://ginko_description/meshes/ginko_xm540/obj/arm_r_link04.obj"/>
      </geometry>
    </visual>
    <collision>
      <origin rpy="0 0 0" xyz="0.110 0 0"/>
      <geometry>
        <box size="0.251 0.02 0.032"/>
      </geometry>
    </collision>
    <inertial>
      <origin rpy="0 0 0" xyz="0.110 0 0"/>
      <mass value="0.122"/>
      <inertia ixx="1.44773333333e-05" ixy="0.0" ixz="0.0" iyy="0.000650920833333" iyz="0.0" izz="0.000644576833333"/>
    </inertial>
  </link>
  <gazebo reference="arm_r_joint01">
    <implicitSpringDamper>1</implicitSpringDamper>
  </gazebo>
  <transmission name="arm_r_joint01_trans">
    <type>transmission_interface/SimpleTransmission</type>
    <joint name="arm_r_joint01">
      <hardwareInterface>hardware_interface/PositionJointInterface</hardwareInterface>
    </joint>
    <actuator name="arm_r_joint01_motor">
      <hardwareInterface>hardware_interface/PositionJointInterface</hardwareInterface>
      <mechanicalReduction>1</mechanicalReduction>
    </actuator>
  </transmission>
  <gazebo reference="arm_r_link01">
    <kp>1000000.0</kp>
    <kd>100.0</kd>
    <mu1>0.0</mu1>
    <maxVel>10.0</maxVel>
    <minDepth>0.0001</minDepth>
    <maxContacts>6</maxContacts>
    <selfCollide>false</selfCollide>
    <dampingFactor>0</dampingFactor>
  </gazebo>
  <gazebo reference="arm_r_joint02">
    <implicitSpringDamper>1</implicitSpringDamper>
  </gazebo>
  <transmission name="arm_r_joint02_trans">
    <type>transmission_interface/SimpleTransmission</type>
    <joint name="arm_r_joint02">
      <hardwareInterface>hardware_interface/PositionJointInterface</hardwareInterface>
    </joint>
    <actuator name="arm_r_joint02_motor">
      <hardwareInterface>hardware_interface/PositionJointInterface</hardwareInterface>
      <mechanicalReduction>1</mechanicalReduction>
    </actuator>
  </transmission>
  <gazebo reference="arm_r_link02">
    <kp>1000000.0</kp>
    <kd>100.0</kd>
    <mu1>0.1</mu1>
    <maxVel>10.0</maxVel>
    <minDepth>0.0001</minDepth>
    <maxContacts>6</maxContacts>
    <selfCollide>false</selfCollide>
    <dampingFactor>0</dampingFactor>
  </gazebo>
  <gazebo reference="arm_r_joint03">
    <implicitSpringDamper>1</implicitSpringDamper>
  </gazebo>
  <transmission name="arm_r_joint03_trans">
    <type>transmission_interface/SimpleTransmission</type>
    <joint name="arm_r_joint03">
      <hardwareInterface>hardware_interface/PositionJointInterface</hardwareInterface>
    </joint>
    <actuator name="arm_r_joint03_motor">
      <hardwareInterface>hardware_interface/PositionJointInterface</hardwareInterface>
      <mechanicalReduction>1</mechanicalReduction>
    </actuator>
  </transmission>
  <gazebo reference="arm_r_link03">
    <kp>1000000.0</kp>
    <kd>100.0</kd>
    <mu1>0.0</mu1>
    <maxVel>10.0</maxVel>
    <minDepth>0.0001</minDepth>
    <maxContacts>6</maxContacts>
    <selfCollide>false</selfCollide>
    <dampingFactor>0</dampingFactor>
  </gazebo>
  <gazebo reference="arm_r_joint04">
    <implicitSpringDamper>1</implicitSpringDamper>
  </gazebo>
  <transmission name="arm_r_joint04_trans">
    <type>transmission_interface/SimpleTransmission</type>
    <joint name="arm_r_joint04">
      <hardwareInterface>hardware_interface/PositionJointInterface</hardwareInterface>
    </joint>
    <actuator name="arm_r_joint04_motor">
      <hardwareInterface>hardware_interface/PositionJointInterface</hardwareInterface>
      <mechanicalReduction>1</mechanicalReduction>
    </actuator>
  </transmission>
  <gazebo reference="arm_r_link04">
    <kp>1000000.0</kp>
    <kd>100.0</kd>
    <mu1>0.0</mu1>
    <maxVel>10.0</maxVel>
    <minDepth>0.0001</minDepth>
    <maxContacts>6</maxContacts>
    <selfCollide>false</selfCollide>
    <dampingFactor>0</dampingFactor>
  </gazebo>
  <!-- Link conencts from body. Shoulder first. -->
  <joint name="arm_l_joint01" type="revolute">
    <parent link="chest_link01"/>
    <child link="arm_l_link01"/>
    <origin rpy="0 0 0" xyz="0 0.087 0"/>
    <axis xyz="0 1 0"/>
    <limit effort="1000.0" lower="-3.1" upper="3.1" velocity="10.0"/>
    <dynamics damping="0.0" friction="0.0"/>
  </joint>
  <link name="arm_l_link01">
    <visual>
      <origin rpy="0 0 0" xyz="0 0.04 0"/>
      <geometry>
        <mesh filename="package://ginko_description/meshes/ginko_xm540/obj/arm_l_link01.obj"/>
      </geometry>
    </visual>
    <collision>
      <origin rpy="0 0 0" xyz="0 0.03475 0"/>
      <geometry>
        <box size="0.052 0.05 0.04"/>
      </geometry>
    </collision>
    <inertial>
      <origin rpy="0 0 0" xyz="0 0.03475 0"/>
      <mass value="0.01"/>
      <inertia ixx="1e-05" ixy="0.0" ixz="0.0" iyy="1e-05" iyz="0.0" izz="1e-05"/>
    </inertial>
  </link>
  <joint name="arm_l_joint02" type="revolute">
    <parent link="arm_l_link01"/>
    <child link="arm_l_link02"/>
    <origin rpy="0 0 0" xyz="0 0.04 0"/>
    <axis xyz="1 0 0"/>
    <limit effort="1000.0" lower="-3.1" upper="3.1" velocity="10.0"/>
    <dynamics damping="0.0" friction="0.0"/>
  </joint>
  <link name="arm_l_link02">
    <visual>
      <origin rpy="0 0 0" xyz="0 0 0"/>
      <geometry>
        <mesh filename="package://ginko_description/meshes/ginko_xm540/obj/arm_l_link02.obj"/>
      </geometry>
    </visual>
    <collision>
      <origin rpy="0 0 0" xyz="-0.006625 0.04275 -0.01775"/>
      <geometry>
        <box size="0.05725 0.113 0.069"/>
      </geometry>
    </collision>
    <inertial>
      <origin rpy="0 0 0" xyz="-0.006625 0.04275 -0.01775"/>
      <mass value="0.35"/>
      <inertia ixx="0.000511291666667" ixy="0.0" ixz="0.0" iyy="0.000234458072917" iyz="0.0" izz="0.000468024739583"/>
    </inertial>
  </link>
  <joint name="arm_l_joint03" type="revolute">
    <parent link="arm_l_link02"/>
    <child link="arm_l_link03"/>
    <origin rpy="0 1.5708 0" xyz="0 0.03325 -0.038"/>
    <axis xyz="0 -1 0"/>
    <limit effort="1000.0" lower="-3.1" upper="3.1" velocity="10.0"/>
    <dynamics damping="0.0" friction="0.0"/>
  </joint>
  <link name="arm_l_link03">
    <visual>
      <origin rpy="0 0 0" xyz="0 0 0"/>
      <geometry>
        <mesh filename="package://ginko_description/meshes/ginko_xm540/obj/arm_r_link03.obj"/>
      </geometry>
    </visual>
    <collision>
      <origin rpy="0 0 0" xyz="0.110 0 0"/>
      <geometry>
        <box size="0.251 0.02 0.032"/>
      </geometry>
    </collision>
    <inertial>
      <origin rpy="0 0 0" xyz="0.110 0 0"/>
      <mass value="0.122"/>
      <inertia ixx="1.44773333333e-05" ixy="0.0" ixz="0.0" iyy="0.000650920833333" iyz="0.0" izz="0.000644576833333"/>
    </inertial>
  </link>
  <joint name="arm_l_joint04" type="revolute">
    <parent link="arm_l_link02"/>
    <child link="arm_l_link04"/>
    <origin rpy="0 1.5708 0" xyz="0 0.03325 -0.038"/>
    <axis xyz="0 -1 0"/>
    <limit effort="1000.0" lower="-3.1" upper="3.1" velocity="10.0"/>
    <dynamics damping="0.0" friction="0.0"/>
  </joint>
  <link name="arm_l_link04">
    <visual>
      <origin rpy="0 0 0" xyz="0 0 0"/>
      <geometry>
        <mesh filename="package://ginko_description/meshes/ginko_xm540/obj/arm_r_link04.obj"/>
      </geometry>
    </visual>
    <collision>
      <origin rpy="0 0 0" xyz="0.110 0 0"/>
      <geometry>
        <box size="0.251 0.02 0.032"/>
      </geometry>
    </collision>
    <inertial>
      <origin rpy="0 0 0" xyz="0.110 0 0"/>
      <mass value="0.122"/>
      <inertia ixx="1.44773333333e-05" ixy="0.0" ixz="0.0" iyy="0.000650920833333" iyz="0.0" izz="0.000644576833333"/>
    </inertial>
  </link>
  <gazebo reference="arm_l_joint01">
    <implicitSpringDamper>1</implicitSpringDamper>
  </gazebo>
  <transmission name="arm_l_joint01_trans">
    <type>transmission_interface/SimpleTransmission</type>
    <joint name="arm_l_joint01">
      <hardwareInterface>hardware_interface/PositionJointInterface</hardwareInterface>
    </joint>
    <actuator name="arm_l_joint01_motor">
      <hardwareInterface>hardware_interface/PositionJointInterface</hardwareInterface>
      <mechanicalReduction>1</mechanicalReduction>
    </actuator>
  </transmission>
  <gazebo reference="arm_l_link01">
    <kp>1000000.0</kp>
    <kd>100.0</kd>
    <mu1>0.0</mu1>
    <maxVel>10.0</maxVel>
    <minDepth>0.0001</minDepth>
    <maxContacts>6</maxContacts>
    <selfCollide>false</selfCollide>
    <dampingFactor>0</dampingFactor>
  </gazebo>
  <gazebo reference="arm_l_joint02">
    <implicitSpringDamper>1</implicitSpringDamper>
  </gazebo>
  <transmission name="arm_l_joint02_trans">
    <type>transmission_interface/SimpleTransmission</type>
    <joint name="arm_l_joint02">
      <hardwareInterface>hardware_interface/PositionJointInterface</hardwareInterface>
    </joint>
    <actuator name="arm_l_joint02_motor">
      <hardwareInterface>hardware_interface/PositionJointInterface</hardwareInterface>
      <mechanicalReduction>1</mechanicalReduction>
    </actuator>
  </transmission>
  <gazebo reference="arm_l_link02">
    <kp>1000000.0</kp>
    <kd>100.0</kd>
    <mu1>0.1</mu1>
    <maxVel>10.0</maxVel>
    <minDepth>0.0001</minDepth>
    <maxContacts>6</maxContacts>
    <selfCollide>false</selfCollide>
    <dampingFactor>0</dampingFactor>
  </gazebo>
  <gazebo reference="arm_l_joint03">
    <implicitSpringDamper>1</implicitSpringDamper>
  </gazebo>
  <transmission name="arm_l_joint03_trans">
    <type>transmission_interface/SimpleTransmission</type>
    <joint name="arm_l_joint03">
      <hardwareInterface>hardware_interface/PositionJointInterface</hardwareInterface>
    </joint>
    <actuator name="arm_l_joint03_motor">
      <hardwareInterface>hardware_interface/PositionJointInterface</hardwareInterface>
      <mechanicalReduction>1</mechanicalReduction>
    </actuator>
  </transmission>
  <gazebo reference="arm_l_link03">
    <kp>1000000.0</kp>
    <kd>100.0</kd>
    <mu1>0.0</mu1>
    <maxVel>10.0</maxVel>
    <minDepth>0.0001</minDepth>
    <maxContacts>6</maxContacts>
    <selfCollide>false</selfCollide>
    <dampingFactor>0</dampingFactor>
  </gazebo>
  <gazebo reference="arm_l_joint04">
    <implicitSpringDamper>1</implicitSpringDamper>
  </gazebo>
  <transmission name="arm_l_joint04_trans">
    <type>transmission_interface/SimpleTransmission</type>
    <joint name="arm_l_joint04">
      <hardwareInterface>hardware_interface/PositionJointInterface</hardwareInterface>
    </joint>
    <actuator name="arm_l_joint04_motor">
      <hardwareInterface>hardware_interface/PositionJointInterface</hardwareInterface>
      <mechanicalReduction>1</mechanicalReduction>
    </actuator>
  </transmission>
  <gazebo reference="arm_l_link04">
    <kp>1000000.0</kp>
    <kd>100.0</kd>
    <mu1>0.0</mu1>
    <maxVel>10.0</maxVel>
    <minDepth>0.0001</minDepth>
    <maxContacts>6</maxContacts>
    <selfCollide>false</selfCollide>
    <dampingFactor>0</dampingFactor>
  </gazebo>
  <gazebo>
    <plugin filename="libgazebo_dc_motor.so" name="gazebo_ros_control">
      <robotNamespace>ginko</robotNamespace>
      <robotSimType>gazebo_dc_motor/DefaultRobotHWSim</robotSimType>
      <legacyModeNS>false</legacyModeNS>
    </plugin>
  </gazebo>
  <!-- <xacro:imu_xacro model_mode="$(arg model_mode)"/> -->
  <!-- <xacro:urg_xacro firame_id="arm_r_urg_link" topic_name="/sensor/urg/right/scan_raw" sensor_name="urg_right"/> -->
  <!-- <xacro:urg_xacro firame_id="arm_l_urg_link" topic_name="/sensor/urg/left/scan_raw" sensor_name="urg_left"/> -->
</robot>
