<?xml version="1.0" ?>
<!-- =================================================================================== -->
<!-- |    This document was autogenerated by xacro from /catkin_ws/src/ginko_ros/ginko_description/xacro/ginko_rs406/ginko.xacro | -->
<!-- |    EDITING THIS FILE BY HAND IS NOT RECOMMENDED                                 | -->
<!-- =================================================================================== -->
<robot name="ginko" xmlns:xacro="http://www.ros.org/wiki/xacro">
  <link name="root_link"/>
  <joint name="root_joint" type="fixed">
    <parent link="root_link"/>
    <child link="body_link0"/>
    <origin rpy="0 0 0" xyz="0 0 0"/>
  </joint>
  <!-- chest -->
  <link name="body_link0">
    <collision>
      <origin rpy="0 0 0" xyz="0 0 0"/>
      <geometry>
        <mesh filename="package://ginko_description/meshes/ginko_rs406/stl/link00_chest.stl"/>
      </geometry>
    </collision>
    <visual>
      <origin rpy="0 0 0" xyz="0 0 0"/>
      <geometry>
        <mesh filename="package://ginko_description/meshes/ginko_rs406/obj/link00_chest.obj"/>
      </geometry>
    </visual>
    <inertial>
      <mass value="1.41502697"/>
      <origin rpy="0 0 0" xyz="0.00008301 0.00000908 0.03819562"/>
      <inertia ixx="0.00248548" ixy="-0.00000074" ixz="0.000003761" iyy="0.00121388" iyz="-0.00000042" izz="0.00287756"/>
    </inertial>
  </link>
  <!-- Joint1 -->
  <joint name="body_joint1" type="revolute">
    <parent link="body_link0"/>
    <child link="body_link1"/>
    <origin rpy="0 0 0" xyz="0.0 0 0"/>
    <axis xyz="0 0 1"/>
    <limit effort="1000.0" lower="-2.6" upper="2.6" velocity="10.0"/>
    <dynamics damping="0.1" friction="0.1"/>
  </joint>
  <!-- waist -->
  <link name="body_link1">
    <collision>
      <origin rpy="0 0 0" xyz="0 0 0"/>
      <geometry>
        <mesh filename="package://ginko_description/meshes/ginko_rs406/stl/link01_waist.stl"/>
      </geometry>
    </collision>
    <visual>
      <origin rpy="0 0 0" xyz="0 0 0"/>
      <geometry>
        <mesh filename="package://ginko_description/meshes/ginko_rs406/obj/link01_waist.obj"/>
      </geometry>
    </visual>
    <inertial>
      <mass value="0.33312665"/>
      <origin rpy="0 0 0" xyz="-0.01135452 -0.00000134 -0.02720222"/>
      <inertia ixx="0.00015328" ixy="0.00000003" ixz="0.00001078" iyy="0.00073745" iyz="0.00000000" izz="0.00073107"/>
    </inertial>
  </link>
  <gazebo reference="body_link0">
    <kp>1000000.0</kp>
    <kd>100.0</kd>
    <mu1>0.1</mu1>
    <maxVel>10.0</maxVel>
    <minDepth>0.0001</minDepth>
    <maxContacts>6</maxContacts>
    <selfCollide>false</selfCollide>
    <dampingFactor>0</dampingFactor>
  </gazebo>
  <gazebo reference="body_joint1">
    <implicitSpringDamper>1</implicitSpringDamper>
  </gazebo>
  <transmission name="body_joint1_trans">
    <type>transmission_interface/SimpleTransmission</type>
    <joint name="body_joint1">
      <hardwareInterface>hardware_interface/PositionJointInterface</hardwareInterface>
    </joint>
    <actuator name="body_joint1_motor">
      <hardwareInterface>hardware_interface/PositionJointInterface</hardwareInterface>
      <mechanicalReduction>1</mechanicalReduction>
    </actuator>
  </transmission>
  <gazebo reference="body_link1">
    <kp>1000000.0</kp>
    <kd>100.0</kd>
    <mu1>0.1</mu1>
    <maxVel>10.0</maxVel>
    <minDepth>0.0001</minDepth>
    <maxContacts>6</maxContacts>
    <selfCollide>false</selfCollide>
    <dampingFactor>0</dampingFactor>
  </gazebo>
  <!-- Link conencts from body. Femoral first. -->
  <joint name="leg_r_joint0" type="revolute">
    <parent link="body_link1"/>
    <child link="leg_r_link0"/>
    <origin rpy="0 0 0" xyz="0.0205 0.0 -0.0409"/>
    <axis xyz="1 0 0"/>
    <limit effort="1000.0" lower="-1.0" upper="0.8" velocity="10.0"/>
    <dynamics damping="0.0" friction="0.3"/>
  </joint>
  <link name="leg_r_link0">
    <collision>
      <origin rpy="0 0 0" xyz="0 0 0"/>
      <geometry>
        <mesh filename="package://ginko_description/meshes/ginko_rs406/stl/link02_r_femoral.stl"/>
      </geometry>
    </collision>
    <visual>
      <origin rpy="0 0 0" xyz="0 0 0"/>
      <geometry>
        <mesh filename="package://ginko_description/meshes/ginko_rs406/obj/link02_r_femoral.obj"/>
      </geometry>
    </visual>
    <inertial>
      <mass value="0.03431457"/>
      <origin rpy="0 0 0" xyz="-0.02905818 -0.03723481 -0.02604954"/>
      <inertia ixx="0.00002441" ixy="0.00000001" ixz="0.00000021" iyy="0.00002285" iyz="0.00000391" izz="0.00002980"/>
    </inertial>
  </link>
  <!-- parallel link (upper-1st) -->
  <joint name="leg_r_joint1" type="revolute">
    <parent link="leg_r_link0"/>
    <child link="leg_r_link1"/>
    <origin rpy="0 0.7854 0" xyz="-0.0176 -0.0175 -0.0481"/>
    <axis xyz="0 1 0"/>
    <limit effort="1000.0" lower="-0.7854" upper="1.3" velocity="10.0"/>
    <dynamics damping="0.0" friction="0.3"/>
  </joint>
  <link name="leg_r_link1">
    <collision>
      <origin rpy="0 0 0" xyz="0 0 0"/>
      <geometry>
        <mesh filename="package://ginko_description/meshes/ginko_rs406/stl/link03_r_leg01.stl"/>
      </geometry>
    </collision>
    <visual>
      <origin rpy="0 0 0" xyz="0 0 0"/>
      <geometry>
        <mesh filename="package://ginko_description/meshes/ginko_rs406/obj/link03_r_leg01.obj"/>
      </geometry>
    </visual>
    <inertial>
      <mass value="0.15115113"/>
      <origin rpy="0 0 0" xyz="0.05000000 -0.02587267 0.00000000"/>
      <inertia ixx="0.00003721" ixy="0.00000000" ixz="0.00000000" iyy="0.00026035" iyz="0.00000000" izz="0.00028077"/>
    </inertial>
  </link>
  <joint name="leg_r_joint3" type="revolute">
    <parent link="leg_r_link1"/>
    <child link="leg_r_link3"/>
    <origin rpy="0 -0.7854 0" xyz="0.1 0.0 0.0"/>
    <axis xyz="0 -1 0"/>
    <limit effort="1000.0" lower="-0.7854" upper="1.3" velocity="10.0"/>
    <dynamics damping="0.0" friction="0.3"/>
    <mimic joint="leg_r_joint1" multiplier="1" offset="0"/>
  </joint>
  <!-- parallel link (upper-2nd) -->
  <joint name="leg_r_joint2" type="revolute">
    <parent link="leg_r_link0"/>
    <child link="leg_r_link2"/>
    <origin rpy="0 0.7854 0" xyz="-0.0389 -0.0175 -0.06015"/>
    <axis xyz="0 1 0"/>
    <limit effort="1000.0" lower="-0.7854" upper="1.3" velocity="10.0"/>
    <dynamics damping="0.0" friction="0.0"/>
    <mimic joint="leg_r_joint1" multiplier="1" offset="0"/>
  </joint>
  <link name="leg_r_link2">
    <collision>
      <origin rpy="0 0 0" xyz="0 0 0"/>
      <geometry>
        <mesh filename="package://ginko_description/meshes/ginko_rs406/stl/link04_r_leg02.stl"/>
      </geometry>
    </collision>
    <visual>
      <origin rpy="0 0 0" xyz="0 0 0"/>
      <geometry>
        <mesh filename="package://ginko_description/meshes/ginko_rs406/obj/link04_r_leg02.obj"/>
      </geometry>
    </visual>
    <inertial>
      <mass value="0.01646643"/>
      <origin rpy="0 0 0" xyz="0.05000000 -0.02495100 -0.00491150"/>
      <inertia ixx="0.00000640" ixy="0.00000000" ixz="0.00000000" iyy="0.00001642" iyz="0.00000000" izz="0.00002264"/>
    </inertial>
  </link>
  <joint name="close_leg_r_joint0" type="revolute">
    <parent link="leg_r_link2"/>
    <child link="dummy0_leg_r_link3"/>
    <origin rpy="0 -0.7854 0" xyz="0.1 0.0 0.0"/>
    <axis xyz="0 -1 0"/>
    <limit effort="1000.0" lower="-0.7854" upper="1.3" velocity="10.0"/>
    <dynamics damping="0.0" friction="0.0"/>
    <mimic joint="leg_r_joint1" multiplier="1" offset="0"/>
  </joint>
  <link name="dummy0_leg_r_link3">
    <inertial>
      <mass value="0.00001"/>
      <origin rpy="0 0 0" xyz="-0.021 0 -0.012"/>
      <inertia ixx="0.00000001" ixy="0.00000000" ixz="0.00000000" iyy="0.00000001" iyz="0.00000000" izz="0.00000001"/>
    </inertial>
  </link>
  <!-- knee -->
  <link name="leg_r_link3">
    <collision>
      <origin rpy="0 0 0" xyz="0 0 0"/>
      <geometry>
        <mesh filename="package://ginko_description/meshes/ginko_rs406/stl/link05_r_knee.stl"/>
      </geometry>
    </collision>
    <visual>
      <origin rpy="0 0 0" xyz="0 0 0"/>
      <geometry>
        <mesh filename="package://ginko_description/meshes/ginko_rs406/obj/link05_r_knee.obj"/>
      </geometry>
    </visual>
    <inertial>
      <mass value="0.01781176"/>
      <origin rpy="0 0 0" xyz="0.00393357 -0.02364163 -0.01930000"/>
      <inertia ixx="0.00001301" ixy="-0.00000008" ixz="0.00000000" iyy="0.00000700" iyz="0.00000000" izz="0.00001388"/>
    </inertial>
  </link>
  <!-- parallel link (lower-1st) -->
  <joint name="leg_r_joint4" type="revolute">
    <parent link="leg_r_link3"/>
    <child link="leg_r_link4"/>
    <origin rpy="0 2.3562 0" xyz="0 0 -0.0386"/>
    <axis xyz="0 1 0"/>
    <limit effort="1000.0" lower="-1.3" upper="0.7854" velocity="10.0"/>
    <dynamics damping="0.0" friction="0.3"/>
  </joint>
  <link name="leg_r_link4">
    <collision>
      <origin rpy="0 0 0" xyz="0 0 0"/>
      <geometry>
        <mesh filename="package://ginko_description/meshes/ginko_rs406/stl/link03_r_leg01.stl"/>
      </geometry>
    </collision>
    <visual>
      <origin rpy="0 0 0" xyz="0 0 0"/>
      <geometry>
        <mesh filename="package://ginko_description/meshes/ginko_rs406/obj/link03_r_leg01.obj"/>
      </geometry>
    </visual>
    <inertial>
      <mass value="0.15115113"/>
      <origin rpy="0 0 0" xyz="0.05000000 -0.02587267 0.00000000"/>
      <inertia ixx="0.00003721" ixy="0.00000000" ixz="0.00000000" iyy="0.00026035" iyz="0.00000000" izz="0.00028077"/>
    </inertial>
  </link>
  <joint name="leg_r_joint6" type="revolute">
    <parent link="leg_r_link4"/>
    <child link="leg_r_link6"/>
    <origin rpy="0 -2.3562 0" xyz="0.1 0.0 0.0"/>
    <axis xyz="0 -1 0"/>
    <limit effort="1000.0" lower="-1.3" upper="0.7854" velocity="10.0"/>
    <dynamics damping="0.0" friction="0.3"/>
    <mimic joint="leg_r_joint4" multiplier="1" offset="0"/>
  </joint>
  <!-- parallel link (lower-2nd) -->
  <joint name="leg_r_joint5" type="revolute">
    <parent link="leg_r_link3"/>
    <child link="leg_r_link5"/>
    <origin rpy="0 2.3562 0" xyz="-0.0213 0 -0.02655"/>
    <axis xyz="0 1 0"/>
    <limit effort="0.0" lower="-1.3" upper="0.7854" velocity="10.0"/>
    <dynamics damping="0.0" friction="0.0"/>
    <mimic joint="leg_r_joint4" multiplier="1" offset="0"/>
  </joint>
  <link name="leg_r_link5">
    <collision>
      <origin rpy="0 0 0" xyz="0 0 0"/>
      <geometry>
        <mesh filename="package://ginko_description/meshes/ginko_rs406/stl/link04_r_leg02.stl"/>
      </geometry>
    </collision>
    <visual>
      <origin rpy="0 0 0" xyz="0 0 0"/>
      <geometry>
        <mesh filename="package://ginko_description/meshes/ginko_rs406/obj/link04_r_leg02.obj"/>
      </geometry>
    </visual>
    <inertial>
      <mass value="0.01646643"/>
      <origin rpy="0 0 0" xyz="0.05000000 -0.02495100 -0.00491150"/>
      <inertia ixx="0.00000640" ixy="0.00000000" ixz="0.00000000" iyy="0.00001642" iyz="0.00000000" izz="0.00002264"/>
    </inertial>
  </link>
  <joint name="close_leg_r_joint1" type="revolute">
    <parent link="leg_r_link5"/>
    <child link="dummy2_leg_r_link6"/>
    <origin rpy="0 -2.3562 0" xyz="0.1 0.0 0.0"/>
    <axis xyz="0 -1 0"/>
    <limit effort="0.0" lower="-1.3" upper="0.7854" velocity="10.0"/>
    <dynamics damping="0.0" friction="0.0"/>
    <mimic joint="leg_r_joint4" multiplier="1" offset="0"/>
  </joint>
  <link name="dummy2_leg_r_link6">
    <inertial>
      <mass value="0.00001"/>
      <origin rpy="0 0 0" xyz="-0.021 0 0.012"/>
      <inertia ixx="0.00000001" ixy="0.00000000" ixz="0.00000000" iyy="0.00000001" iyz="0.00000000" izz="0.00000001"/>
    </inertial>
  </link>
  <!-- toe -->
  <link name="leg_r_link6">
    <collision>
      <origin rpy="0 0 0" xyz="0 0 0"/>
      <geometry>
        <mesh filename="package://ginko_description/meshes/ginko_rs406/stl/link06_r_toe01.stl"/>
      </geometry>
    </collision>
    <visual>
      <origin rpy="0 0 0" xyz="0 0 0"/>
      <geometry>
        <mesh filename="package://ginko_description/meshes/ginko_rs406/obj/link06_r_toe01.obj"/>
      </geometry>
    </visual>
    <inertial>
      <mass value="0.08799204"/>
      <origin rpy="0 0 0" xyz="-0.04166125 -0.02463880 -0.02586249"/>
      <inertia ixx="0.00002815" ixy="0.00000041" ixz="0.00000980" iyy="0.00006846" iyz="0.00000026" izz="0.00006529"/>
    </inertial>
  </link>
  <joint name="leg_r_joint7" type="revolute">
    <parent link="leg_r_link6"/>
    <child link="leg_r_link7"/>
    <origin rpy="0 0 0" xyz="-0.028 -0.02475 -0.0391"/>
    <axis xyz="-1 0 0"/>
    <limit effort="1000.0" lower="-1.6" upper="1.6" velocity="10.0"/>
    <dynamics damping="0.0" friction="0.3"/>
  </joint>
  <link name="leg_r_link7">
    <collision>
      <origin rpy="0 0 0" xyz="0 0 0"/>
      <geometry>
        <mesh filename="package://ginko_description/meshes/ginko_rs406/stl/link07_r_toe02.stl"/>
      </geometry>
    </collision>
    <visual>
      <origin rpy="0 0 0" xyz="0 0 0"/>
      <geometry>
        <mesh filename="package://ginko_description/meshes/ginko_rs406/obj/link07_r_toe02.obj"/>
      </geometry>
    </visual>
    <inertial>
      <mass value="0.10920041"/>
      <origin rpy="0 0 0" xyz="0.02658756 -0.00000053 -0.01782468"/>
      <inertia ixx="0.00003853" ixy="0.00000000" ixz="-0.00000479" iyy="0.00005192" iyz="0.00000000" izz="0.00003521"/>
    </inertial>
  </link>
  <joint name="leg_r_joint8" type="revolute">
    <parent link="leg_r_link7"/>
    <child link="leg_r_link8"/>
    <origin rpy="0 0 0" xyz="0.0342 0 -0.04"/>
    <axis xyz="0 0 1"/>
    <limit effort="1000.0" lower="-2.6" upper="2.6" velocity="10.0"/>
    <dynamics damping="0.0" friction="0.3"/>
  </joint>
  <link name="leg_r_link8">
    <collision>
      <origin rpy="0 0 0" xyz="0 0 -0.003"/>
      <geometry>
        <box size="0.128 0.08 0.006"/>
      </geometry>
    </collision>
    <visual>
      <origin rpy="0 0 0" xyz="0 0 0"/>
      <geometry>
        <mesh filename="package://ginko_description/meshes/ginko_rs406/obj/link08_r_toe03.obj"/>
      </geometry>
    </visual>
    <inertial>
      <mass value="0.05363111"/>
      <origin rpy="0 0 0" xyz="0.00000000 0.00000000 -0.00269342"/>
      <inertia ixx="0.00002877" ixy="0.00000000" ixz="0.00000000" iyy="0.00007083" iyz="-0.00000000" izz="0.00009934"/>
    </inertial>
  </link>
  <joint name="leg_r_toe_joint0" type="fixed">
    <parent link="leg_r_link8"/>
    <child link="leg_r_toe_link0"/>
    <origin rpy="0 0 0" xyz="0.064 0.040 -0.005"/>
  </joint>
  <link name="leg_r_toe_link0"/>
  <joint name="leg_r_toe_joint1" type="fixed">
    <parent link="leg_r_link8"/>
    <child link="leg_r_toe_link1"/>
    <origin rpy="0 0 0" xyz="-0.064 0.040 -0.005"/>
  </joint>
  <link name="leg_r_toe_link1"/>
  <joint name="leg_r_toe_joint2" type="fixed">
    <parent link="leg_r_link8"/>
    <child link="leg_r_toe_link2"/>
    <origin rpy="0 0 0" xyz="-0.064 -0.040 -0.005"/>
  </joint>
  <link name="leg_r_toe_link2"/>
  <joint name="leg_r_toe_joint3" type="fixed">
    <parent link="leg_r_link8"/>
    <child link="leg_r_toe_link3"/>
    <origin rpy="0 0 0" xyz="0.064 -0.040 -0.005"/>
  </joint>
  <link name="leg_r_toe_link3"/>
  <joint name="leg_r_toe_center_joint" type="fixed">
    <parent link="leg_r_link8"/>
    <child link="leg_r_toe_center"/>
    <origin rpy="0 0 0" xyz="0.0 0.0 -0.005"/>
  </joint>
  <link name="leg_r_toe_center"/>
  <gazebo reference="leg_r_link0">
    <kp>1000000.0</kp>
    <kd>100.0</kd>
    <mu1>0.2</mu1>
    <maxVel>10.0</maxVel>
    <minDepth>0.0001</minDepth>
    <maxContacts>6</maxContacts>
    <selfCollide>false</selfCollide>
    <dampingFactor>0</dampingFactor>
  </gazebo>
  <gazebo reference="leg_r_link1">
    <kp>1000000.0</kp>
    <kd>100.0</kd>
    <mu1>0.2</mu1>
    <maxVel>10.0</maxVel>
    <minDepth>0.0001</minDepth>
    <maxContacts>6</maxContacts>
    <selfCollide>false</selfCollide>
    <dampingFactor>0</dampingFactor>
  </gazebo>
  <gazebo reference="leg_r_link3">
    <kp>1000000.0</kp>
    <kd>100.0</kd>
    <mu1>0.2</mu1>
    <maxVel>10.0</maxVel>
    <minDepth>0.0001</minDepth>
    <maxContacts>6</maxContacts>
    <selfCollide>false</selfCollide>
    <dampingFactor>0</dampingFactor>
  </gazebo>
  <gazebo reference="leg_r_link4">
    <kp>1000000.0</kp>
    <kd>100.0</kd>
    <mu1>0.2</mu1>
    <maxVel>10.0</maxVel>
    <minDepth>0.0001</minDepth>
    <maxContacts>6</maxContacts>
    <selfCollide>false</selfCollide>
    <dampingFactor>0</dampingFactor>
  </gazebo>
  <gazebo reference="leg_r_link6">
    <kp>1000000.0</kp>
    <kd>100.0</kd>
    <mu1>0.2</mu1>
    <maxVel>10.0</maxVel>
    <minDepth>0.0001</minDepth>
    <maxContacts>6</maxContacts>
    <selfCollide>false</selfCollide>
    <dampingFactor>0</dampingFactor>
  </gazebo>
  <gazebo reference="leg_r_link7">
    <kp>1000000.0</kp>
    <kd>100.0</kd>
    <mu1>0.2</mu1>
    <maxVel>10.0</maxVel>
    <minDepth>0.0001</minDepth>
    <maxContacts>6</maxContacts>
    <selfCollide>false</selfCollide>
    <dampingFactor>0</dampingFactor>
  </gazebo>
  <!-- <xacro:default_link_collision link_name="leg_r_link8" friction="1.0"/> -->
  <gazebo reference="leg_r_link8">
    <kp>2000000.0</kp>
    <kd>200.0</kd>
    <mu1>1.0</mu1>
    <maxVel>1.0</maxVel>
    <minDepth>0.0001</minDepth>
    <maxContacts>5</maxContacts>
    <selfCollide>true</selfCollide>
    <dampingFactor>0.0</dampingFactor>
  </gazebo>
  <gazebo reference="leg_r_joint0">
    <implicitSpringDamper>1</implicitSpringDamper>
  </gazebo>
  <transmission name="leg_r_joint0_trans">
    <type>transmission_interface/SimpleTransmission</type>
    <joint name="leg_r_joint0">
      <hardwareInterface>hardware_interface/PositionJointInterface</hardwareInterface>
    </joint>
    <actuator name="leg_r_joint0_motor">
      <hardwareInterface>hardware_interface/PositionJointInterface</hardwareInterface>
      <mechanicalReduction>1</mechanicalReduction>
    </actuator>
  </transmission>
  <gazebo reference="leg_r_joint1">
    <implicitSpringDamper>1</implicitSpringDamper>
  </gazebo>
  <transmission name="leg_r_joint1_trans">
    <type>transmission_interface/SimpleTransmission</type>
    <joint name="leg_r_joint1">
      <hardwareInterface>hardware_interface/PositionJointInterface</hardwareInterface>
    </joint>
    <actuator name="leg_r_joint1_motor">
      <hardwareInterface>hardware_interface/PositionJointInterface</hardwareInterface>
      <mechanicalReduction>1</mechanicalReduction>
    </actuator>
  </transmission>
  <gazebo reference="leg_r_joint3">
    <implicitSpringDamper>1</implicitSpringDamper>
  </gazebo>
  <transmission name="leg_r_joint3_trans">
    <type>transmission_interface/SimpleTransmission</type>
    <joint name="leg_r_joint3">
      <hardwareInterface>hardware_interface/PositionJointInterface</hardwareInterface>
    </joint>
    <actuator name="leg_r_joint3_motor">
      <hardwareInterface>hardware_interface/PositionJointInterface</hardwareInterface>
      <mechanicalReduction>1</mechanicalReduction>
    </actuator>
  </transmission>
  <gazebo reference="leg_r_joint4">
    <implicitSpringDamper>1</implicitSpringDamper>
  </gazebo>
  <transmission name="leg_r_joint4_trans">
    <type>transmission_interface/SimpleTransmission</type>
    <joint name="leg_r_joint4">
      <hardwareInterface>hardware_interface/PositionJointInterface</hardwareInterface>
    </joint>
    <actuator name="leg_r_joint4_motor">
      <hardwareInterface>hardware_interface/PositionJointInterface</hardwareInterface>
      <mechanicalReduction>1</mechanicalReduction>
    </actuator>
  </transmission>
  <gazebo reference="leg_r_joint6">
    <implicitSpringDamper>1</implicitSpringDamper>
  </gazebo>
  <transmission name="leg_r_joint6_trans">
    <type>transmission_interface/SimpleTransmission</type>
    <joint name="leg_r_joint6">
      <hardwareInterface>hardware_interface/PositionJointInterface</hardwareInterface>
    </joint>
    <actuator name="leg_r_joint6_motor">
      <hardwareInterface>hardware_interface/PositionJointInterface</hardwareInterface>
      <mechanicalReduction>1</mechanicalReduction>
    </actuator>
  </transmission>
  <gazebo reference="leg_r_joint7">
    <implicitSpringDamper>1</implicitSpringDamper>
  </gazebo>
  <transmission name="leg_r_joint7_trans">
    <type>transmission_interface/SimpleTransmission</type>
    <joint name="leg_r_joint7">
      <hardwareInterface>hardware_interface/PositionJointInterface</hardwareInterface>
    </joint>
    <actuator name="leg_r_joint7_motor">
      <hardwareInterface>hardware_interface/PositionJointInterface</hardwareInterface>
      <mechanicalReduction>1</mechanicalReduction>
    </actuator>
  </transmission>
  <gazebo reference="leg_r_joint8">
    <implicitSpringDamper>1</implicitSpringDamper>
  </gazebo>
  <transmission name="leg_r_joint8_trans">
    <type>transmission_interface/SimpleTransmission</type>
    <joint name="leg_r_joint8">
      <hardwareInterface>hardware_interface/PositionJointInterface</hardwareInterface>
    </joint>
    <actuator name="leg_r_joint8_motor">
      <hardwareInterface>hardware_interface/PositionJointInterface</hardwareInterface>
      <mechanicalReduction>1</mechanicalReduction>
    </actuator>
  </transmission>
  <!-- Link conencts from body. Femoral first. -->
  <joint name="leg_l_joint0" type="revolute">
    <parent link="body_link1"/>
    <child link="leg_l_link0"/>
    <origin rpy="0 0 0" xyz="-0.0404 0.0 -0.0409"/>
    <axis xyz="-1 0 0"/>
    <limit effort="1000.0" lower="-0.8" upper="1.0" velocity="10.0"/>
    <dynamics damping="0.0" friction="0.3"/>
  </joint>
  <link name="leg_l_link0">
    <collision>
      <origin rpy="0 0 0" xyz="0 0 0"/>
      <geometry>
        <mesh filename="package://ginko_description/meshes/ginko_rs406/stl/link02_l_femoral.stl"/>
      </geometry>
    </collision>
    <visual>
      <origin rpy="0 0 0" xyz="0 0 0"/>
      <geometry>
        <mesh filename="package://ginko_description/meshes/ginko_rs406/obj/link02_l_femoral.obj"/>
      </geometry>
    </visual>
    <inertial>
      <mass value="0.03433352"/>
      <origin rpy="0 0 0" xyz="0.02930795 0.03723759 -0.02605386"/>
      <inertia ixx="0.00002443" ixy="-0.00000021" ixz="-0.00000021" iyy="0.00002287" iyz="-0.00000391" izz="0.00002983"/>
    </inertial>
  </link>
  <!-- parallel link (upper-1st) -->
  <joint name="leg_l_joint1" type="revolute">
    <parent link="leg_l_link0"/>
    <child link="leg_l_link1"/>
    <origin rpy="0 0.7854 0" xyz="0.0433 0.0175 -0.0481"/>
    <axis xyz="0 -1 0"/>
    <limit effort="1000.0" lower="-1.3" upper="0.7854" velocity="10.0"/>
    <dynamics damping="0.0" friction="0.3"/>
  </joint>
  <link name="leg_l_link1">
    <collision>
      <origin rpy="0 0 0" xyz="0 0 0"/>
      <geometry>
        <mesh filename="package://ginko_description/meshes/ginko_rs406/stl/link03_l_leg01.stl"/>
      </geometry>
    </collision>
    <visual>
      <origin rpy="0 0 0" xyz="0 0 0"/>
      <geometry>
        <mesh filename="package://ginko_description/meshes/ginko_rs406/obj/link03_l_leg01.obj"/>
      </geometry>
    </visual>
    <inertial>
      <mass value="0.15115113"/>
      <origin rpy="0 0 0" xyz="0.05000000 0.02587267 0.00000000"/>
      <inertia ixx="0.00003721" ixy="0.00000000" ixz="0.00000000" iyy="0.00026035" iyz="0.00000000" izz="0.00028077"/>
    </inertial>
  </link>
  <joint name="leg_l_joint3" type="revolute">
    <parent link="leg_l_link1"/>
    <child link="leg_l_link3"/>
    <origin rpy="0 -0.7854 0" xyz="0.1 0.0 0.0"/>
    <axis xyz="0 1 0"/>
    <limit effort="1000.0" lower="-1.3" upper="0.7854" velocity="10.0"/>
    <dynamics damping="0.0" friction="0.3"/>
    <mimic joint="leg_l_joint1" multiplier="1" offset="0"/>
  </joint>
  <!-- parallel link (upper-2nd) -->
  <joint name="leg_l_joint2" type="revolute">
    <parent link="leg_l_link0"/>
    <child link="leg_l_link2"/>
    <origin rpy="0 0.7854 0" xyz="0.022 0.0175 -0.06015"/>
    <axis xyz="0 -1 0"/>
    <limit effort="1000.0" lower="-1.3" upper="0.7854" velocity="10.0"/>
    <dynamics damping="0.0" friction="0.3"/>
    <mimic joint="leg_l_joint1" multiplier="1" offset="0"/>
  </joint>
  <link name="leg_l_link2">
    <collision>
      <origin rpy="0 0 0" xyz="0 0 0"/>
      <geometry>
        <mesh filename="package://ginko_description/meshes/ginko_rs406/stl/link04_l_leg02.stl"/>
      </geometry>
    </collision>
    <visual>
      <origin rpy="0 0 0" xyz="0 0 0"/>
      <geometry>
        <mesh filename="package://ginko_description/meshes/ginko_rs406/obj/link04_l_leg02.obj"/>
      </geometry>
    </visual>
    <inertial>
      <mass value="0.01646643"/>
      <origin rpy="0 0 0" xyz="0.05000000 0.02495100 -0.00491150"/>
      <inertia ixx="0.00000640" ixy="0.00000000" ixz="0.00000000" iyy="0.00001642" iyz="0.00000000" izz="0.00002264"/>
    </inertial>
  </link>
  <joint name="close_leg_l_joint0" type="revolute">
    <parent link="leg_l_link2"/>
    <child link="dummy0_leg_l_link3"/>
    <origin rpy="0 -0.7854 0" xyz="0.1 0.0 0.0"/>
    <axis xyz="0 1 0"/>
    <limit effort="1000.0" lower="-1.3" upper="0.7854" velocity="10.0"/>
    <dynamics damping="0.0" friction="0.0"/>
    <mimic joint="leg_l_joint1" multiplier="1" offset="0"/>
  </joint>
  <link name="dummy0_leg_l_link3">
    <inertial>
      <mass value="0.00001"/>
      <origin rpy="0 0 0" xyz="-0.021 0 -0.012"/>
      <inertia ixx="0.00000001" ixy="0.00000000" ixz="0.00000000" iyy="0.00000001" iyz="0.00000000" izz="0.00000001"/>
    </inertial>
  </link>
  <!-- knee -->
  <link name="leg_l_link3">
    <collision>
      <origin rpy="0 0 0" xyz="0 0 0"/>
      <geometry>
        <mesh filename="package://ginko_description/meshes/ginko_rs406/stl/link05_l_knee.stl"/>
      </geometry>
    </collision>
    <visual>
      <origin rpy="0 0 0" xyz="0 0 0"/>
      <geometry>
        <mesh filename="package://ginko_description/meshes/ginko_rs406/obj/link05_l_knee.obj"/>
      </geometry>
    </visual>
    <inertial>
      <mass value="0.01781176"/>
      <origin rpy="0 0 0" xyz="0.00393357 0.02364163 -0.01930000"/>
      <inertia ixx="0.00001301" ixy="0.00000008" ixz="0.00000000" iyy="0.00000700" iyz="0.00000000" izz="0.00001388"/>
    </inertial>
  </link>
  <!-- parallel link (lower-1st) -->
  <joint name="leg_l_joint4" type="revolute">
    <parent link="leg_l_link3"/>
    <child link="leg_l_link4"/>
    <origin rpy="0 2.3562 0" xyz="0 0 -0.0386"/>
    <axis xyz="0 -1 0"/>
    <limit effort="1000.0" lower="-0.7854" upper="1.3" velocity="10.0"/>
    <dynamics damping="0.0" friction="0.3"/>
  </joint>
  <link name="leg_l_link4">
    <collision>
      <origin rpy="0 0 0" xyz="0 0 0"/>
      <geometry>
        <mesh filename="package://ginko_description/meshes/ginko_rs406/stl/link03_l_leg01.stl"/>
      </geometry>
    </collision>
    <visual>
      <origin rpy="0 0 0" xyz="0 0 0"/>
      <geometry>
        <mesh filename="package://ginko_description/meshes/ginko_rs406/obj/link03_l_leg01.obj"/>
      </geometry>
    </visual>
    <inertial>
      <mass value="0.15115113"/>
      <origin rpy="0 0 0" xyz="0.05000000 0.02587267 0.00000000"/>
      <inertia ixx="0.00003721" ixy="0.00000000" ixz="0.00000000" iyy="0.00026035" iyz="0.00000000" izz="0.00028077"/>
    </inertial>
  </link>
  <joint name="leg_l_joint6" type="revolute">
    <parent link="leg_l_link4"/>
    <child link="leg_l_link6"/>
    <origin rpy="0 -2.3562 0" xyz="0.1 0.0 0.0"/>
    <axis xyz="0 1 0"/>
    <limit effort="1000.0" lower="-0.7854" upper="1.3" velocity="10.0"/>
    <dynamics damping="0.0" friction="0.3"/>
    <mimic joint="leg_l_joint4" multiplier="1" offset="0"/>
  </joint>
  <!-- parallel link (lower-2nd) -->
  <joint name="leg_l_joint5" type="revolute">
    <parent link="leg_l_link3"/>
    <child link="leg_l_link5"/>
    <origin rpy="0 2.3562 0" xyz="-0.0213 0 -0.02655"/>
    <axis xyz="0 -1 0"/>
    <limit effort="0.0" lower="-0.7854" upper="1.3" velocity="10.0"/>
    <dynamics damping="0.0" friction="0.0"/>
    <mimic joint="leg_l_joint4" multiplier="1" offset="0"/>
  </joint>
  <link name="leg_l_link5">
    <collision>
      <origin rpy="0 0 0" xyz="0 0 0"/>
      <geometry>
        <mesh filename="package://ginko_description/meshes/ginko_rs406/stl/link04_l_leg02.stl"/>
      </geometry>
    </collision>
    <visual>
      <origin rpy="0 0 0" xyz="0 0 0"/>
      <geometry>
        <mesh filename="package://ginko_description/meshes/ginko_rs406/obj/link04_l_leg02.obj"/>
      </geometry>
    </visual>
    <inertial>
      <mass value="0.01646643"/>
      <origin rpy="0 0 0" xyz="0.05000000 0.02495100 -0.00491150"/>
      <inertia ixx="0.00000640" ixy="0.00000000" ixz="0.00000000" iyy="0.00001642" iyz="0.00000000" izz="0.00002264"/>
    </inertial>
  </link>
  <joint name="close_leg_l_joint1" type="revolute">
    <parent link="leg_l_link5"/>
    <child link="dummy2_leg_l_link6"/>
    <origin rpy="0 -2.3562 0" xyz="0.1 0.0 0.0"/>
    <axis xyz="0 1 0"/>
    <limit effort="0.0" lower="-1.3" upper="0.7854" velocity="10.0"/>
    <dynamics damping="0.0" friction="0.0"/>
    <mimic joint="leg_l_joint4" multiplier="1" offset="0"/>
  </joint>
  <link name="dummy2_leg_l_link6">
    <inertial>
      <mass value="0.00001"/>
      <origin rpy="0 0 0" xyz="-0.021 0 0.012"/>
      <inertia ixx="0.00000001" ixy="0.00000000" ixz="0.00000000" iyy="0.00000001" iyz="0.00000000" izz="0.00000001"/>
    </inertial>
  </link>
  <!-- toe -->
  <link name="leg_l_link6">
    <collision>
      <origin rpy="0 0 0" xyz="0 0 0"/>
      <geometry>
        <mesh filename="package://ginko_description/meshes/ginko_rs406/stl/link06_l_toe01.stl"/>
      </geometry>
    </collision>
    <visual>
      <origin rpy="0 0 0" xyz="0 0 0"/>
      <geometry>
        <mesh filename="package://ginko_description/meshes/ginko_rs406/obj/link06_l_toe01.obj"/>
      </geometry>
    </visual>
    <inertial>
      <mass value="0.08799204"/>
      <origin rpy="0 0 0" xyz="-0.04166125 0.02463880 -0.02586249"/>
      <inertia ixx="0.00002815" ixy="-0.00000041" ixz="0.00000980" iyy="0.00006846" iyz="-0.00000026" izz="0.00006529"/>
    </inertial>
  </link>
  <joint name="leg_l_joint7" type="revolute">
    <parent link="leg_l_link6"/>
    <child link="leg_l_link7"/>
    <origin rpy="0 0 0" xyz="-0.028 0.02475 -0.0391"/>
    <axis xyz="-1 0 0"/>
    <limit effort="1000.0" lower="-1.6" upper="1.6" velocity="10.0"/>
    <dynamics damping="0.0" friction="0.3"/>
  </joint>
  <link name="leg_l_link7">
    <collision>
      <origin rpy="0 0 0" xyz="0 0 0"/>
      <geometry>
        <mesh filename="package://ginko_description/meshes/ginko_rs406/stl/link07_l_toe02.stl"/>
      </geometry>
    </collision>
    <visual>
      <origin rpy="0 0 0" xyz="0 0 0"/>
      <geometry>
        <mesh filename="package://ginko_description/meshes/ginko_rs406/obj/link07_l_toe02.obj"/>
      </geometry>
    </visual>
    <inertial>
      <mass value="0.10920041"/>
      <origin rpy="0 0 0" xyz="0.02658756 0.00000053 -0.01782468"/>
      <inertia ixx="0.00003853" ixy="0.00000000" ixz="-0.00000479" iyy="0.00005192" iyz="0.00000000" izz="0.00003521"/>
    </inertial>
  </link>
  <joint name="leg_l_joint8" type="revolute">
    <parent link="leg_l_link7"/>
    <child link="leg_l_link8"/>
    <origin rpy="0 0 0" xyz="0.0342 0 -0.04"/>
    <axis xyz="0 0 1"/>
    <limit effort="1000.0" lower="-2.6" upper="2.6" velocity="10.0"/>
    <dynamics damping="0.0" friction="0.3"/>
  </joint>
  <link name="leg_l_link8">
    <collision>
      <origin rpy="0 0 0" xyz="0 0 -0.003"/>
      <geometry>
        <box size="0.128 0.08 0.006"/>
      </geometry>
    </collision>
    <visual>
      <origin rpy="0 0 0" xyz="0 0 0"/>
      <geometry>
        <mesh filename="package://ginko_description/meshes/ginko_rs406/obj/link08_l_toe03.obj"/>
      </geometry>
    </visual>
    <inertial>
      <mass value="0.05363111"/>
      <origin rpy="0 0 0" xyz="0.00000000 0.00000000 -0.00269342"/>
      <inertia ixx="0.00002877" ixy="0.00000000" ixz="0.00000000" iyy="0.00007083" iyz="-0.00000000" izz="0.00009934"/>
    </inertial>
  </link>
  <joint name="leg_l_toe_joint0" type="fixed">
    <parent link="leg_l_link8"/>
    <child link="leg_l_toe_link0"/>
    <origin rpy="0 0 0" xyz="0.064 0.040 -0.005"/>
  </joint>
  <link name="leg_l_toe_link0"/>
  <joint name="leg_l_toe_joint1" type="fixed">
    <parent link="leg_l_link8"/>
    <child link="leg_l_toe_link1"/>
    <origin rpy="0 0 0" xyz="-0.064 0.040 -0.005"/>
  </joint>
  <link name="leg_l_toe_link1"/>
  <joint name="leg_l_toe_joint2" type="fixed">
    <parent link="leg_l_link8"/>
    <child link="leg_l_toe_link2"/>
    <origin rpy="0 0 0" xyz="-0.064 -0.040 -0.005"/>
  </joint>
  <link name="leg_l_toe_link2"/>
  <joint name="leg_l_toe_joint3" type="fixed">
    <parent link="leg_l_link8"/>
    <child link="leg_l_toe_link3"/>
    <origin rpy="0 0 0" xyz="0.064 -0.040 -0.005"/>
  </joint>
  <link name="leg_l_toe_link3"/>
  <joint name="leg_l_toe_center_joint" type="fixed">
    <parent link="leg_l_link8"/>
    <child link="leg_l_toe_center"/>
    <origin rpy="0 0 0" xyz="0.0 0.0 -0.005"/>
  </joint>
  <link name="leg_l_toe_center"/>
  <gazebo reference="leg_l_link0">
    <kp>1000000.0</kp>
    <kd>100.0</kd>
    <mu1>0.1</mu1>
    <maxVel>10.0</maxVel>
    <minDepth>0.0001</minDepth>
    <maxContacts>6</maxContacts>
    <selfCollide>false</selfCollide>
    <dampingFactor>0</dampingFactor>
  </gazebo>
  <gazebo reference="leg_l_link1">
    <kp>1000000.0</kp>
    <kd>100.0</kd>
    <mu1>0.1</mu1>
    <maxVel>10.0</maxVel>
    <minDepth>0.0001</minDepth>
    <maxContacts>6</maxContacts>
    <selfCollide>false</selfCollide>
    <dampingFactor>0</dampingFactor>
  </gazebo>
  <gazebo reference="leg_l_link3">
    <kp>1000000.0</kp>
    <kd>100.0</kd>
    <mu1>0.1</mu1>
    <maxVel>10.0</maxVel>
    <minDepth>0.0001</minDepth>
    <maxContacts>6</maxContacts>
    <selfCollide>false</selfCollide>
    <dampingFactor>0</dampingFactor>
  </gazebo>
  <gazebo reference="leg_l_link4">
    <kp>1000000.0</kp>
    <kd>100.0</kd>
    <mu1>0.1</mu1>
    <maxVel>10.0</maxVel>
    <minDepth>0.0001</minDepth>
    <maxContacts>6</maxContacts>
    <selfCollide>false</selfCollide>
    <dampingFactor>0</dampingFactor>
  </gazebo>
  <gazebo reference="leg_l_link6">
    <kp>1000000.0</kp>
    <kd>100.0</kd>
    <mu1>0.1</mu1>
    <maxVel>10.0</maxVel>
    <minDepth>0.0001</minDepth>
    <maxContacts>6</maxContacts>
    <selfCollide>false</selfCollide>
    <dampingFactor>0</dampingFactor>
  </gazebo>
  <gazebo reference="leg_l_link7">
    <kp>1000000.0</kp>
    <kd>100.0</kd>
    <mu1>0.1</mu1>
    <maxVel>10.0</maxVel>
    <minDepth>0.0001</minDepth>
    <maxContacts>6</maxContacts>
    <selfCollide>false</selfCollide>
    <dampingFactor>0</dampingFactor>
  </gazebo>
  <!-- <xacro:default_link_collision link_name="leg_l_link8" friction="1.0"/> -->
  <gazebo reference="leg_l_link8">
    <kp>2000000.0</kp>
    <kd>200.0</kd>
    <mu1>1.0</mu1>
    <maxVel>10.0</maxVel>
    <minDepth>0.0001</minDepth>
    <maxContacts>5</maxContacts>
    <selfCollide>true</selfCollide>
    <dampingFactor>0.0</dampingFactor>
  </gazebo>
  <gazebo reference="leg_l_joint0">
    <implicitSpringDamper>1</implicitSpringDamper>
  </gazebo>
  <transmission name="leg_l_joint0_trans">
    <type>transmission_interface/SimpleTransmission</type>
    <joint name="leg_l_joint0">
      <hardwareInterface>hardware_interface/PositionJointInterface</hardwareInterface>
    </joint>
    <actuator name="leg_l_joint0_motor">
      <hardwareInterface>hardware_interface/PositionJointInterface</hardwareInterface>
      <mechanicalReduction>1</mechanicalReduction>
    </actuator>
  </transmission>
  <gazebo reference="leg_l_joint1">
    <implicitSpringDamper>1</implicitSpringDamper>
  </gazebo>
  <transmission name="leg_l_joint1_trans">
    <type>transmission_interface/SimpleTransmission</type>
    <joint name="leg_l_joint1">
      <hardwareInterface>hardware_interface/PositionJointInterface</hardwareInterface>
    </joint>
    <actuator name="leg_l_joint1_motor">
      <hardwareInterface>hardware_interface/PositionJointInterface</hardwareInterface>
      <mechanicalReduction>1</mechanicalReduction>
    </actuator>
  </transmission>
  <gazebo reference="leg_l_joint3">
    <implicitSpringDamper>1</implicitSpringDamper>
  </gazebo>
  <transmission name="leg_l_joint3_trans">
    <type>transmission_interface/SimpleTransmission</type>
    <joint name="leg_l_joint3">
      <hardwareInterface>hardware_interface/PositionJointInterface</hardwareInterface>
    </joint>
    <actuator name="leg_l_joint3_motor">
      <hardwareInterface>hardware_interface/PositionJointInterface</hardwareInterface>
      <mechanicalReduction>1</mechanicalReduction>
    </actuator>
  </transmission>
  <gazebo reference="leg_l_joint4">
    <implicitSpringDamper>1</implicitSpringDamper>
  </gazebo>
  <transmission name="leg_l_joint4_trans">
    <type>transmission_interface/SimpleTransmission</type>
    <joint name="leg_l_joint4">
      <hardwareInterface>hardware_interface/PositionJointInterface</hardwareInterface>
    </joint>
    <actuator name="leg_l_joint4_motor">
      <hardwareInterface>hardware_interface/PositionJointInterface</hardwareInterface>
      <mechanicalReduction>1</mechanicalReduction>
    </actuator>
  </transmission>
  <gazebo reference="leg_l_joint6">
    <implicitSpringDamper>1</implicitSpringDamper>
  </gazebo>
  <transmission name="leg_l_joint6_trans">
    <type>transmission_interface/SimpleTransmission</type>
    <joint name="leg_l_joint6">
      <hardwareInterface>hardware_interface/PositionJointInterface</hardwareInterface>
    </joint>
    <actuator name="leg_l_joint6_motor">
      <hardwareInterface>hardware_interface/PositionJointInterface</hardwareInterface>
      <mechanicalReduction>1</mechanicalReduction>
    </actuator>
  </transmission>
  <gazebo reference="leg_l_joint7">
    <implicitSpringDamper>1</implicitSpringDamper>
  </gazebo>
  <transmission name="leg_l_joint7_trans">
    <type>transmission_interface/SimpleTransmission</type>
    <joint name="leg_l_joint7">
      <hardwareInterface>hardware_interface/PositionJointInterface</hardwareInterface>
    </joint>
    <actuator name="leg_l_joint7_motor">
      <hardwareInterface>hardware_interface/PositionJointInterface</hardwareInterface>
      <mechanicalReduction>1</mechanicalReduction>
    </actuator>
  </transmission>
  <gazebo reference="leg_l_joint8">
    <implicitSpringDamper>1</implicitSpringDamper>
  </gazebo>
  <transmission name="leg_l_joint8_trans">
    <type>transmission_interface/SimpleTransmission</type>
    <joint name="leg_l_joint8">
      <hardwareInterface>hardware_interface/PositionJointInterface</hardwareInterface>
    </joint>
    <actuator name="leg_l_joint8_motor">
      <hardwareInterface>hardware_interface/PositionJointInterface</hardwareInterface>
      <mechanicalReduction>1</mechanicalReduction>
    </actuator>
  </transmission>
  <!-- shoulder pitch. -->
  <joint name="arm_r_joint0" type="revolute">
    <parent link="body_link0"/>
    <child link="arm_r_link0"/>
    <origin rpy="0 0.3927 0" xyz="0 -0.10683 0.05115"/>
    <axis xyz="0 1 0"/>
    <limit effort="1000.0" lower="-2.6" upper="2.6" velocity="10.0"/>
    <dynamics damping="0.1" friction="0.1"/>
  </joint>
  <link name="arm_r_link0">
    <collision>
      <origin rpy="0 0 0" xyz="0 0 0"/>
      <geometry>
        <mesh filename="package://ginko_description/meshes/ginko_rs406/stl/link09_r_arm01.stl"/>
      </geometry>
    </collision>
    <visual>
      <origin rpy="0 0 0" xyz="0 0 0"/>
      <geometry>
        <mesh filename="package://ginko_description/meshes/ginko_rs406/obj/link09_r_arm01.obj"/>
      </geometry>
    </visual>
    <inertial>
      <mass value="0.01356014"/>
      <origin rpy="0 0 0" xyz="-0.01125790 -0.00529265 0.00000000"/>
      <inertia ixx="0.00000235" ixy="-0.00000004" ixz="0.00000000" iyy="0.00001670" iyz="0.00000000" izz="0.00001606"/>
    </inertial>
  </link>
  <!-- shoulder roll -->
  <joint name="arm_r_joint1" type="revolute">
    <parent link="arm_r_link0"/>
    <child link="arm_r_link1"/>
    <origin rpy="-1.1781 0 0" xyz="0.035 -0.0246 0"/>
    <axis xyz="1 0 0"/>
    <limit effort="1000.0" lower="-1.6" upper="1.18" velocity="10.0"/>
    <dynamics damping="0.1" friction="0.1"/>
  </joint>
  <link name="arm_r_link1">
    <collision>
      <origin rpy="0 0 0" xyz="0 0 0"/>
      <geometry>
        <mesh filename="package://ginko_description/meshes/ginko_rs406/stl/link10_r_arm02.stl"/>
      </geometry>
    </collision>
    <visual>
      <origin rpy="0 0 0" xyz="0 0 0"/>
      <geometry>
        <mesh filename="package://ginko_description/meshes/ginko_rs406/obj/link10_r_arm02.obj"/>
      </geometry>
    </visual>
    <inertial>
      <mass value="0.33139947"/>
      <origin rpy="0 0 0" xyz="-0.02612786 -0.02650564 -0.06333369"/>
      <inertia ixx="0.00115128" ixy="-0.00015366" ixz="-0.00031848" iyy="0.00113572" iyz="0.00037104" izz="0.00064743"/>
    </inertial>
  </link>
  <joint name="arm_r_joint1_rev" type="revolute">
    <parent link="arm_r_link0"/>
    <child link="dummy0_arm_r_link1"/>
    <origin rpy="-1.1781 0 0" xyz="-0.0562 -0.0246 0"/>
    <axis xyz="-1 0 0"/>
    <limit effort="1000.0" lower="-1.18" upper="1.6" velocity="10.0"/>
    <dynamics damping="0.0" friction="0.0"/>
  </joint>
  <link name="dummy0_arm_r_link1">
    <inertial>
      <mass value="0.00001"/>
      <origin rpy="0 0 0" xyz="-0.0912 0 0"/>
      <inertia ixx="0.00000001" ixy="0.00000000" ixz="0.00000000" iyy="0.00000001" iyz="0.00000000" izz="0.00000001"/>
    </inertial>
  </link>
  <!-- scissors -->
  <joint name="arm_r_joint2" type="revolute">
    <parent link="arm_r_link1"/>
    <child link="arm_r_link2"/>
    <origin rpy="0 0.7854 0" xyz="0.0092 -0.0547 -0.11295"/>
    <axis xyz="0 -1 0"/>
    <limit effort="1000.0" lower="-2.36" upper="2.36" velocity="10.0"/>
    <dynamics damping="0.1" friction="0.1"/>
  </joint>
  <link name="arm_r_link2">
    <collision>
      <origin rpy="0 0 0" xyz="0 0 0"/>
      <geometry>
        <mesh filename="package://ginko_description/meshes/ginko_rs406/stl/link11_r_scissor01.stl"/>
      </geometry>
    </collision>
    <visual>
      <origin rpy="0 0 0" xyz="0 0 0"/>
      <geometry>
        <mesh filename="package://ginko_description/meshes/ginko_rs406/obj/link11_r_scissor01.obj"/>
      </geometry>
    </visual>
    <inertial>
      <mass value="0.03287850"/>
      <origin rpy="0 0 0" xyz="0.08234859 0.030246866 0.00514112"/>
      <inertia ixx="0.00002277" ixy="0.00000014" ixz="-0.00000058" iyy="0.00008197" iyz="0.00000001" izz="0.00010105"/>
    </inertial>
  </link>
  <joint name="arm_r_joint3" type="revolute">
    <parent link="arm_r_link1"/>
    <child link="arm_r_link3"/>
    <origin rpy="0 0.7854 0" xyz="0.0092 0.0018 -0.11295"/>
    <axis xyz="0 -1 0"/>
    <limit effort="1000.0" lower="-2.36" upper="2.36" velocity="10.0"/>
    <dynamics damping="0.1" friction="0.1"/>
  </joint>
  <link name="arm_r_link3">
    <collision>
      <origin rpy="0 0 0" xyz="0 0 0"/>
      <geometry>
        <mesh filename="package://ginko_description/meshes/ginko_rs406/stl/link12_r_scissor02.stl"/>
      </geometry>
    </collision>
    <visual>
      <origin rpy="0 0 0" xyz="0 0 0"/>
      <geometry>
        <mesh filename="package://ginko_description/meshes/ginko_rs406/obj/link12_r_scissor02.obj"/>
      </geometry>
    </visual>
    <inertial>
      <mass value="0.02936110"/>
      <origin rpy="0 0 0" xyz="0.07807033 -0.02515230 -0.00665437"/>
      <inertia ixx="0.00001452" ixy="-0.00000023" ixz="-0.00000245" iyy="0.00006407" iyz="0.00000002" izz="0.00008024"/>
    </inertial>
  </link>
  <joint name="arm_r_urg_joint" type="fixed">
    <parent link="arm_r_link1"/>
    <child link="arm_r_urg_link"/>
    <origin rpy="0 1.57 1.57" xyz="-0.0456 0.01715 -0.06795"/>
  </joint>
  <link name="arm_r_urg_link">
    <collision>
      <origin rpy="0 0 0" xyz="0 0 0"/>
      <geometry>
        <mesh filename="package://ginko_description/meshes/ginko_rs406/stl/urg.stl"/>
      </geometry>
    </collision>
    <visual>
      <origin rpy="0 0 0" xyz="0 0 0"/>
      <geometry>
        <mesh filename="package://ginko_description/meshes/ginko_rs406/obj/urg.obj"/>
      </geometry>
    </visual>
    <inertial>
      <mass value="0.16705492"/>
      <origin rpy="0 0 0" xyz="-0.00014579 0.00000831 -0.02360505"/>
      <inertia ixx="0.00008801" ixy="0.00000000" ixz="-0.00000049" iyy="0.00008854" iyz="-0.00000004" izz="0.00006019"/>
    </inertial>
  </link>
  <gazebo reference="arm_r_link0">
    <kp>1000000.0</kp>
    <kd>100.0</kd>
    <mu1>0.1</mu1>
    <maxVel>10.0</maxVel>
    <minDepth>0.0001</minDepth>
    <maxContacts>6</maxContacts>
    <selfCollide>false</selfCollide>
    <dampingFactor>0</dampingFactor>
  </gazebo>
  <gazebo reference="arm_r_link1">
    <kp>1000000.0</kp>
    <kd>100.0</kd>
    <mu1>0.1</mu1>
    <maxVel>10.0</maxVel>
    <minDepth>0.0001</minDepth>
    <maxContacts>6</maxContacts>
    <selfCollide>false</selfCollide>
    <dampingFactor>0</dampingFactor>
  </gazebo>
  <gazebo reference="arm_r_link2">
    <kp>1000000.0</kp>
    <kd>100.0</kd>
    <mu1>0.1</mu1>
    <maxVel>10.0</maxVel>
    <minDepth>0.0001</minDepth>
    <maxContacts>6</maxContacts>
    <selfCollide>false</selfCollide>
    <dampingFactor>0</dampingFactor>
  </gazebo>
  <gazebo reference="arm_r_link3">
    <kp>1000000.0</kp>
    <kd>100.0</kd>
    <mu1>0.1</mu1>
    <maxVel>10.0</maxVel>
    <minDepth>0.0001</minDepth>
    <maxContacts>6</maxContacts>
    <selfCollide>false</selfCollide>
    <dampingFactor>0</dampingFactor>
  </gazebo>
  <gazebo reference="arm_r_joint0">
    <implicitSpringDamper>1</implicitSpringDamper>
  </gazebo>
  <transmission name="arm_r_joint0_trans">
    <type>transmission_interface/SimpleTransmission</type>
    <joint name="arm_r_joint0">
      <hardwareInterface>hardware_interface/PositionJointInterface</hardwareInterface>
    </joint>
    <actuator name="arm_r_joint0_motor">
      <hardwareInterface>hardware_interface/PositionJointInterface</hardwareInterface>
      <mechanicalReduction>1</mechanicalReduction>
    </actuator>
  </transmission>
  <gazebo reference="arm_r_joint1">
    <implicitSpringDamper>1</implicitSpringDamper>
  </gazebo>
  <transmission name="arm_r_joint1_trans">
    <type>transmission_interface/SimpleTransmission</type>
    <joint name="arm_r_joint1">
      <hardwareInterface>hardware_interface/PositionJointInterface</hardwareInterface>
    </joint>
    <actuator name="arm_r_joint1_motor">
      <hardwareInterface>hardware_interface/PositionJointInterface</hardwareInterface>
      <mechanicalReduction>1</mechanicalReduction>
    </actuator>
  </transmission>
  <gazebo reference="arm_r_joint1_rev">
    <implicitSpringDamper>1</implicitSpringDamper>
  </gazebo>
  <transmission name="arm_r_joint1_rev_trans">
    <type>transmission_interface/SimpleTransmission</type>
    <joint name="arm_r_joint1_rev">
      <hardwareInterface>hardware_interface/PositionJointInterface</hardwareInterface>
    </joint>
    <actuator name="arm_r_joint1_rev_motor">
      <hardwareInterface>hardware_interface/PositionJointInterface</hardwareInterface>
      <mechanicalReduction>1</mechanicalReduction>
    </actuator>
  </transmission>
  <gazebo reference="arm_r_joint2">
    <implicitSpringDamper>1</implicitSpringDamper>
  </gazebo>
  <transmission name="arm_r_joint2_trans">
    <type>transmission_interface/SimpleTransmission</type>
    <joint name="arm_r_joint2">
      <hardwareInterface>hardware_interface/PositionJointInterface</hardwareInterface>
    </joint>
    <actuator name="arm_r_joint2_motor">
      <hardwareInterface>hardware_interface/PositionJointInterface</hardwareInterface>
      <mechanicalReduction>1</mechanicalReduction>
    </actuator>
  </transmission>
  <gazebo reference="arm_r_joint3">
    <implicitSpringDamper>1</implicitSpringDamper>
  </gazebo>
  <transmission name="arm_r_joint3_trans">
    <type>transmission_interface/SimpleTransmission</type>
    <joint name="arm_r_joint3">
      <hardwareInterface>hardware_interface/PositionJointInterface</hardwareInterface>
    </joint>
    <actuator name="arm_r_joint3_motor">
      <hardwareInterface>hardware_interface/PositionJointInterface</hardwareInterface>
      <mechanicalReduction>1</mechanicalReduction>
    </actuator>
  </transmission>
  <!-- shoulder pitch. -->
  <joint name="arm_l_joint0" type="revolute">
    <parent link="body_link0"/>
    <child link="arm_l_link0"/>
    <origin rpy="0 0.3927 0" xyz="0 0.10683 0.05115"/>
    <axis xyz="0 -1 0"/>
    <limit effort="1000.0" lower="-2.6" upper="2.6" velocity="10.0"/>
    <dynamics damping="0.1" friction="0.1"/>
  </joint>
  <link name="arm_l_link0">
    <collision>
      <origin rpy="0 0 0" xyz="0 0 0"/>
      <geometry>
        <mesh filename="package://ginko_description/meshes/ginko_rs406/stl/link09_l_arm01.stl"/>
      </geometry>
    </collision>
    <visual>
      <origin rpy="0 0 0" xyz="0 0 0"/>
      <geometry>
        <mesh filename="package://ginko_description/meshes/ginko_rs406/obj/link09_l_arm01.obj"/>
      </geometry>
    </visual>
    <inertial>
      <mass value="0.01356014"/>
      <origin rpy="0 0 0" xyz="-0.01125790 0.00529265 0.00000000"/>
      <inertia ixx="0.00000235" ixy="0.00000004" ixz="0.00000000" iyy="0.00001670" iyz="0.00000000" izz="0.00001606"/>
    </inertial>
  </link>
  <!-- shoulder roll -->
  <joint name="arm_l_joint1" type="revolute">
    <parent link="arm_l_link0"/>
    <child link="arm_l_link1"/>
    <origin rpy="1.1781 0 0" xyz="0.035 0.0246 0"/>
    <axis xyz="1 0 0"/>
    <limit effort="1000.0" lower="-1.18" upper="1.6" velocity="10.0"/>
    <dynamics damping="0.1" friction="0.1"/>
  </joint>
  <link name="arm_l_link1">
    <collision>
      <origin rpy="0 0 0" xyz="0 0 0"/>
      <geometry>
        <mesh filename="package://ginko_description/meshes/ginko_rs406/stl/link10_l_arm02.stl"/>
      </geometry>
    </collision>
    <visual>
      <origin rpy="0 0 0" xyz="0 0 0"/>
      <geometry>
        <mesh filename="package://ginko_description/meshes/ginko_rs406/obj/link10_l_arm02.obj"/>
      </geometry>
    </visual>
    <inertial>
      <mass value="0.33139947"/>
      <origin rpy="0 0 0" xyz="-0.02612786 0.02650564 -0.06333369"/>
      <inertia ixx="0.00115128" ixy="0.00015366" ixz="-0.00031848" iyy="0.00113572" iyz="-0.00037104" izz="0.00064743"/>
    </inertial>
  </link>
  <joint name="arm_l_joint1_rev" type="revolute">
    <parent link="arm_l_link0"/>
    <child link="dummy0_arm_l_link1"/>
    <origin rpy="1.1781 0 0" xyz="-0.0562 0.0246 0"/>
    <axis xyz="-1 0 0"/>
    <limit effort="1000.0" lower="-1.6" upper="1.18" velocity="10.0"/>
    <dynamics damping="0.0" friction="0.0"/>
  </joint>
  <link name="dummy0_arm_l_link1">
    <inertial>
      <mass value="0.00001"/>
      <origin rpy="0 0 0" xyz="-0.0912 0 0"/>
      <inertia ixx="0.00000001" ixy="0.00000000" ixz="0.00000000" iyy="0.00000001" iyz="0.00000000" izz="0.00000001"/>
    </inertial>
  </link>
  <!-- scissors -->
  <joint name="arm_l_joint2" type="revolute">
    <parent link="arm_l_link1"/>
    <child link="arm_l_link2"/>
    <origin rpy="0 0.7854 0" xyz="0.0092 0.0547 -0.11295"/>
    <axis xyz="0 1 0"/>
    <limit effort="1000.0" lower="-2.36" upper="2.36" velocity="10.0"/>
    <dynamics damping="0.1" friction="0.1"/>
  </joint>
  <link name="arm_l_link2">
    <collision>
      <origin rpy="0 0 0" xyz="0 0 0"/>
      <geometry>
        <mesh filename="package://ginko_description/meshes/ginko_rs406/stl/link11_l_scissor01.stl"/>
      </geometry>
    </collision>
    <visual>
      <origin rpy="0 0 0" xyz="0 0 0"/>
      <geometry>
        <mesh filename="package://ginko_description/meshes/ginko_rs406/obj/link11_l_scissor01.obj"/>
      </geometry>
    </visual>
    <inertial>
      <mass value="0.03287850"/>
      <origin rpy="0 0 0" xyz="0.08234859 -0.030246866 0.00514112"/>
      <inertia ixx="0.00002277" ixy="-0.00000014" ixz="-0.00000058" iyy="0.00008197" iyz="-0.00000001" izz="0.00010105"/>
    </inertial>
  </link>
  <joint name="arm_l_joint3" type="revolute">
    <parent link="arm_l_link1"/>
    <child link="arm_l_link3"/>
    <origin rpy="0 0.7854 0" xyz="0.0092 -0.0018 -0.11295"/>
    <axis xyz="0 1 0"/>
    <limit effort="1000.0" lower="-2.36" upper="2.36" velocity="10.0"/>
    <dynamics damping="0.1" friction="0.1"/>
  </joint>
  <link name="arm_l_link3">
    <collision>
      <origin rpy="0 0 0" xyz="0 0 0"/>
      <geometry>
        <mesh filename="package://ginko_description/meshes/ginko_rs406/stl/link12_l_scissor02.stl"/>
      </geometry>
    </collision>
    <visual>
      <origin rpy="0 0 0" xyz="0 0 0"/>
      <geometry>
        <mesh filename="package://ginko_description/meshes/ginko_rs406/obj/link12_l_scissor02.obj"/>
      </geometry>
    </visual>
    <inertial>
      <mass value="0.02936110"/>
      <origin rpy="0 0 0" xyz="0.07807033 0.02515230 -0.00665437"/>
      <inertia ixx="0.00001452" ixy="0.00000023" ixz="-0.00000245" iyy="0.00006407" iyz="-0.00000002" izz="0.00008024"/>
    </inertial>
  </link>
  <joint name="arm_l_urg_joint" type="fixed">
    <parent link="arm_l_link1"/>
    <child link="arm_l_urg_link"/>
    <origin rpy="0 1.57 -1.57" xyz="-0.0456 -0.01715 -0.06795"/>
  </joint>
  <link name="arm_l_urg_link">
    <collision>
      <origin rpy="0 0 0" xyz="0 0 0"/>
      <geometry>
        <mesh filename="package://ginko_description/meshes/ginko_rs406/stl/urg.stl"/>
      </geometry>
    </collision>
    <visual>
      <origin rpy="0 0 0" xyz="0 0 0"/>
      <geometry>
        <mesh filename="package://ginko_description/meshes/ginko_rs406/obj/urg.obj"/>
      </geometry>
    </visual>
    <inertial>
      <mass value="0.16705492"/>
      <origin rpy="0 0 0" xyz="-0.00014579 0.00000831 -0.02360505"/>
      <inertia ixx="0.00008801" ixy="0.00000000" ixz="-0.00000049" iyy="0.00008854" iyz="-0.00000004" izz="0.00006019"/>
    </inertial>
  </link>
  <gazebo reference="arm_l_link0">
    <kp>1000000.0</kp>
    <kd>100.0</kd>
    <mu1>0.1</mu1>
    <maxVel>10.0</maxVel>
    <minDepth>0.0001</minDepth>
    <maxContacts>6</maxContacts>
    <selfCollide>false</selfCollide>
    <dampingFactor>0</dampingFactor>
  </gazebo>
  <gazebo reference="arm_l_link1">
    <kp>1000000.0</kp>
    <kd>100.0</kd>
    <mu1>0.1</mu1>
    <maxVel>10.0</maxVel>
    <minDepth>0.0001</minDepth>
    <maxContacts>6</maxContacts>
    <selfCollide>false</selfCollide>
    <dampingFactor>0</dampingFactor>
  </gazebo>
  <gazebo reference="arm_l_link2">
    <kp>1000000.0</kp>
    <kd>100.0</kd>
    <mu1>0.1</mu1>
    <maxVel>10.0</maxVel>
    <minDepth>0.0001</minDepth>
    <maxContacts>6</maxContacts>
    <selfCollide>false</selfCollide>
    <dampingFactor>0</dampingFactor>
  </gazebo>
  <gazebo reference="arm_l_link3">
    <kp>1000000.0</kp>
    <kd>100.0</kd>
    <mu1>0.1</mu1>
    <maxVel>10.0</maxVel>
    <minDepth>0.0001</minDepth>
    <maxContacts>6</maxContacts>
    <selfCollide>false</selfCollide>
    <dampingFactor>0</dampingFactor>
  </gazebo>
  <gazebo reference="arm_l_joint0">
    <implicitSpringDamper>1</implicitSpringDamper>
  </gazebo>
  <transmission name="arm_l_joint0_trans">
    <type>transmission_interface/SimpleTransmission</type>
    <joint name="arm_l_joint0">
      <hardwareInterface>hardware_interface/PositionJointInterface</hardwareInterface>
    </joint>
    <actuator name="arm_l_joint0_motor">
      <hardwareInterface>hardware_interface/PositionJointInterface</hardwareInterface>
      <mechanicalReduction>1</mechanicalReduction>
    </actuator>
  </transmission>
  <gazebo reference="arm_l_joint1">
    <implicitSpringDamper>1</implicitSpringDamper>
  </gazebo>
  <transmission name="arm_l_joint1_trans">
    <type>transmission_interface/SimpleTransmission</type>
    <joint name="arm_l_joint1">
      <hardwareInterface>hardware_interface/PositionJointInterface</hardwareInterface>
    </joint>
    <actuator name="arm_l_joint1_motor">
      <hardwareInterface>hardware_interface/PositionJointInterface</hardwareInterface>
      <mechanicalReduction>1</mechanicalReduction>
    </actuator>
  </transmission>
  <gazebo reference="arm_l_joint1_rev">
    <implicitSpringDamper>1</implicitSpringDamper>
  </gazebo>
  <transmission name="arm_l_joint1_rev_trans">
    <type>transmission_interface/SimpleTransmission</type>
    <joint name="arm_l_joint1_rev">
      <hardwareInterface>hardware_interface/PositionJointInterface</hardwareInterface>
    </joint>
    <actuator name="arm_l_joint1_rev_motor">
      <hardwareInterface>hardware_interface/PositionJointInterface</hardwareInterface>
      <mechanicalReduction>1</mechanicalReduction>
    </actuator>
  </transmission>
  <gazebo reference="arm_l_joint2">
    <implicitSpringDamper>1</implicitSpringDamper>
  </gazebo>
  <transmission name="arm_l_joint2_trans">
    <type>transmission_interface/SimpleTransmission</type>
    <joint name="arm_l_joint2">
      <hardwareInterface>hardware_interface/PositionJointInterface</hardwareInterface>
    </joint>
    <actuator name="arm_l_joint2_motor">
      <hardwareInterface>hardware_interface/PositionJointInterface</hardwareInterface>
      <mechanicalReduction>1</mechanicalReduction>
    </actuator>
  </transmission>
  <gazebo reference="arm_l_joint3">
    <implicitSpringDamper>1</implicitSpringDamper>
  </gazebo>
  <transmission name="arm_l_joint3_trans">
    <type>transmission_interface/SimpleTransmission</type>
    <joint name="arm_l_joint3">
      <hardwareInterface>hardware_interface/PositionJointInterface</hardwareInterface>
    </joint>
    <actuator name="arm_l_joint3_motor">
      <hardwareInterface>hardware_interface/PositionJointInterface</hardwareInterface>
      <mechanicalReduction>1</mechanicalReduction>
    </actuator>
  </transmission>
  <gazebo>
    <plugin filename="libgazebo_dc_motor.so" name="gazebo_ros_control">
      <robotNamespace>ginko</robotNamespace>
      <robotSimType>gazebo_dc_motor/DefaultRobotHWSim</robotSimType>
      <legacyModeNS>false</legacyModeNS>
    </plugin>
  </gazebo>
  <link name="body_imu_attached_link"/>
  <joint name="body_imu_attached_joint" type="fixed">
    <parent link="body_link1"/>
    <child link="body_imu_attached_link"/>
    <origin rpy="0 1.5708 0" xyz="-0.09 0 -0.0379"/>
  </joint>
  <link name="body_imu_base_link"/>
  <joint name="imu_joint" type="fixed">
    <parent link="body_link1"/>
    <child link="body_imu_base_link"/>
    <origin rpy="0 0 0" xyz="-0.09 0 -0.0379"/>
  </joint>
  <gazebo>
    <plugin filename="libgazebo_ros_imu.so" name="imu_plugin">
      <alwaysOn>true</alwaysOn>
      <bodyName>body_imu_attached_link</bodyName>
      <topicName>/sensor/imu/raw/gazebo</topicName>
      <serviceName>gazebo_imu_service</serviceName>
      <gaussianNoise>0.0</gaussianNoise>
      <updateRate>400.0</updateRate>
    </plugin>
  </gazebo>
  <gazebo reference="arm_r_urg_link">
    <sensor name="urg_right" type="gpu_ray">
      <update_rate>10.0</update_rate>
      <pose>0 0 0 0 0 0</pose>
      <!-- <visualize>true</visualize> -->
      <ray>
        <scan>
          <horizontal>
            <samples>666</samples>
            <resolution>1</resolution>
            <min_angle>-2.094</min_angle>
            <max_angle>2.094</max_angle>
          </horizontal>
        </scan>
        <range>
          <min>0.02</min>
          <max>5.6</max>
          <resolution>0.001</resolution>
        </range>
        <noise>
          <type>gaussian</type>
          <mean>0.0</mean>
          <stddev>0.01</stddev>
        </noise>
      </ray>
      <plugin filename="libgazebo_ros_gpu_laser.so" name="urg_right_gazebo_plugin">
        <frameName>arm_r_urg_link</frameName>
        <topicName>/sensor/urg/right/scan_raw</topicName>
      </plugin>
    </sensor>
  </gazebo>
  <gazebo reference="arm_l_urg_link">
    <sensor name="urg_left" type="gpu_ray">
      <update_rate>10.0</update_rate>
      <pose>0 0 0 0 0 0</pose>
      <!-- <visualize>true</visualize> -->
      <ray>
        <scan>
          <horizontal>
            <samples>666</samples>
            <resolution>1</resolution>
            <min_angle>-2.094</min_angle>
            <max_angle>2.094</max_angle>
          </horizontal>
        </scan>
        <range>
          <min>0.02</min>
          <max>5.6</max>
          <resolution>0.001</resolution>
        </range>
        <noise>
          <type>gaussian</type>
          <mean>0.0</mean>
          <stddev>0.01</stddev>
        </noise>
      </ray>
      <plugin filename="libgazebo_ros_gpu_laser.so" name="urg_left_gazebo_plugin">
        <frameName>arm_l_urg_link</frameName>
        <topicName>/sensor/urg/left/scan_raw</topicName>
      </plugin>
    </sensor>
  </gazebo>
</robot>
