<?xml version="1.0" ?>
<!-- =================================================================================== -->
<!-- |    This document was autogenerated by xacro from /catkin_ws/src/kuroko_ros/kuroko_description/xacro/kuroko/kuroko.xacro | -->
<!-- |    EDITING THIS FILE BY HAND IS NOT RECOMMENDED                                 | -->
<!-- =================================================================================== -->
<robot name="kuroko" xmlns:controller="http://playerstage.sourceforge.net/gazebo/xmlschema/#controller" xmlns:interface="http://playerstage.sourceforge.net/gazebo/xmlschema/#interface" xmlns:sensor="http://playerstage.sourceforge.net/gazebo/xmlschema/#sensor" xmlns:xacro="http://www.ros.org/wiki/xacro">
  <link name="root_link"/>
  <joint name="root_joint" type="fixed">
    <parent link="root_link"/>
    <child link="chest"/>
    <origin rpy="0 0 0" xyz="0 0 0"/>
  </joint>
  <!-- chest -->
  <link name="chest">
    <visual>
      <origin rpy="0 0 0" xyz="0 0 0"/>
      <geometry>
        <mesh filename="package://kuroko_description/meshes/kuroko/obj/chest.obj"/>
      </geometry>
    </visual>
    <collision>
      <origin rpy="0 0 0" xyz="0 0 0.057"/>
      <geometry>
        <box size="0.1 0.204 0.114"/>
      </geometry>
    </collision>
    <inertial>
      <origin rpy="0 0 0" xyz="0 0 0.057"/>
      <mass value="0.991"/>
      <inertia ixx="0.004510041" ixy="0.0" ixz="0.0" iyy="0.00189908633333" iyz="0.0" izz="0.00426262133333"/>
    </inertial>
  </link>
  <!-- Joint1 -->
  <joint name="waist_joint" type="revolute">
    <parent link="chest"/>
    <child link="waist"/>
    <origin rpy="0 0 0" xyz="0 0 0"/>
    <axis xyz="0 0 -1"/>
    <limit effort="1000.0" lower="-3.1" upper="3.1" velocity="10.0"/>
    <dynamics damping="0.0" friction="0.0"/>
  </joint>
  <!-- waist -->
  <link name="waist">
    <visual>
      <origin rpy="0 0 0" xyz="0 0 0"/>
      <geometry>
        <mesh filename="package://kuroko_description/meshes/kuroko/obj/waist.obj"/>
      </geometry>
    </visual>
    <collision>
      <origin rpy="0 0 0" xyz="0.00125 0 -0.04875"/>
      <geometry>
        <box size="0.0705 0.0325 0.0975"/>
      </geometry>
    </collision>
    <inertial>
      <origin rpy="0 0 0" xyz="0.00125 0 -0.04875"/>
      <mass value="0.337"/>
      <inertia ixx="0.000296630208333" ixy="0.0" ixz="0.0" iyy="0.000406548375" iyz="0.0" izz="0.000169244208333"/>
    </inertial>
  </link>
  <gazebo reference="waist_joint">
    <implicitSpringDamper>1</implicitSpringDamper>
  </gazebo>
  <transmission name="waist_joint_trans">
    <type>transmission_interface/SimpleTransmission</type>
    <joint name="waist_joint">
      <hardwareInterface>hardware_interface/PositionJointInterface</hardwareInterface>
    </joint>
    <actuator name="waist_joint_motor">
      <hardwareInterface>hardware_interface/PositionJointInterface</hardwareInterface>
      <mechanicalReduction>1</mechanicalReduction>
    </actuator>
  </transmission>
  <gazebo reference="chest">
    <kp>1000000.0</kp>
    <kd>100.0</kd>
    <mu1>0.1</mu1>
    <maxVel>10.0</maxVel>
    <minDepth>0.0001</minDepth>
    <maxContacts>6</maxContacts>
    <selfCollide>false</selfCollide>
    <dampingFactor>0</dampingFactor>
  </gazebo>
  <gazebo reference="waist">
    <kp>1000000.0</kp>
    <kd>100.0</kd>
    <mu1>0.1</mu1>
    <maxVel>10.0</maxVel>
    <minDepth>0.0001</minDepth>
    <maxContacts>6</maxContacts>
    <selfCollide>false</selfCollide>
    <dampingFactor>0</dampingFactor>
  </gazebo>
  <!-- Link conencts from body. Shoulder first. -->
  <joint name="shoulder_r_joint" type="revolute">
    <parent link="chest"/>
    <child link="shoulder_r"/>
    <origin rpy="0 0 0" xyz="0 -0.108 0.01275"/>
    <axis xyz="0 -1 0"/>
    <limit effort="1000.0" lower="-3.1" upper="3.1" velocity="10.0"/>
    <dynamics damping="0.0" friction="0.0"/>
  </joint>
  <link name="shoulder_r">
    <visual>
      <origin rpy="0 0 0" xyz="0 0 0"/>
      <geometry>
        <mesh filename="package://kuroko_description/meshes/kuroko/obj/shoulder_r.obj"/>
      </geometry>
    </visual>
    <collision>
      <origin rpy="0 0 0" xyz="0 -0.0205 0"/>
      <geometry>
        <box size="0.042 0.041 0.04"/>
      </geometry>
    </collision>
    <inertial>
      <origin rpy="0 0 0" xyz="0 -0.0205 0"/>
      <mass value="0.022"/>
      <inertia ixx="1e-05" ixy="0.0" ixz="0.0" iyy="1e-05" iyz="0.0" izz="1e-05"/>
    </inertial>
  </link>
  <joint name="arm_r_joint" type="revolute">
    <parent link="shoulder_r"/>
    <child link="arm_r"/>
    <origin rpy="0 0 0" xyz="0 -0.028 0"/>
    <axis xyz="-1 0 0"/>
    <limit effort="1000.0" lower="-1.0472" upper="2.0071" velocity="10.0"/>
    <dynamics damping="0.0" friction="0.0"/>
  </joint>
  <link name="arm_r">
    <visual>
      <origin rpy="0 0 0" xyz="0 0 0"/>
      <geometry>
        <mesh filename="package://kuroko_description/meshes/kuroko/obj/arm_r.obj"/>
      </geometry>
    </visual>
    <collision>
      <origin rpy="0 0 0" xyz="0 -0.0385 -0.02575"/>
      <geometry>
        <box size="0.0285 0.1045 0.08"/>
      </geometry>
    </collision>
    <inertial>
      <origin rpy="0 0 0" xyz="0 -0.0385 -0.02575"/>
      <mass value="0.342"/>
      <inertia ixx="0.000493627125" ixy="0.0" ixz="0.0" iyy="0.000205549125" iyz="0.0" izz="0.00033437625"/>
    </inertial>
  </link>
  <joint name="scissor_rf_joint" type="revolute">
    <parent link="arm_r"/>
    <child link="scissor_rf"/>
    <origin rpy="0 0 0" xyz="0 -0.0265 -0.0545"/>
    <axis xyz="0 1 0"/>
    <limit effort="1000.0" lower="-2.6180" upper="2.6180" velocity="10.0"/>
    <dynamics damping="0.0" friction="0.0"/>
  </joint>
  <link name="scissor_rf">
    <visual>
      <origin rpy="0 0 0" xyz="0 0 0"/>
      <geometry>
        <mesh filename="package://kuroko_description/meshes/kuroko/obj/scissor_rf.obj"/>
      </geometry>
    </visual>
    <collision>
      <origin rpy="0 0 0" xyz="0.0043 0 -0.104"/>
      <geometry>
        <box size="0.01085 0.058 0.208"/>
      </geometry>
    </collision>
    <collision>
      <origin rpy="0 0 0" xyz="-0.0206 0 -0.201"/>
      <geometry>
        <box size="0.039 0.058 0.014"/>
      </geometry>
    </collision>
    <inertial>
      <origin rpy="0 0 0" xyz="0.0043 0 -0.104"/>
      <mass value="0.032"/>
      <inertia ixx="0.000124341333333" ixy="0.0" ixz="0.0" iyy="0.000120533333333" iyz="0.0" izz="1.41333333333e-05"/>
    </inertial>
  </link>
  <joint name="scissor_rr_joint" type="revolute">
    <parent link="arm_r"/>
    <child link="scissor_rr"/>
    <origin rpy="0 0 0" xyz="0 -0.0265 -0.0545"/>
    <axis xyz="0 -1 0"/>
    <limit effort="1000.0" lower="-2.6180" upper="2.6180" velocity="10.0"/>
    <dynamics damping="0.0" friction="0.0"/>
  </joint>
  <link name="scissor_rr">
    <visual>
      <origin rpy="0 0 0" xyz="0 0 0"/>
      <geometry>
        <mesh filename="package://kuroko_description/meshes/kuroko/obj/scissor_rr.obj"/>
      </geometry>
    </visual>
    <collision>
      <origin rpy="0 0 0" xyz="-0.0043 0 -0.1"/>
      <geometry>
        <box size="0.01085 0.044 0.2"/>
      </geometry>
    </collision>
    <collision>
      <origin rpy="0 0 0" xyz="0.0206 0 -0.193"/>
      <geometry>
        <box size="0.039 0.044 0.014"/>
      </geometry>
    </collision>
    <inertial>
      <origin rpy="0 0 0" xyz="-0.0043 0 -0.1"/>
      <mass value="0.031"/>
      <inertia ixx="0.000108334666667" ixy="0.0" ixz="0.0" iyy="0.000108334666667" iyz="0.0" izz="1.00026666667e-05"/>
    </inertial>
  </link>
  <gazebo reference="shoulder_r_joint">
    <implicitSpringDamper>1</implicitSpringDamper>
  </gazebo>
  <transmission name="shoulder_r_joint_trans">
    <type>transmission_interface/SimpleTransmission</type>
    <joint name="shoulder_r_joint">
      <hardwareInterface>hardware_interface/PositionJointInterface</hardwareInterface>
    </joint>
    <actuator name="shoulder_r_joint_motor">
      <hardwareInterface>hardware_interface/PositionJointInterface</hardwareInterface>
      <mechanicalReduction>1</mechanicalReduction>
    </actuator>
  </transmission>
  <gazebo reference="arm_r_joint">
    <implicitSpringDamper>1</implicitSpringDamper>
  </gazebo>
  <transmission name="arm_r_joint_trans">
    <type>transmission_interface/SimpleTransmission</type>
    <joint name="arm_r_joint">
      <hardwareInterface>hardware_interface/PositionJointInterface</hardwareInterface>
    </joint>
    <actuator name="arm_r_joint_motor">
      <hardwareInterface>hardware_interface/PositionJointInterface</hardwareInterface>
      <mechanicalReduction>1</mechanicalReduction>
    </actuator>
  </transmission>
  <gazebo reference="scissor_rf_joint">
    <implicitSpringDamper>1</implicitSpringDamper>
  </gazebo>
  <transmission name="scissor_rf_joint_trans">
    <type>transmission_interface/SimpleTransmission</type>
    <joint name="scissor_rf_joint">
      <hardwareInterface>hardware_interface/PositionJointInterface</hardwareInterface>
    </joint>
    <actuator name="scissor_rf_joint_motor">
      <hardwareInterface>hardware_interface/PositionJointInterface</hardwareInterface>
      <mechanicalReduction>1</mechanicalReduction>
    </actuator>
  </transmission>
  <gazebo reference="scissor_rr_joint">
    <implicitSpringDamper>1</implicitSpringDamper>
  </gazebo>
  <transmission name="scissor_rr_joint_trans">
    <type>transmission_interface/SimpleTransmission</type>
    <joint name="scissor_rr_joint">
      <hardwareInterface>hardware_interface/PositionJointInterface</hardwareInterface>
    </joint>
    <actuator name="scissor_rr_joint_motor">
      <hardwareInterface>hardware_interface/PositionJointInterface</hardwareInterface>
      <mechanicalReduction>1</mechanicalReduction>
    </actuator>
  </transmission>
  <gazebo reference="shoulder_r">
    <kp>1000000.0</kp>
    <kd>100.0</kd>
    <mu1>0.01</mu1>
    <maxVel>10.0</maxVel>
    <minDepth>0.0001</minDepth>
    <maxContacts>6</maxContacts>
    <selfCollide>false</selfCollide>
    <dampingFactor>0</dampingFactor>
  </gazebo>
  <gazebo reference="arm_r">
    <kp>1000000.0</kp>
    <kd>100.0</kd>
    <mu1>0.01</mu1>
    <maxVel>10.0</maxVel>
    <minDepth>0.0001</minDepth>
    <maxContacts>6</maxContacts>
    <selfCollide>false</selfCollide>
    <dampingFactor>0</dampingFactor>
  </gazebo>
  <gazebo reference="scissor_rf">
    <kp>1000000.0</kp>
    <kd>100.0</kd>
    <mu1>0.01</mu1>
    <maxVel>10.0</maxVel>
    <minDepth>0.0001</minDepth>
    <maxContacts>6</maxContacts>
    <selfCollide>false</selfCollide>
    <dampingFactor>0</dampingFactor>
  </gazebo>
  <gazebo reference="scissor_rr">
    <kp>1000000.0</kp>
    <kd>100.0</kd>
    <mu1>0.01</mu1>
    <maxVel>10.0</maxVel>
    <minDepth>0.0001</minDepth>
    <maxContacts>6</maxContacts>
    <selfCollide>false</selfCollide>
    <dampingFactor>0</dampingFactor>
  </gazebo>
  <!-- Link conencts from body. Shoulder first. -->
  <joint name="shoulder_l_joint" type="revolute">
    <parent link="chest"/>
    <child link="shoulder_l"/>
    <origin rpy="0 0 0" xyz="0 0.108 0.01275"/>
    <axis xyz="0 1 0"/>
    <limit effort="1000.0" lower="-3.1" upper="3.1" velocity="10.0"/>
    <dynamics damping="0.0" friction="0.0"/>
  </joint>
  <link name="shoulder_l">
    <visual>
      <origin rpy="0 0 0" xyz="0 0 0"/>
      <geometry>
        <mesh filename="package://kuroko_description/meshes/kuroko/obj/shoulder_l.obj"/>
      </geometry>
    </visual>
    <collision>
      <origin rpy="0 0 0" xyz="0 0.0205 0"/>
      <geometry>
        <box size="0.042 0.041 0.04"/>
      </geometry>
    </collision>
    <inertial>
      <origin rpy="0 0 0" xyz="0 0.0205 0"/>
      <mass value="0.022"/>
      <inertia ixx="1e-05" ixy="0.0" ixz="0.0" iyy="1e-05" iyz="0.0" izz="1e-05"/>
    </inertial>
  </link>
  <joint name="arm_l_joint" type="revolute">
    <parent link="shoulder_l"/>
    <child link="arm_l"/>
    <origin rpy="0 0 0" xyz="0 0.028 0"/>
    <axis xyz="-1 0 0"/>
    <limit effort="1000.0" lower="-2.0071" upper="1.0472" velocity="10.0"/>
    <dynamics damping="0.0" friction="0.0"/>
  </joint>
  <link name="arm_l">
    <visual>
      <origin rpy="0 0 0" xyz="0 0 0"/>
      <geometry>
        <mesh filename="package://kuroko_description/meshes/kuroko/obj/arm_l.obj"/>
      </geometry>
    </visual>
    <collision>
      <origin rpy="0 0 0" xyz="0 0.0385 -0.02575"/>
      <geometry>
        <box size="0.0285 0.1045 0.08"/>
      </geometry>
    </collision>
    <inertial>
      <origin rpy="0 0 0" xyz="0 0.0385 -0.02575"/>
      <mass value="0.342"/>
      <inertia ixx="0.000493627125" ixy="0.0" ixz="0.0" iyy="0.000205549125" iyz="0.0" izz="0.00033437625"/>
    </inertial>
  </link>
  <joint name="scissor_lf_joint" type="revolute">
    <parent link="arm_l"/>
    <child link="scissor_lf"/>
    <origin rpy="0 0 0" xyz="0 0.0265 -0.0545"/>
    <axis xyz="0 -1 0"/>
    <limit effort="1000.0" lower="-2.6180" upper="2.6180" velocity="10.0"/>
    <dynamics damping="0.0" friction="0.0"/>
  </joint>
  <link name="scissor_lf">
    <visual>
      <origin rpy="0 0 0" xyz="0 0 0"/>
      <geometry>
        <mesh filename="package://kuroko_description/meshes/kuroko/obj/scissor_lf.obj"/>
      </geometry>
    </visual>
    <collision>
      <origin rpy="0 0 0" xyz="0.0043 0 -0.104"/>
      <geometry>
        <box size="0.01085 0.058 0.208"/>
      </geometry>
    </collision>
    <collision>
      <origin rpy="0 0 0" xyz="-0.0206 0 -0.201"/>
      <geometry>
        <box size="0.039 0.058 0.014"/>
      </geometry>
    </collision>
    <inertial>
      <origin rpy="0 0 0" xyz="0.0043 0 -0.104"/>
      <mass value="0.032"/>
      <inertia ixx="0.000124341333333" ixy="0.0" ixz="0.0" iyy="0.000120533333333" iyz="0.0" izz="1.41333333333e-05"/>
    </inertial>
  </link>
  <joint name="scissor_lr_joint" type="revolute">
    <parent link="arm_l"/>
    <child link="scissor_lr"/>
    <origin rpy="0 0 0" xyz="0 0.0265 -0.0545"/>
    <axis xyz="0 1 0"/>
    <limit effort="1000.0" lower="-2.6180" upper="2.6180" velocity="10.0"/>
    <dynamics damping="0.0" friction="0.0"/>
  </joint>
  <link name="scissor_lr">
    <visual>
      <origin rpy="0 0 0" xyz="0 0 0"/>
      <geometry>
        <mesh filename="package://kuroko_description/meshes/kuroko/obj/scissor_lr.obj"/>
      </geometry>
    </visual>
    <collision>
      <origin rpy="0 0 0" xyz="-0.0043 0 -0.1"/>
      <geometry>
        <box size="0.01085 0.044 0.2"/>
      </geometry>
    </collision>
    <collision>
      <origin rpy="0 0 0" xyz="0.0206 0 -0.193"/>
      <geometry>
        <box size="0.039 0.044 0.014"/>
      </geometry>
    </collision>
    <inertial>
      <origin rpy="0 0 0" xyz="-0.0043 0 -0.1"/>
      <mass value="0.031"/>
      <inertia ixx="0.000108334666667" ixy="0.0" ixz="0.0" iyy="0.000108334666667" iyz="0.0" izz="1.00026666667e-05"/>
    </inertial>
  </link>
  <gazebo reference="shoulder_l_joint">
    <implicitSpringDamper>1</implicitSpringDamper>
  </gazebo>
  <transmission name="shoulder_l_joint_trans">
    <type>transmission_interface/SimpleTransmission</type>
    <joint name="shoulder_l_joint">
      <hardwareInterface>hardware_interface/PositionJointInterface</hardwareInterface>
    </joint>
    <actuator name="shoulder_l_joint_motor">
      <hardwareInterface>hardware_interface/PositionJointInterface</hardwareInterface>
      <mechanicalReduction>1</mechanicalReduction>
    </actuator>
  </transmission>
  <gazebo reference="arm_l_joint">
    <implicitSpringDamper>1</implicitSpringDamper>
  </gazebo>
  <transmission name="arm_l_joint_trans">
    <type>transmission_interface/SimpleTransmission</type>
    <joint name="arm_l_joint">
      <hardwareInterface>hardware_interface/PositionJointInterface</hardwareInterface>
    </joint>
    <actuator name="arm_l_joint_motor">
      <hardwareInterface>hardware_interface/PositionJointInterface</hardwareInterface>
      <mechanicalReduction>1</mechanicalReduction>
    </actuator>
  </transmission>
  <gazebo reference="scissor_lf_joint">
    <implicitSpringDamper>1</implicitSpringDamper>
  </gazebo>
  <transmission name="scissor_lf_joint_trans">
    <type>transmission_interface/SimpleTransmission</type>
    <joint name="scissor_lf_joint">
      <hardwareInterface>hardware_interface/PositionJointInterface</hardwareInterface>
    </joint>
    <actuator name="scissor_lf_joint_motor">
      <hardwareInterface>hardware_interface/PositionJointInterface</hardwareInterface>
      <mechanicalReduction>1</mechanicalReduction>
    </actuator>
  </transmission>
  <gazebo reference="scissor_lr_joint">
    <implicitSpringDamper>1</implicitSpringDamper>
  </gazebo>
  <transmission name="scissor_lr_joint_trans">
    <type>transmission_interface/SimpleTransmission</type>
    <joint name="scissor_lr_joint">
      <hardwareInterface>hardware_interface/PositionJointInterface</hardwareInterface>
    </joint>
    <actuator name="scissor_lr_joint_motor">
      <hardwareInterface>hardware_interface/PositionJointInterface</hardwareInterface>
      <mechanicalReduction>1</mechanicalReduction>
    </actuator>
  </transmission>
  <gazebo reference="shoulder_l">
    <kp>1000000.0</kp>
    <kd>100.0</kd>
    <mu1>0.01</mu1>
    <maxVel>10.0</maxVel>
    <minDepth>0.0001</minDepth>
    <maxContacts>6</maxContacts>
    <selfCollide>false</selfCollide>
    <dampingFactor>0</dampingFactor>
  </gazebo>
  <gazebo reference="arm_l">
    <kp>1000000.0</kp>
    <kd>100.0</kd>
    <mu1>0.01</mu1>
    <maxVel>10.0</maxVel>
    <minDepth>0.0001</minDepth>
    <maxContacts>6</maxContacts>
    <selfCollide>false</selfCollide>
    <dampingFactor>0</dampingFactor>
  </gazebo>
  <gazebo reference="scissor_lf">
    <kp>1000000.0</kp>
    <kd>100.0</kd>
    <mu1>0.01</mu1>
    <maxVel>10.0</maxVel>
    <minDepth>0.0001</minDepth>
    <maxContacts>6</maxContacts>
    <selfCollide>false</selfCollide>
    <dampingFactor>0</dampingFactor>
  </gazebo>
  <gazebo reference="scissor_lr">
    <kp>1000000.0</kp>
    <kd>100.0</kd>
    <mu1>0.01</mu1>
    <maxVel>10.0</maxVel>
    <minDepth>0.0001</minDepth>
    <maxContacts>6</maxContacts>
    <selfCollide>false</selfCollide>
    <dampingFactor>0</dampingFactor>
  </gazebo>
  <!-- Link conencts from body. Femoral first. -->
  <joint name="crotch_r_joint" type="revolute">
    <parent link="waist"/>
    <child link="crotch_r"/>
    <origin rpy="0 0 0" xyz="0.00125 0 -0.08425"/>
    <axis xyz="1 0 0"/>
    <limit effort="1000.0" lower="-0.5550" upper="1.8640" velocity="10.0"/>
    <dynamics damping="0.0" friction="0.0"/>
  </joint>
  <link name="crotch_r">
    <visual>
      <origin rpy="0 0 0" xyz="0 0 0"/>
      <geometry>
        <mesh filename="package://kuroko_description/meshes/kuroko/obj/crotch_r.obj"/>
      </geometry>
    </visual>
    <collision>
      <origin rpy="0 0 0" xyz="0 -0.0065 -0.004125"/>
      <geometry>
        <box size="0.092 0.041 0.03625"/>
      </geometry>
    </collision>
    <inertial>
      <origin rpy="0 0 0" xyz="0 -0.0065 -0.004125"/>
      <mass value="0.026"/>
      <inertia ixx="1e-05" ixy="0.0" ixz="0.0" iyy="2.11858020833e-05" iyz="0.0" izz="2.19808333333e-05"/>
    </inertial>
  </link>
  <joint name="thigh_r_01_joint" type="revolute">
    <parent link="crotch_r"/>
    <child link="thigh_r_01"/>
    <origin rpy="0 0 0" xyz="0 -0.027 0"/>
    <axis xyz="0 -1 0"/>
    <limit effort="1000.0" lower="-3.1" upper="3.1" velocity="10.0"/>
    <dynamics damping="0.0" friction="0.0"/>
  </joint>
  <link name="thigh_r_01">
    <visual>
      <origin rpy="0 0 0" xyz="0 0 0"/>
      <geometry>
        <mesh filename="package://kuroko_description/meshes/kuroko/obj/thigh_r_01.obj"/>
      </geometry>
    </visual>
    <collision>
      <origin rpy="0 0 0" xyz="-0.00175 -0.049 -0.015"/>
      <geometry>
        <box size="0.067 0.098 0.0585"/>
      </geometry>
    </collision>
    <inertial>
      <origin rpy="0 0 0" xyz="-0.00175 -0.049 -0.015"/>
      <mass value="0.478"/>
      <inertia ixx="0.000518878958333" ixy="0.0" ixz="0.0" iyy="0.000315131458333" iyz="0.0" izz="0.000561371166667"/>
    </inertial>
  </link>
  <joint name="thigh_r_02_joint" type="revolute">
    <parent link="thigh_r_01"/>
    <child link="thigh_r_02"/>
    <origin rpy="0 -0.785398163 0" xyz="0.015 -0.02925 -0.0305"/>
    <axis xyz="0 1 0"/>
    <limit effort="1000.0" lower="-0.4974" upper="1.8588" velocity="10.0"/>
    <dynamics damping="0.0" friction="0.0"/>
  </joint>
  <link name="thigh_r_02">
    <visual>
      <origin rpy="0 0 0" xyz="0 0 0"/>
      <geometry>
        <mesh filename="package://kuroko_description/meshes/kuroko/obj/thigh_r_02.obj"/>
      </geometry>
    </visual>
    <collision>
      <origin rpy="0 0 0" xyz="0 0 -0.05"/>
      <geometry>
        <box size="0.014 0.0445 0.114"/>
      </geometry>
    </collision>
    <inertial>
      <origin rpy="0 0 0" xyz="0 0 -0.05"/>
      <mass value="0.012"/>
      <inertia ixx="1.497625e-05" ixy="0.0" ixz="0.0" iyy="1.3192e-05" iyz="0.0" izz="1e-05"/>
    </inertial>
  </link>
  <joint name="thigh_r_03_joint" type="revolute">
    <parent link="thigh_r_01"/>
    <child link="thigh_r_03"/>
    <origin rpy="0 1.047197551 0" xyz="-0.0185 -0.02925 -0.0305"/>
    <axis xyz="0 1 0"/>
    <limit effort="1000.0" lower="-1.8588" upper="0.4974" velocity="10.0"/>
    <dynamics damping="0.0" friction="0.0"/>
  </joint>
  <link name="thigh_r_03">
    <visual>
      <origin rpy="0 0 0" xyz="0 0 0"/>
      <geometry>
        <mesh filename="package://kuroko_description/meshes/kuroko/obj/thigh_r_03.obj"/>
      </geometry>
    </visual>
    <collision>
      <origin rpy="0 0 0" xyz="-0.004745 0 -0.015"/>
      <geometry>
        <box size="0.02349 0.0445 0.044"/>
      </geometry>
    </collision>
    <inertial>
      <origin rpy="0 0 0" xyz="-0.004745 0 -0.015"/>
      <mass value="0.008"/>
      <inertia ixx="1e-05" ixy="0.0" ixz="0.0" iyy="1e-05" iyz="0.0" izz="1e-05"/>
    </inertial>
  </link>
  <joint name="thigh_r_04_joint" type="revolute">
    <parent link="thigh_r_01"/>
    <child link="thigh_r_04"/>
    <origin rpy="0 -0.785398163 0" xyz="-0.0185 -0.02925 -0.0305"/>
    <axis xyz="0 1 0"/>
    <limit effort="1000.0" lower="-3.1" upper="3.1" velocity="10.0"/>
    <dynamics damping="0.0" friction="0.0"/>
    <mimic joint="thigh_r_02_joint" multiplier="1" offset="0"/>
  </joint>
  <link name="thigh_r_04">
    <visual>
      <origin rpy="0 0 0" xyz="0 0 0"/>
      <geometry>
        <mesh filename="package://kuroko_description/meshes/kuroko/obj/thigh_r_04.obj"/>
      </geometry>
    </visual>
    <collision>
      <origin rpy="0 0 0" xyz="0 0 -0.05"/>
      <geometry>
        <box size="0.014 0.0345 0.114"/>
      </geometry>
    </collision>
    <inertial>
      <origin rpy="0 0 0" xyz="0 0 -0.05"/>
      <mass value="0.012"/>
      <inertia ixx="1.418625e-05" ixy="0.0" ixz="0.0" iyy="1.3192e-05" iyz="0.0" izz="1e-05"/>
    </inertial>
  </link>
  <joint name="thigh_r_05_mimic1" type="revolute">
    <parent link="thigh_r_03"/>
    <child link="thigh_r_05_mimic"/>
    <origin rpy="0 -1.832597551 0" xyz="0 0 -0.03"/>
    <axis xyz="0 1 0"/>
    <limit effort="1000.0" lower="-3.1" upper="3.1" velocity="10.0"/>
    <dynamics damping="0.0" friction="0.0"/>
    <mimic joint="thigh_r_03_joint" multiplier="-1" offset="0"/>
  </joint>
  <link name="thigh_r_05_mimic"/>
  <joint name="thigh_r_05_mimic2" type="revolute">
    <parent link="thigh_r_05_mimic"/>
    <child link="thigh_r_05"/>
    <origin rpy="0 0 0" xyz="0 0 0"/>
    <axis xyz="0 1 0"/>
    <limit effort="1000.0" lower="-3.1" upper="3.1" velocity="10.0"/>
    <dynamics damping="0.0" friction="0.0"/>
    <mimic joint="thigh_r_02_joint" multiplier="1" offset="0"/>
  </joint>
  <link name="thigh_r_05">
    <visual>
      <origin rpy="0 0 0" xyz="0 0 0"/>
      <geometry>
        <mesh filename="package://kuroko_description/meshes/kuroko/obj/thigh_r_05.obj"/>
      </geometry>
    </visual>
    <collision>
      <origin rpy="0 0 0" xyz="0 0 -0.05"/>
      <geometry>
        <box size="0.014 0.0285 0.114"/>
      </geometry>
    </collision>
    <inertial>
      <origin rpy="0 0 0" xyz="0 0 -0.05"/>
      <mass value="0.011"/>
      <inertia ixx="1.26575625e-05" ixy="0.0" ixz="0.0" iyy="1.20926666667e-05" iyz="0.0" izz="1e-05"/>
    </inertial>
  </link>
  <joint name="knee_r_joint" type="revolute">
    <parent link="thigh_r_02"/>
    <child link="knee_r"/>
    <origin rpy="0 0.785398163 0" xyz="0 0 -0.1"/>
    <axis xyz="0 1 0"/>
    <limit effort="1000.0" lower="-1.8588" upper="0.4974" velocity="10.0"/>
    <dynamics damping="0.0" friction="0.0"/>
    <mimic joint="thigh_r_02_joint" multiplier="-1" offset="0"/>
  </joint>
  <link name="knee_r">
    <visual>
      <origin rpy="0 0 0" xyz="0 0 0"/>
      <geometry>
        <mesh filename="package://kuroko_description/meshes/kuroko/obj/knee_r.obj"/>
      </geometry>
    </visual>
    <collision>
      <origin rpy="0 0 0" xyz="-0.01675 0 0"/>
      <geometry>
        <box size="0.0475 0.0505 0.014"/>
      </geometry>
    </collision>
    <inertial>
      <origin rpy="0 0 0" xyz="-0.01675 0 0"/>
      <mass value="0.007"/>
      <inertia ixx="1e-05" ixy="0.0" ixz="0.0" iyy="1e-05" iyz="0.0" izz="1e-05"/>
    </inertial>
  </link>
  <joint name="leg_r_01_joint" type="revolute">
    <parent link="knee_r"/>
    <child link="leg_r_01"/>
    <origin rpy="0 0.785398163 0" xyz="0 0 0"/>
    <axis xyz="0 1 0"/>
    <limit effort="1000.0" lower="-1.8588" upper="0.4974" velocity="10.0"/>
    <dynamics damping="0.0" friction="0.0"/>
    <mimic joint="thigh_r_03_joint" multiplier="1" offset="0"/>
  </joint>
  <link name="leg_r_01">
    <visual>
      <origin rpy="0 0 0" xyz="0 0 0"/>
      <geometry>
        <mesh filename="package://kuroko_description/meshes/kuroko/obj/leg_r_01.obj"/>
      </geometry>
    </visual>
    <collision>
      <origin rpy="0 0 0" xyz="0 0 -0.05"/>
      <geometry>
        <box size="0.014 0.0385 0.114"/>
      </geometry>
    </collision>
    <inertial>
      <origin rpy="0 0 0" xyz="0 0 -0.05"/>
      <mass value="0.013"/>
      <inertia ixx="1.56847708333e-05" ixy="0.0" ixz="0.0" iyy="1.42913333333e-05" iyz="0.0" izz="1e-05"/>
    </inertial>
  </link>
  <joint name="leg_r_02_joint" type="revolute">
    <parent link="knee_r"/>
    <child link="leg_r_02"/>
    <origin rpy="0 0.785398163 0" xyz="-0.0335 0 0"/>
    <axis xyz="0 1 0"/>
    <limit effort="1000.0" lower="-1.8588" upper="0.4974" velocity="10.0"/>
    <dynamics damping="0.0" friction="0.0"/>
    <mimic joint="thigh_r_03_joint" multiplier="1" offset="0"/>
  </joint>
  <link name="leg_r_02">
    <visual>
      <origin rpy="0 0 0" xyz="0 0 0"/>
      <geometry>
        <mesh filename="package://kuroko_description/meshes/kuroko/obj/leg_r_02.obj"/>
      </geometry>
    </visual>
    <collision>
      <origin rpy="0 0 0" xyz="0 0 -0.05"/>
      <geometry>
        <box size="0.014 0.0445 0.114"/>
      </geometry>
    </collision>
    <inertial>
      <origin rpy="0 0 0" xyz="0 0 -0.05"/>
      <mass value="0.016"/>
      <inertia ixx="1.99683333333e-05" ixy="0.0" ixz="0.0" iyy="1.75893333333e-05" iyz="0.0" izz="1e-05"/>
    </inertial>
  </link>
  <joint name="ankle_r_01_joint" type="revolute">
    <parent link="leg_r_01"/>
    <child link="ankle_r_01"/>
    <origin rpy="0 -0.785398163 0" xyz="0 0 -0.1"/>
    <axis xyz="0 1 0"/>
    <limit effort="1000.0" lower="-0.4974" upper="1.8588" velocity="10.0"/>
    <dynamics damping="0.0" friction="0.0"/>
    <mimic joint="thigh_r_03_joint" multiplier="-1" offset="0"/>
  </joint>
  <link name="ankle_r_01">
    <visual>
      <origin rpy="0 0 0" xyz="0 0 0"/>
      <geometry>
        <mesh filename="package://kuroko_description/meshes/kuroko/obj/ankle_r_01.obj"/>
      </geometry>
    </visual>
    <collision>
      <origin rpy="0 0 0" xyz="-0.0285 0 -0.013"/>
      <geometry>
        <box size="0.0855 0.0325 0.0465"/>
      </geometry>
    </collision>
    <inertial>
      <origin rpy="0 0 0" xyz="-0.0285 0 -0.013"/>
      <mass value="0.104"/>
      <inertia ixx="2.78936666667e-05" ixy="0.0" ixz="0.0" iyy="8.2095e-05" iyz="0.0" izz="7.25096666667e-05"/>
    </inertial>
  </link>
  <joint name="toe_r_01_joint" type="revolute">
    <parent link="ankle_r_01"/>
    <child link="toe_r_01"/>
    <origin rpy="0 0 0" xyz="-0.015 0 -0.025"/>
    <axis xyz="1 0 0"/>
    <limit effort="1000.0" lower="-0.3704" upper="1.5708" velocity="10.0"/>
    <dynamics damping="0.0" friction="0.0"/>
  </joint>
  <link name="toe_r_01">
    <visual>
      <origin rpy="0 0 0" xyz="0 0 0"/>
      <geometry>
        <mesh filename="package://kuroko_description/meshes/kuroko/obj/toe_r_01.obj"/>
      </geometry>
    </visual>
    <collision>
      <origin rpy="0 0 0" xyz="0 -0.009375 -0.01175"/>
      <geometry>
        <box size="0.0365 0.05375 0.043"/>
      </geometry>
    </collision>
    <inertial>
      <origin rpy="0 0 0" xyz="0 -0.009375 -0.01175"/>
      <mass value="0.136"/>
      <inertia ixx="5.36980416667e-05" ixy="0.0" ixz="0.0" iyy="3.60541666667e-05" iyz="0.0" izz="4.78415416667e-05"/>
    </inertial>
  </link>
  <joint name="toe_r_02_joint" type="revolute">
    <parent link="toe_r_01"/>
    <child link="toe_r_02"/>
    <origin rpy="0 0 0" xyz="0 0 -0.03825"/>
    <axis xyz="0 0 -1"/>
    <limit effort="1000.0" lower="-3.1" upper="3.1" velocity="10.0"/>
    <dynamics damping="0.0" friction="0.0"/>
  </joint>
  <link name="toe_r_02">
    <visual>
      <origin rpy="0 0 0" xyz="0 0 0"/>
      <geometry>
        <mesh filename="package://kuroko_description/meshes/kuroko/obj/toe_r_02.obj"/>
      </geometry>
    </visual>
    <collision>
      <origin rpy="0 0 0" xyz="0 0 -0.0025"/>
      <geometry>
        <box size="0.12 0.075 0.005"/>
      </geometry>
    </collision>
    <inertial>
      <origin rpy="0 0 0" xyz="0 0 -0.0025"/>
      <mass value="0.043"/>
      <inertia ixx="2.02458333333e-05" ixy="0.0" ixz="0.0" iyy="5.16895833333e-05" iyz="0.0" izz="7.175625e-05"/>
    </inertial>
  </link>
  <gazebo reference="crotch_r_joint">
    <implicitSpringDamper>1</implicitSpringDamper>
  </gazebo>
  <transmission name="crotch_r_joint_trans">
    <type>transmission_interface/SimpleTransmission</type>
    <joint name="crotch_r_joint">
      <hardwareInterface>hardware_interface/PositionJointInterface</hardwareInterface>
    </joint>
    <actuator name="crotch_r_joint_motor">
      <hardwareInterface>hardware_interface/PositionJointInterface</hardwareInterface>
      <mechanicalReduction>1</mechanicalReduction>
    </actuator>
  </transmission>
  <gazebo reference="thigh_r_01_joint">
    <implicitSpringDamper>1</implicitSpringDamper>
  </gazebo>
  <transmission name="thigh_r_01_joint_trans">
    <type>transmission_interface/SimpleTransmission</type>
    <joint name="thigh_r_01_joint">
      <hardwareInterface>hardware_interface/PositionJointInterface</hardwareInterface>
    </joint>
    <actuator name="thigh_r_01_joint_motor">
      <hardwareInterface>hardware_interface/PositionJointInterface</hardwareInterface>
      <mechanicalReduction>1</mechanicalReduction>
    </actuator>
  </transmission>
  <gazebo reference="thigh_r_02_joint">
    <implicitSpringDamper>1</implicitSpringDamper>
  </gazebo>
  <transmission name="thigh_r_02_joint_trans">
    <type>transmission_interface/SimpleTransmission</type>
    <joint name="thigh_r_02_joint">
      <hardwareInterface>hardware_interface/PositionJointInterface</hardwareInterface>
    </joint>
    <actuator name="thigh_r_02_joint_motor">
      <hardwareInterface>hardware_interface/PositionJointInterface</hardwareInterface>
      <mechanicalReduction>1</mechanicalReduction>
    </actuator>
  </transmission>
  <gazebo reference="thigh_r_03_joint">
    <implicitSpringDamper>1</implicitSpringDamper>
  </gazebo>
  <transmission name="thigh_r_03_joint_trans">
    <type>transmission_interface/SimpleTransmission</type>
    <joint name="thigh_r_03_joint">
      <hardwareInterface>hardware_interface/PositionJointInterface</hardwareInterface>
    </joint>
    <actuator name="thigh_r_03_joint_motor">
      <hardwareInterface>hardware_interface/PositionJointInterface</hardwareInterface>
      <mechanicalReduction>1</mechanicalReduction>
    </actuator>
  </transmission>
  <gazebo reference="toe_r_01_joint">
    <implicitSpringDamper>1</implicitSpringDamper>
  </gazebo>
  <transmission name="toe_r_01_joint_trans">
    <type>transmission_interface/SimpleTransmission</type>
    <joint name="toe_r_01_joint">
      <hardwareInterface>hardware_interface/PositionJointInterface</hardwareInterface>
    </joint>
    <actuator name="toe_r_01_joint_motor">
      <hardwareInterface>hardware_interface/PositionJointInterface</hardwareInterface>
      <mechanicalReduction>1</mechanicalReduction>
    </actuator>
  </transmission>
  <gazebo reference="toe_r_02_joint">
    <implicitSpringDamper>1</implicitSpringDamper>
  </gazebo>
  <transmission name="toe_r_02_joint_trans">
    <type>transmission_interface/SimpleTransmission</type>
    <joint name="toe_r_02_joint">
      <hardwareInterface>hardware_interface/PositionJointInterface</hardwareInterface>
    </joint>
    <actuator name="toe_r_02_joint_motor">
      <hardwareInterface>hardware_interface/PositionJointInterface</hardwareInterface>
      <mechanicalReduction>1</mechanicalReduction>
    </actuator>
  </transmission>
  <gazebo reference="thigh_r_04_joint">
    <physics>
      <ode>
        <implicit_spring_damper>1</implicit_spring_damper>
        <cfm_damping>0</cfm_damping>
        <cfm>1e-7</cfm>
        <erp>0.8</erp>
        <limit>
          <cfm>1e-7</cfm>
          <erp>0.8</erp>
        </limit>
      </ode>
    </physics>
  </gazebo>
  <gazebo reference="thigh_r_05_joint">
    <physics>
      <ode>
        <implicit_spring_damper>1</implicit_spring_damper>
        <cfm_damping>0</cfm_damping>
        <cfm>1e-7</cfm>
        <erp>0.8</erp>
        <limit>
          <cfm>1e-7</cfm>
          <erp>0.8</erp>
        </limit>
      </ode>
    </physics>
  </gazebo>
  <gazebo reference="knee_r_joint">
    <physics>
      <ode>
        <implicit_spring_damper>1</implicit_spring_damper>
        <cfm_damping>0</cfm_damping>
        <cfm>1e-7</cfm>
        <erp>0.8</erp>
        <limit>
          <cfm>1e-7</cfm>
          <erp>0.8</erp>
        </limit>
      </ode>
    </physics>
  </gazebo>
  <gazebo reference="leg_r_01_joint">
    <physics>
      <ode>
        <implicit_spring_damper>1</implicit_spring_damper>
        <cfm_damping>0</cfm_damping>
        <cfm>1e-7</cfm>
        <erp>0.8</erp>
        <limit>
          <cfm>1e-7</cfm>
          <erp>0.8</erp>
        </limit>
      </ode>
    </physics>
  </gazebo>
  <gazebo reference="leg_r_02_joint">
    <physics>
      <ode>
        <implicit_spring_damper>1</implicit_spring_damper>
        <cfm_damping>0</cfm_damping>
        <cfm>1e-7</cfm>
        <erp>0.8</erp>
        <limit>
          <cfm>1e-7</cfm>
          <erp>0.8</erp>
        </limit>
      </ode>
    </physics>
  </gazebo>
  <gazebo reference="ankle_r_01_joint">
    <physics>
      <ode>
        <implicit_spring_damper>1</implicit_spring_damper>
        <cfm_damping>0</cfm_damping>
        <cfm>1e-7</cfm>
        <erp>0.8</erp>
        <limit>
          <cfm>1e-7</cfm>
          <erp>0.8</erp>
        </limit>
      </ode>
    </physics>
  </gazebo>
  <gazebo reference="crotch_r">
    <kp>1000000.0</kp>
    <kd>100.0</kd>
    <mu1>0.01</mu1>
    <maxVel>10.0</maxVel>
    <minDepth>0.0001</minDepth>
    <maxContacts>6</maxContacts>
    <selfCollide>false</selfCollide>
    <dampingFactor>0</dampingFactor>
  </gazebo>
  <gazebo reference="thigh_r_01">
    <kp>1000000.0</kp>
    <kd>100.0</kd>
    <mu1>0.01</mu1>
    <maxVel>10.0</maxVel>
    <minDepth>0.0001</minDepth>
    <maxContacts>6</maxContacts>
    <selfCollide>false</selfCollide>
    <dampingFactor>0</dampingFactor>
  </gazebo>
  <gazebo reference="thigh_r_02">
    <kp>1000000.0</kp>
    <kd>100.0</kd>
    <mu1>0.0</mu1>
    <maxVel>10.0</maxVel>
    <minDepth>0.0001</minDepth>
    <maxContacts>6</maxContacts>
    <selfCollide>false</selfCollide>
    <dampingFactor>0</dampingFactor>
  </gazebo>
  <gazebo reference="thigh_r_03">
    <kp>1000000.0</kp>
    <kd>100.0</kd>
    <mu1>0.01</mu1>
    <maxVel>10.0</maxVel>
    <minDepth>0.0001</minDepth>
    <maxContacts>6</maxContacts>
    <selfCollide>false</selfCollide>
    <dampingFactor>0</dampingFactor>
  </gazebo>
  <gazebo reference="thigh_r_04">
    <kp>1000000.0</kp>
    <kd>100.0</kd>
    <mu1>0.0</mu1>
    <maxVel>10.0</maxVel>
    <minDepth>0.0001</minDepth>
    <maxContacts>6</maxContacts>
    <selfCollide>false</selfCollide>
    <dampingFactor>0</dampingFactor>
  </gazebo>
  <gazebo reference="thigh_r_05">
    <kp>1000000.0</kp>
    <kd>100.0</kd>
    <mu1>0.0</mu1>
    <maxVel>10.0</maxVel>
    <minDepth>0.0001</minDepth>
    <maxContacts>6</maxContacts>
    <selfCollide>false</selfCollide>
    <dampingFactor>0</dampingFactor>
  </gazebo>
  <gazebo reference="knee_r">
    <kp>1000000.0</kp>
    <kd>100.0</kd>
    <mu1>0.01</mu1>
    <maxVel>10.0</maxVel>
    <minDepth>0.0001</minDepth>
    <maxContacts>6</maxContacts>
    <selfCollide>false</selfCollide>
    <dampingFactor>0</dampingFactor>
  </gazebo>
  <gazebo reference="leg_r_01">
    <kp>1000000.0</kp>
    <kd>100.0</kd>
    <mu1>0.0</mu1>
    <maxVel>10.0</maxVel>
    <minDepth>0.0001</minDepth>
    <maxContacts>6</maxContacts>
    <selfCollide>false</selfCollide>
    <dampingFactor>0</dampingFactor>
  </gazebo>
  <gazebo reference="leg_r_02">
    <kp>1000000.0</kp>
    <kd>100.0</kd>
    <mu1>0.0</mu1>
    <maxVel>10.0</maxVel>
    <minDepth>0.0001</minDepth>
    <maxContacts>6</maxContacts>
    <selfCollide>false</selfCollide>
    <dampingFactor>0</dampingFactor>
  </gazebo>
  <gazebo reference="ankle_r_01">
    <kp>1000000.0</kp>
    <kd>100.0</kd>
    <mu1>0.01</mu1>
    <maxVel>10.0</maxVel>
    <minDepth>0.0001</minDepth>
    <maxContacts>6</maxContacts>
    <selfCollide>false</selfCollide>
    <dampingFactor>0</dampingFactor>
  </gazebo>
  <gazebo reference="toe_r_01">
    <kp>1000000.0</kp>
    <kd>100.0</kd>
    <mu1>0.0</mu1>
    <maxVel>10.0</maxVel>
    <minDepth>0.0001</minDepth>
    <maxContacts>6</maxContacts>
    <selfCollide>false</selfCollide>
    <dampingFactor>0</dampingFactor>
  </gazebo>
  <gazebo reference="toe_r_02">
    <kp>2000000.0</kp>
    <kd>200.0</kd>
    <mu1>1.0</mu1>
    <maxVel>1.0</maxVel>
    <minDepth>0.0001</minDepth>
    <maxContacts>5</maxContacts>
    <selfCollide>true</selfCollide>
    <dampingFactor>0.0</dampingFactor>
  </gazebo>
  <!-- Link conencts from body. Femoral first. -->
  <joint name="crotch_l_joint" type="revolute">
    <parent link="waist"/>
    <child link="crotch_l"/>
    <origin rpy="0 0 0" xyz="0.00125 0 -0.08425"/>
    <axis xyz="-1 0 0"/>
    <limit effort="1000.0" lower="-0.5550" upper="1.8640" velocity="10.0"/>
    <dynamics damping="0.0" friction="0.0"/>
  </joint>
  <link name="crotch_l">
    <visual>
      <origin rpy="0 0 0" xyz="0 0 0"/>
      <geometry>
        <mesh filename="package://kuroko_description/meshes/kuroko/obj/crotch_l.obj"/>
      </geometry>
    </visual>
    <collision>
      <origin rpy="0 0 0" xyz="0 0.0065 -0.004125"/>
      <geometry>
        <box size="0.092 0.041 0.03625"/>
      </geometry>
    </collision>
    <inertial>
      <origin rpy="0 0 0" xyz="0 0.0065 -0.004125"/>
      <mass value="0.026"/>
      <inertia ixx="1e-05" ixy="0.0" ixz="0.0" iyy="2.11858020833e-05" iyz="0.0" izz="2.19808333333e-05"/>
    </inertial>
  </link>
  <joint name="thigh_l_01_joint" type="revolute">
    <parent link="crotch_l"/>
    <child link="thigh_l_01"/>
    <origin rpy="0 0 0" xyz="0 0.027 0"/>
    <axis xyz="0 1 0"/>
    <limit effort="1000.0" lower="-3.1" upper="3.1" velocity="10.0"/>
    <dynamics damping="0.0" friction="0.0"/>
  </joint>
  <link name="thigh_l_01">
    <visual>
      <origin rpy="0 0 0" xyz="0 0 0"/>
      <geometry>
        <mesh filename="package://kuroko_description/meshes/kuroko/obj/thigh_l_01.obj"/>
      </geometry>
    </visual>
    <collision>
      <origin rpy="0 0 0" xyz="-0.00175 0.049 -0.015"/>
      <geometry>
        <box size="0.067 0.098 0.0585"/>
      </geometry>
    </collision>
    <inertial>
      <origin rpy="0 0 0" xyz="-0.00175 0.049 -0.015"/>
      <mass value="0.478"/>
      <inertia ixx="0.000518878958333" ixy="0.0" ixz="0.0" iyy="0.000315131458333" iyz="0.0" izz="0.000561371166667"/>
    </inertial>
  </link>
  <joint name="thigh_l_02_joint" type="revolute">
    <parent link="thigh_l_01"/>
    <child link="thigh_l_02"/>
    <origin rpy="0 -0.785398163 0" xyz="0.015 0.02925 -0.0305"/>
    <axis xyz="0 -1 0"/>
    <limit effort="1000.0" lower="-1.8588" upper="0.4974" velocity="10.0"/>
    <dynamics damping="0.0" friction="0.0"/>
  </joint>
  <link name="thigh_l_02">
    <visual>
      <origin rpy="0 0 0" xyz="0 0 0"/>
      <geometry>
        <mesh filename="package://kuroko_description/meshes/kuroko/obj/thigh_l_02.obj"/>
      </geometry>
    </visual>
    <collision>
      <origin rpy="0 0 0" xyz="0 0 -0.05"/>
      <geometry>
        <box size="0.014 0.0445 0.114"/>
      </geometry>
    </collision>
    <inertial>
      <origin rpy="0 0 0" xyz="0 0 -0.05"/>
      <mass value="0.012"/>
      <inertia ixx="1.497625e-05" ixy="0.0" ixz="0.0" iyy="1.3192e-05" iyz="0.0" izz="1e-05"/>
    </inertial>
  </link>
  <joint name="thigh_l_03_joint" type="revolute">
    <parent link="thigh_l_01"/>
    <child link="thigh_l_03"/>
    <origin rpy="0 1.047197551 0" xyz="-0.0185 0.02925 -0.0305"/>
    <axis xyz="0 -1 0"/>
    <limit effort="1000.0" lower="-0.4974" upper="1.8588" velocity="10.0"/>
    <dynamics damping="0.0" friction="0.0"/>
  </joint>
  <link name="thigh_l_03">
    <visual>
      <origin rpy="0 0 0" xyz="0 0 0"/>
      <geometry>
        <mesh filename="package://kuroko_description/meshes/kuroko/obj/thigh_l_03.obj"/>
      </geometry>
    </visual>
    <collision>
      <origin rpy="0 0 0" xyz="-0.004745 0 -0.015"/>
      <geometry>
        <box size="0.02349 0.0445 0.044"/>
      </geometry>
    </collision>
    <inertial>
      <origin rpy="0 0 0" xyz="-0.004745 0 -0.015"/>
      <mass value="0.008"/>
      <inertia ixx="1e-05" ixy="0.0" ixz="0.0" iyy="1e-05" iyz="0.0" izz="1e-05"/>
    </inertial>
  </link>
  <joint name="thigh_l_04_joint" type="revolute">
    <parent link="thigh_l_01"/>
    <child link="thigh_l_04"/>
    <origin rpy="0 -0.785398163 0" xyz="-0.0185 0.02925 -0.0305"/>
    <axis xyz="0 -1 0"/>
    <limit effort="1000.0" lower="-3.1" upper="3.1" velocity="10.0"/>
    <dynamics damping="0.0" friction="0.0"/>
    <mimic joint="thigh_l_02_joint" multiplier="1" offset="0"/>
  </joint>
  <link name="thigh_l_04">
    <visual>
      <origin rpy="0 0 0" xyz="0 0 0"/>
      <geometry>
        <mesh filename="package://kuroko_description/meshes/kuroko/obj/thigh_r_04.obj"/>
      </geometry>
    </visual>
    <collision>
      <origin rpy="0 0 0" xyz="0 0 -0.05"/>
      <geometry>
        <box size="0.014 0.0345 0.114"/>
      </geometry>
    </collision>
    <inertial>
      <origin rpy="0 0 0" xyz="0 0 -0.05"/>
      <mass value="0.012"/>
      <inertia ixx="1.418625e-05" ixy="0.0" ixz="0.0" iyy="1.3192e-05" iyz="0.0" izz="1e-05"/>
    </inertial>
  </link>
  <joint name="thigh_l_05_mimic1" type="revolute">
    <parent link="thigh_l_03"/>
    <child link="thigh_l_05_mimic"/>
    <origin rpy="0 -1.832597551 0" xyz="0 0 -0.03"/>
    <axis xyz="0 -1 0"/>
    <limit effort="1000.0" lower="-3.1" upper="3.1" velocity="10.0"/>
    <dynamics damping="0.0" friction="0.0"/>
    <mimic joint="thigh_l_03_joint" multiplier="-1" offset="0"/>
  </joint>
  <link name="thigh_l_05_mimic"/>
  <joint name="thigh_l_05_mimic2" type="revolute">
    <parent link="thigh_l_05_mimic"/>
    <child link="thigh_l_05"/>
    <origin rpy="0 0 0" xyz="0 0 0"/>
    <axis xyz="0 -1 0"/>
    <limit effort="1000.0" lower="-3.1" upper="3.1" velocity="10.0"/>
    <dynamics damping="0.0" friction="0.0"/>
    <mimic joint="thigh_l_02_joint" multiplier="1" offset="0"/>
  </joint>
  <link name="thigh_l_05">
    <visual>
      <origin rpy="0 0 0" xyz="0 0 0"/>
      <geometry>
        <mesh filename="package://kuroko_description/meshes/kuroko/obj/thigh_r_05.obj"/>
      </geometry>
    </visual>
    <collision>
      <origin rpy="0 0 0" xyz="0 0 -0.05"/>
      <geometry>
        <box size="0.014 0.0285 0.114"/>
      </geometry>
    </collision>
    <inertial>
      <origin rpy="0 0 0" xyz="0 0 -0.05"/>
      <mass value="0.011"/>
      <inertia ixx="1.26575625e-05" ixy="0.0" ixz="0.0" iyy="1.20926666667e-05" iyz="0.0" izz="1e-05"/>
    </inertial>
  </link>
  <joint name="knee_l_joint" type="revolute">
    <parent link="thigh_l_02"/>
    <child link="knee_l"/>
    <origin rpy="0 0.785398163 0" xyz="0 0 -0.1"/>
    <axis xyz="0 -1 0"/>
    <limit effort="1000.0" lower="-0.4974" upper="1.8588" velocity="10.0"/>
    <dynamics damping="0.0" friction="0.0"/>
    <mimic joint="thigh_l_02_joint" multiplier="-1" offset="0"/>
  </joint>
  <link name="knee_l">
    <visual>
      <origin rpy="0 0 0" xyz="0 0 0"/>
      <geometry>
        <mesh filename="package://kuroko_description/meshes/kuroko/obj/knee_r.obj"/>
      </geometry>
    </visual>
    <collision>
      <origin rpy="0 0 0" xyz="-0.01675 0 0"/>
      <geometry>
        <box size="0.0475 0.0505 0.014"/>
      </geometry>
    </collision>
    <inertial>
      <origin rpy="0 0 0" xyz="-0.01675 0 0"/>
      <mass value="0.007"/>
      <inertia ixx="1e-05" ixy="0.0" ixz="0.0" iyy="1e-05" iyz="0.0" izz="1e-05"/>
    </inertial>
  </link>
  <joint name="leg_l_01_joint" type="revolute">
    <parent link="knee_l"/>
    <child link="leg_l_01"/>
    <origin rpy="0 0.785398163 0" xyz="0 0 0"/>
    <axis xyz="0 -1 0"/>
    <limit effort="1000.0" lower="-0.4974" upper="1.8588" velocity="10.0"/>
    <dynamics damping="0.0" friction="0.0"/>
    <mimic joint="thigh_l_03_joint" multiplier="1" offset="0"/>
  </joint>
  <link name="leg_l_01">
    <visual>
      <origin rpy="0 0 0" xyz="0 0 0"/>
      <geometry>
        <mesh filename="package://kuroko_description/meshes/kuroko/obj/leg_r_01.obj"/>
      </geometry>
    </visual>
    <collision>
      <origin rpy="0 0 0" xyz="0 0 -0.05"/>
      <geometry>
        <box size="0.014 0.0385 0.114"/>
      </geometry>
    </collision>
    <inertial>
      <origin rpy="0 0 0" xyz="0 0 -0.05"/>
      <mass value="0.013"/>
      <inertia ixx="1.56847708333e-05" ixy="0.0" ixz="0.0" iyy="1.42913333333e-05" iyz="0.0" izz="1e-05"/>
    </inertial>
  </link>
  <joint name="leg_l_02_joint" type="revolute">
    <parent link="knee_l"/>
    <child link="leg_l_02"/>
    <origin rpy="0 0.785398163 0" xyz="-0.0335 0 0"/>
    <axis xyz="0 -1 0"/>
    <limit effort="1000.0" lower="-0.4974" upper="1.8588" velocity="10.0"/>
    <dynamics damping="0.0" friction="0.0"/>
    <mimic joint="thigh_l_03_joint" multiplier="1" offset="0"/>
  </joint>
  <link name="leg_l_02">
    <visual>
      <origin rpy="0 0 0" xyz="0 0 0"/>
      <geometry>
        <mesh filename="package://kuroko_description/meshes/kuroko/obj/leg_r_02.obj"/>
      </geometry>
    </visual>
    <collision>
      <origin rpy="0 0 0" xyz="0 0 -0.05"/>
      <geometry>
        <box size="0.014 0.0445 0.114"/>
      </geometry>
    </collision>
    <inertial>
      <origin rpy="0 0 0" xyz="0 0 -0.05"/>
      <mass value="0.016"/>
      <inertia ixx="1.99683333333e-05" ixy="0.0" ixz="0.0" iyy="1.75893333333e-05" iyz="0.0" izz="1e-05"/>
    </inertial>
  </link>
  <joint name="ankle_l_01_joint" type="revolute">
    <parent link="leg_l_01"/>
    <child link="ankle_l_01"/>
    <origin rpy="0 -0.785398163 0" xyz="0 0 -0.1"/>
    <axis xyz="0 -1 0"/>
    <limit effort="1000.0" lower="-1.8588" upper="0.4974" velocity="10.0"/>
    <dynamics damping="0.0" friction="0.0"/>
    <mimic joint="thigh_l_03_joint" multiplier="-1" offset="0"/>
  </joint>
  <link name="ankle_l_01">
    <visual>
      <origin rpy="0 0 0" xyz="0 0 0"/>
      <geometry>
        <mesh filename="package://kuroko_description/meshes/kuroko/obj/ankle_r_01.obj"/>
      </geometry>
    </visual>
    <collision>
      <origin rpy="0 0 0" xyz="-0.0285 0 -0.013"/>
      <geometry>
        <box size="0.0855 0.0325 0.0465"/>
      </geometry>
    </collision>
    <inertial>
      <origin rpy="0 0 0" xyz="-0.0285 0 -0.013"/>
      <mass value="0.104"/>
      <inertia ixx="2.78936666667e-05" ixy="0.0" ixz="0.0" iyy="8.2095e-05" iyz="0.0" izz="7.25096666667e-05"/>
    </inertial>
  </link>
  <joint name="toe_l_01_joint" type="revolute">
    <parent link="ankle_l_01"/>
    <child link="toe_l_01"/>
    <origin rpy="0 0 0" xyz="-0.015 0 -0.025"/>
    <axis xyz="1 0 0"/>
    <limit effort="1000.0" lower="-1.5708" upper="0.3704" velocity="10.0"/>
    <dynamics damping="0.0" friction="0.0"/>
  </joint>
  <link name="toe_l_01">
    <visual>
      <origin rpy="0 0 0" xyz="0 0 0"/>
      <geometry>
        <mesh filename="package://kuroko_description/meshes/kuroko/obj/toe_l_01.obj"/>
      </geometry>
    </visual>
    <collision>
      <origin rpy="0 0 0" xyz="0 0.009375 -0.01175"/>
      <geometry>
        <box size="0.0365 0.05375 0.043"/>
      </geometry>
    </collision>
    <inertial>
      <origin rpy="0 0 0" xyz="0 0.009375 -0.01175"/>
      <mass value="0.136"/>
      <inertia ixx="5.36980416667e-05" ixy="0.0" ixz="0.0" iyy="3.60541666667e-05" iyz="0.0" izz="4.78415416667e-05"/>
    </inertial>
  </link>
  <joint name="toe_l_02_joint" type="revolute">
    <parent link="toe_l_01"/>
    <child link="toe_l_02"/>
    <origin rpy="0 0 0" xyz="0 0 -0.03825"/>
    <axis xyz="0 0 -1"/>
    <limit effort="1000.0" lower="-3.1" upper="3.1" velocity="10.0"/>
    <dynamics damping="0.0" friction="0.0"/>
  </joint>
  <link name="toe_l_02">
    <visual>
      <origin rpy="0 0 0" xyz="0 0 0"/>
      <geometry>
        <mesh filename="package://kuroko_description/meshes/kuroko/obj/toe_r_02.obj"/>
      </geometry>
    </visual>
    <collision>
      <origin rpy="0 0 0" xyz="0 0 -0.0025"/>
      <geometry>
        <box size="0.12 0.075 0.005"/>
      </geometry>
    </collision>
    <inertial>
      <origin rpy="0 0 0" xyz="0 0 -0.0025"/>
      <mass value="0.043"/>
      <inertia ixx="2.02458333333e-05" ixy="0.0" ixz="0.0" iyy="5.16895833333e-05" iyz="0.0" izz="7.175625e-05"/>
    </inertial>
  </link>
  <gazebo reference="crotch_l_joint">
    <implicitSpringDamper>1</implicitSpringDamper>
  </gazebo>
  <transmission name="crotch_l_joint_trans">
    <type>transmission_interface/SimpleTransmission</type>
    <joint name="crotch_l_joint">
      <hardwareInterface>hardware_interface/PositionJointInterface</hardwareInterface>
    </joint>
    <actuator name="crotch_l_joint_motor">
      <hardwareInterface>hardware_interface/PositionJointInterface</hardwareInterface>
      <mechanicalReduction>1</mechanicalReduction>
    </actuator>
  </transmission>
  <gazebo reference="thigh_l_01_joint">
    <implicitSpringDamper>1</implicitSpringDamper>
  </gazebo>
  <transmission name="thigh_l_01_joint_trans">
    <type>transmission_interface/SimpleTransmission</type>
    <joint name="thigh_l_01_joint">
      <hardwareInterface>hardware_interface/PositionJointInterface</hardwareInterface>
    </joint>
    <actuator name="thigh_l_01_joint_motor">
      <hardwareInterface>hardware_interface/PositionJointInterface</hardwareInterface>
      <mechanicalReduction>1</mechanicalReduction>
    </actuator>
  </transmission>
  <gazebo reference="thigh_l_02_joint">
    <implicitSpringDamper>1</implicitSpringDamper>
  </gazebo>
  <transmission name="thigh_l_02_joint_trans">
    <type>transmission_interface/SimpleTransmission</type>
    <joint name="thigh_l_02_joint">
      <hardwareInterface>hardware_interface/PositionJointInterface</hardwareInterface>
    </joint>
    <actuator name="thigh_l_02_joint_motor">
      <hardwareInterface>hardware_interface/PositionJointInterface</hardwareInterface>
      <mechanicalReduction>1</mechanicalReduction>
    </actuator>
  </transmission>
  <gazebo reference="thigh_l_03_joint">
    <implicitSpringDamper>1</implicitSpringDamper>
  </gazebo>
  <transmission name="thigh_l_03_joint_trans">
    <type>transmission_interface/SimpleTransmission</type>
    <joint name="thigh_l_03_joint">
      <hardwareInterface>hardware_interface/PositionJointInterface</hardwareInterface>
    </joint>
    <actuator name="thigh_l_03_joint_motor">
      <hardwareInterface>hardware_interface/PositionJointInterface</hardwareInterface>
      <mechanicalReduction>1</mechanicalReduction>
    </actuator>
  </transmission>
  <gazebo reference="toe_l_01_joint">
    <implicitSpringDamper>1</implicitSpringDamper>
  </gazebo>
  <transmission name="toe_l_01_joint_trans">
    <type>transmission_interface/SimpleTransmission</type>
    <joint name="toe_l_01_joint">
      <hardwareInterface>hardware_interface/PositionJointInterface</hardwareInterface>
    </joint>
    <actuator name="toe_l_01_joint_motor">
      <hardwareInterface>hardware_interface/PositionJointInterface</hardwareInterface>
      <mechanicalReduction>1</mechanicalReduction>
    </actuator>
  </transmission>
  <gazebo reference="toe_l_02_joint">
    <implicitSpringDamper>1</implicitSpringDamper>
  </gazebo>
  <transmission name="toe_l_02_joint_trans">
    <type>transmission_interface/SimpleTransmission</type>
    <joint name="toe_l_02_joint">
      <hardwareInterface>hardware_interface/PositionJointInterface</hardwareInterface>
    </joint>
    <actuator name="toe_l_02_joint_motor">
      <hardwareInterface>hardware_interface/PositionJointInterface</hardwareInterface>
      <mechanicalReduction>1</mechanicalReduction>
    </actuator>
  </transmission>
  <gazebo reference="thigh_l_04_joint">
    <physics>
      <ode>
        <implicit_spring_damper>1</implicit_spring_damper>
        <cfm_damping>0</cfm_damping>
        <cfm>1e-7</cfm>
        <erp>0.8</erp>
        <limit>
          <cfm>1e-7</cfm>
          <erp>0.8</erp>
        </limit>
      </ode>
    </physics>
  </gazebo>
  <gazebo reference="thigh_l_05_joint">
    <physics>
      <ode>
        <implicit_spring_damper>1</implicit_spring_damper>
        <cfm_damping>0</cfm_damping>
        <cfm>1e-7</cfm>
        <erp>0.8</erp>
        <limit>
          <cfm>1e-7</cfm>
          <erp>0.8</erp>
        </limit>
      </ode>
    </physics>
  </gazebo>
  <gazebo reference="knee_l_joint">
    <physics>
      <ode>
        <implicit_spring_damper>1</implicit_spring_damper>
        <cfm_damping>0</cfm_damping>
        <cfm>1e-7</cfm>
        <erp>0.8</erp>
        <limit>
          <cfm>1e-7</cfm>
          <erp>0.8</erp>
        </limit>
      </ode>
    </physics>
  </gazebo>
  <gazebo reference="leg_l_01_joint">
    <physics>
      <ode>
        <implicit_spring_damper>1</implicit_spring_damper>
        <cfm_damping>0</cfm_damping>
        <cfm>1e-7</cfm>
        <erp>0.8</erp>
        <limit>
          <cfm>1e-7</cfm>
          <erp>0.8</erp>
        </limit>
      </ode>
    </physics>
  </gazebo>
  <gazebo reference="leg_l_02_joint">
    <physics>
      <ode>
        <implicit_spring_damper>1</implicit_spring_damper>
        <cfm_damping>0</cfm_damping>
        <cfm>1e-7</cfm>
        <erp>0.8</erp>
        <limit>
          <cfm>1e-7</cfm>
          <erp>0.8</erp>
        </limit>
      </ode>
    </physics>
  </gazebo>
  <gazebo reference="ankle_l_01_joint">
    <physics>
      <ode>
        <implicit_spring_damper>1</implicit_spring_damper>
        <cfm_damping>0</cfm_damping>
        <cfm>1e-7</cfm>
        <erp>0.8</erp>
        <limit>
          <cfm>1e-7</cfm>
          <erp>0.8</erp>
        </limit>
      </ode>
    </physics>
  </gazebo>
  <gazebo reference="crotch_l">
    <kp>1000000.0</kp>
    <kd>100.0</kd>
    <mu1>0.01</mu1>
    <maxVel>10.0</maxVel>
    <minDepth>0.0001</minDepth>
    <maxContacts>6</maxContacts>
    <selfCollide>false</selfCollide>
    <dampingFactor>0</dampingFactor>
  </gazebo>
  <gazebo reference="thigh_l_01">
    <kp>1000000.0</kp>
    <kd>100.0</kd>
    <mu1>0.01</mu1>
    <maxVel>10.0</maxVel>
    <minDepth>0.0001</minDepth>
    <maxContacts>6</maxContacts>
    <selfCollide>false</selfCollide>
    <dampingFactor>0</dampingFactor>
  </gazebo>
  <gazebo reference="thigh_l_02">
    <kp>1000000.0</kp>
    <kd>100.0</kd>
    <mu1>0.0</mu1>
    <maxVel>10.0</maxVel>
    <minDepth>0.0001</minDepth>
    <maxContacts>6</maxContacts>
    <selfCollide>false</selfCollide>
    <dampingFactor>0</dampingFactor>
  </gazebo>
  <gazebo reference="thigh_l_03">
    <kp>1000000.0</kp>
    <kd>100.0</kd>
    <mu1>0.01</mu1>
    <maxVel>10.0</maxVel>
    <minDepth>0.0001</minDepth>
    <maxContacts>6</maxContacts>
    <selfCollide>false</selfCollide>
    <dampingFactor>0</dampingFactor>
  </gazebo>
  <gazebo reference="thigh_l_04">
    <kp>1000000.0</kp>
    <kd>100.0</kd>
    <mu1>0.0</mu1>
    <maxVel>10.0</maxVel>
    <minDepth>0.0001</minDepth>
    <maxContacts>6</maxContacts>
    <selfCollide>false</selfCollide>
    <dampingFactor>0</dampingFactor>
  </gazebo>
  <gazebo reference="thigh_l_05">
    <kp>1000000.0</kp>
    <kd>100.0</kd>
    <mu1>0.0</mu1>
    <maxVel>10.0</maxVel>
    <minDepth>0.0001</minDepth>
    <maxContacts>6</maxContacts>
    <selfCollide>false</selfCollide>
    <dampingFactor>0</dampingFactor>
  </gazebo>
  <gazebo reference="knee_l">
    <kp>1000000.0</kp>
    <kd>100.0</kd>
    <mu1>0.01</mu1>
    <maxVel>10.0</maxVel>
    <minDepth>0.0001</minDepth>
    <maxContacts>6</maxContacts>
    <selfCollide>false</selfCollide>
    <dampingFactor>0</dampingFactor>
  </gazebo>
  <gazebo reference="leg_l_01">
    <kp>1000000.0</kp>
    <kd>100.0</kd>
    <mu1>0.0</mu1>
    <maxVel>10.0</maxVel>
    <minDepth>0.0001</minDepth>
    <maxContacts>6</maxContacts>
    <selfCollide>false</selfCollide>
    <dampingFactor>0</dampingFactor>
  </gazebo>
  <gazebo reference="leg_l_02">
    <kp>1000000.0</kp>
    <kd>100.0</kd>
    <mu1>0.0</mu1>
    <maxVel>10.0</maxVel>
    <minDepth>0.0001</minDepth>
    <maxContacts>6</maxContacts>
    <selfCollide>false</selfCollide>
    <dampingFactor>0</dampingFactor>
  </gazebo>
  <gazebo reference="ankle_l_01">
    <kp>1000000.0</kp>
    <kd>100.0</kd>
    <mu1>0.01</mu1>
    <maxVel>10.0</maxVel>
    <minDepth>0.0001</minDepth>
    <maxContacts>6</maxContacts>
    <selfCollide>false</selfCollide>
    <dampingFactor>0</dampingFactor>
  </gazebo>
  <gazebo reference="toe_l_01">
    <kp>1000000.0</kp>
    <kd>100.0</kd>
    <mu1>0.0</mu1>
    <maxVel>10.0</maxVel>
    <minDepth>0.0001</minDepth>
    <maxContacts>6</maxContacts>
    <selfCollide>false</selfCollide>
    <dampingFactor>0</dampingFactor>
  </gazebo>
  <gazebo reference="toe_l_02">
    <kp>2000000.0</kp>
    <kd>200.0</kd>
    <mu1>1.0</mu1>
    <maxVel>1.0</maxVel>
    <minDepth>0.0001</minDepth>
    <maxContacts>5</maxContacts>
    <selfCollide>true</selfCollide>
    <dampingFactor>0.0</dampingFactor>
  </gazebo>
  <joint name="imu_joint" type="fixed">
    <parent link="chest"/>
    <child link="imu_link"/>
    <origin rpy="0 0 0" xyz="-0.05 0 0.04425"/>
  </joint>
  <link name="imu_link">
    <visual>
      <origin rpy="0 0 0" xyz="0 0 0"/>
      <geometry>
        <box size="0.0245 0.0245 0.0145"/>
      </geometry>
      <material name="gray">
        <color rgba="0.5 0.5 0.5 1"/>
      </material>
    </visual>
    <collision>
      <origin rpy="0 0 0" xyz="0 0 0"/>
      <geometry>
        <box size="0.0245 0.0245 0.0145"/>
      </geometry>
    </collision>
    <inertial>
      <origin rpy="0 0 0" xyz="0 0 0"/>
      <mass value="0.013"/>
      <inertia ixx="1e-05" ixy="0.0" ixz="0.0" iyy="1e-05" iyz="0.0" izz="1e-05"/>
    </inertial>
  </link>
  <!-- gazebo extensions -->
  <gazebo reference="imu_joint">
    <disableFixedJointLumping>true</disableFixedJointLumping>
    <preserveFixedJoint>true</preserveFixedJoint>
  </gazebo>
  <gazebo reference="imu_link">
    <material>Gazebo/Gray</material>
  </gazebo>
  <gazebo>
    <plugin filename="libhector_gazebo_ros_imu.so" name="imu_controller">
      <alwaysOn>true</alwaysOn>
      <updateRate>400</updateRate>
      <bodyName>imu_link</bodyName>
      <topicName>imu/data</topicName>
      <serviceName>imu/service</serviceName>
      <frameId>imu_link</frameId>
      <gaussianNoise>0</gaussianNoise>
      <xyzOffset>0 0 0</xyzOffset>
      <rateOffset>0 0 0.01</rateOffset>
      <rpyOffset>0 0 0</rpyOffset>
    </plugin>
    <plugin filename="libhector_gazebo_ros_magnetic.so" name="magnetic_controller">
      <alwaysOn>true</alwaysOn>
      <updateRate>400</updateRate>
      <bodyName>imu_link</bodyName>
      <topicName>imu/mag</topicName>
      <frameId>imu_link</frameId>
      <useMagneticFieldMsgs>true</useMagneticFieldMsgs>
      <magnitude>0.000047</magnitude>
      <declination>-7.81</declination>
      <inclination>49.48</inclination>
      <offset>0 0 0</offset>
      <drift>0 0 0</drift>
      <driftFrequency>0 0 0</driftFrequency>
      <gaussianNoise>0 0 0</gaussianNoise>
    </plugin>
  </gazebo>
  <joint name="rgbd_joint" type="fixed">
    <origin rpy="0 0 0" xyz="0.04425 0 0.017"/>
    <parent link="chest"/>
    <child link="rgbd_body"/>
  </joint>
  <link name="rgbd_body">
    <visual>
      <origin xyz="0 0 0"/>
      <geometry>
        <box size="0.014 0.036 0.036"/>
      </geometry>
      <material name="gray">
        <color rgba="0.5 0.5 0.5 1"/>
      </material>
    </visual>
    <collision>
      <origin xyz="0 0 0"/>
      <geometry>
        <box size="0.014 0.036 0.036"/>
      </geometry>
    </collision>
    <inertial>
      <origin rpy="0 0 0" xyz="0 0 0"/>
      <mass value="0.043"/>
      <inertia ixx="1e-05" ixy="0.0" ixz="0.0" iyy="1e-05" iyz="0.0" izz="1e-05"/>
    </inertial>
  </link>
  <joint name="rgbd_depth_optical_joint" type="fixed">
    <origin rpy="-1.57079632679 0 -1.57079632679" xyz="0.007 0.0055 -0.0055"/>
    <parent link="rgbd_body"/>
    <child link="rgbd_depth_optical_frame"/>
  </joint>
  <link name="rgbd_depth_optical_frame"/>
  <joint name="rgbd_depth_joint" type="fixed">
    <origin rpy="0 -1.57079632679 1.57079632679" xyz="0 0 0"/>
    <parent link="rgbd_depth_optical_frame"/>
    <child link="rgbd_depth_frame"/>
  </joint>
  <link name="rgbd_depth_frame"/>
  <joint name="rgbd_rgb_optical_joint" type="fixed">
    <origin rpy="0 0 0" xyz="0.007 -0.0055 0.0055"/>
    <parent link="rgbd_body"/>
    <child link="rgbd_rgb_optical_frame"/>
  </joint>
  <link name="rgbd_rgb_optical_frame"/>
  <joint name="rgbd_rgb_joint" type="fixed">
    <origin rpy="0 -1.57079632679 1.57079632679" xyz="0 0 0"/>
    <parent link="rgbd_rgb_optical_frame"/>
    <child link="rgbd_rgb_frame"/>
  </joint>
  <link name="rgbd_rgb_frame"/>
  <gazebo reference="rgbd_base">
    <material>Gazebo/Grey</material>
  </gazebo>
  <gazebo reference="rgbd_depth_frame">
    <sensor name="camera" type="depth">
      <always_on>true</always_on>
      <update_rate>15.0</update_rate>
      <camera>
        <horizontal_fov>1.308996939</horizontal_fov>
        <vertical_fov>1.1344640138</vertical_fov>
        <image>
          <format>B8G8R8</format>
          <width>320</width>
          <height>240</height>
        </image>
        <clip>
          <near>0.2</near>
          <far>2.0</far>
        </clip>
      </camera>
      <plugin filename="libgazebo_ros_openni_kinect.so" name="depth_controller">
        <cameraName>rgbd/depth</cameraName>
        <alwaysOn>true</alwaysOn>
        <updateRate>15</updateRate>
        <imageTopicName>gazebo/rgb/image_raw</imageTopicName>
        <cameraInfoTopicName>gazebo/rgb/camera_info</cameraInfoTopicName>
        <depthImageTopicName>image_raw</depthImageTopicName>
        <depthImageCameraInfoTopicName>camera_info</depthImageCameraInfoTopicName>
        <pointCloudTopicName>gazebo/points</pointCloudTopicName>
        <frameName>rgbd_depth_optical_frame</frameName>
        <baseline>0.1</baseline>
        <distortion_k1>0.0</distortion_k1>
        <distortion_k2>0.0</distortion_k2>
        <distortion_k3>0.0</distortion_k3>
        <distortion_t1>0.0</distortion_t1>
        <distortion_t2>0.0</distortion_t2>
        <pointCloudCutoff>0.2</pointCloudCutoff>
        <pointCloudCutoffMax>2.0</pointCloudCutoffMax>
      </plugin>
    </sensor>
  </gazebo>
  <gazebo reference="rgbd_rgb_frame">
    <sensor name="camera" type="camera">
      <always_on>true</always_on>
      <update_rate>15.0</update_rate>
      <camera>
        <horizontal_fov>1.57079632679</horizontal_fov>
        <vertical_fov>1.29677963423</vertical_fov>
        <image>
          <format>B8G8R8</format>
          <width>800</width>
          <height>600</height>
        </image>
        <clip>
          <near>0.01</near>
          <far>8.0</far>
        </clip>
      </camera>
      <plugin filename="libgazebo_ros_camera.so" name="rgb_controller">
        <cameraName>rgbd/rgb_no_resized</cameraName>
        <alwaysOn>true</alwaysOn>
        <updateRate>0</updateRate>
        <imageTopicName>image_raw</imageTopicName>
        <cameraInfoTopicName>camera_info</cameraInfoTopicName>
        <frameName>rgbd_rgb_optical_frame</frameName>
        <baseline>0.1</baseline>
        <distortion_k1>0.0</distortion_k1>
        <distortion_k2>0.0</distortion_k2>
        <distortion_k3>0.0</distortion_k3>
        <distortion_t1>0.0</distortion_t1>
        <distortion_t2>0.0</distortion_t2>
        <pointCloudCutoff>0.01</pointCloudCutoff>
        <pointCloudCutoffMax>8.0</pointCloudCutoffMax>
      </plugin>
    </sensor>
  </gazebo>
  <gazebo>
    <plugin filename="libgazebo_dc_motor.so" name="gazebo_ros_control">
      <robotNamespace>kuroko</robotNamespace>
      <robotSimType>gazebo_dc_motor/DefaultRobotHWSim</robotSimType>
      <legacyModeNS>false</legacyModeNS>
    </plugin>
  </gazebo>
</robot>
